<?xml version="1.0" ?>
<!-- =================================================================================== -->
<!-- |    This document was autogenerated by xacro from snake_monster.xacro            | -->
<!-- |    EDITING THIS FILE BY HAND IS NOT RECOMMENDED                                 | -->
<!-- =================================================================================== -->
<robot name="snake_monster" xmlns:xacro="http://www.ros.org/wiki/xacro">
  <!-- *************************** XACRO MACROS *************************** -->
  <!-- TODO: technically, this should include the elbow/extend/rotary/etc...are mult. def'ns OK? -->
  <!-- ************************* ROBOT DEFINITION ************************* -->
  <!-- base body -->
  <link name="base">
    <visual>
      <origin rpy="0 0 0" xyz="0 0 0.0381"/>
      <geometry>
        <box size="0.185 0.3 0.0762"/>
      </geometry>
      <material name="silver">
        <color rgba="0.6 0.6 0.6 1"/>
      </material>
    </visual>
  </link>
  <!-- leg outputs on the base -->
  <joint name="leg1__OUTPUT_INTERFACE" type="fixed">
    <parent link="base"/>
    <child link="SA014__MoJo__INPUT_INTERFACE"/>
    <origin rpy="-1.57079632679 0 -1.57079632679" xyz="0.0925 0.125 0.0381"/>
  </joint>
  <joint name="leg2__OUTPUT_INTERFACE" type="fixed">
    <parent link="base"/>
    <child link="SA037__MoJo__INPUT_INTERFACE"/>
    <origin rpy="-1.57079632679 0 -1.57079632679" xyz="0.0925 0 0.0381"/>
  </joint>
  <joint name="leg3__OUTPUT_INTERFACE" type="fixed">
    <parent link="base"/>
    <child link="SA036__MoJo__INPUT_INTERFACE"/>
    <origin rpy="-1.57079632679 0 -1.57079632679" xyz="0.0925 -0.125 0.0381"/>
  </joint>
  <joint name="leg6__OUTPUT_INTERFACE" type="fixed">
    <parent link="base"/>
    <child link="SA043__MoJo__INPUT_INTERFACE"/>
    <origin rpy="-1.57079632679 0 1.57079632679" xyz="-0.0925 0.125 0.0381"/>
  </joint>
  <joint name="leg5__OUTPUT_INTERFACE" type="fixed">
    <parent link="base"/>
    <child link="SA002__MoJo__INPUT_INTERFACE"/>
    <origin rpy="-1.57079632679 0 1.57079632679" xyz="-0.0925 0 0.0381"/>
  </joint>
  <joint name="leg4__OUTPUT_INTERFACE" type="fixed">
    <parent link="base"/>
    <child link="SA022__MoJo__INPUT_INTERFACE"/>
    <origin rpy="-1.57079632679 0 1.57079632679" xyz="-0.0925 -0.125 0.0381"/>
  </joint>
  <link name="SA014__MoJo__INPUT_INTERFACE">
    <visual>
      <origin rpy="1.57075 0 0" xyz="0 0 0.035"/>
      <geometry>
        <mesh filename="package://snake_monster/meshes/rotary_input.stl"/>
      </geometry>
      <material name="red">
        <color rgba=".82 0.06 0.06 1"/>
      </material>
    </visual>
    <collision>
      <origin rpy="0 0 0" xyz="0 0 0.0183"/>
      <geometry>
        <cylinder length="0.033" radius="0.026"/>
      </geometry>
    </collision>
    <inertial>
      <origin rpy="0 0 0" xyz="0 0 0.0366"/>
      <mass value="0.103"/>
      <inertia ixx="5.4796e-05" ixy="0" ixz="0" iyy="5.4796e-05" iyz="0" izz="3.4814e-05"/>
    </inertial>
  </link>
  <link name="SA014__MoJo__INPUT_INTERFACE__COLLAR">
    <visual>
      <origin rpy="0 0 0" xyz="0 0 0.005"/>
      <geometry>
        <cylinder length="0.01" radius="0.026"/>
      </geometry>
      <material name="black">
        <color rgba="0 0 0 1"/>
      </material>
    </visual>
  </link>
  <joint name="SA014__MoJo__INPUT_INTERFACE__COLLAR_JOINT" type="fixed">
    <parent link="SA014__MoJo__INPUT_INTERFACE"/>
    <child link="SA014__MoJo__INPUT_INTERFACE__COLLAR"/>
  </joint>
  <joint name="SA014__MoJo" type="revolute">
    <parent link="SA014__MoJo__INPUT_INTERFACE"/>
    <child link="SA014__MoJo__OUTPUT_BODY"/>
    <origin rpy="0 0 0" xyz="0 0 0.0366"/>
    <axis xyz="0 1 0"/>
    <dynamics damping=".1" friction="0.2"/>
    <limit effort="7.0" lower="-1.57" upper="1.57" velocity="2.208932"/>
  </joint>
  <transmission name="SA014__MoJo_trans">
    <type>transmission_interface/SimpleTransmission</type>
    <joint name="SA014__MoJo">
      <hardwareInterface>EffortJointInterface</hardwareInterface>
    </joint>
    <actuator name="SA014__MoJo_motor">
      <hardwareInterface>EffortJointInterface</hardwareInterface>
      <mechanicalReduction>300</mechanicalReduction>
    </actuator>
  </transmission>
  <link name="SA014__MoJo__OUTPUT_BODY">
    <visual>
      <origin rpy="1.57075 0 0" xyz="0 0 0"/>
      <geometry>
        <mesh filename="package://snake_monster/meshes/rotary_output.stl"/>
        <!-- <cylinder radius=".0025" length=".1" /> -->
      </geometry>
      <material name="red">
        <color rgba=".82 0.06 0.06 1"/>
      </material>
    </visual>
    <collision>
      <origin rpy="0 0 0" xyz="0 0 0.0183"/>
      <geometry>
        <cylinder length="0.033" radius="0.026"/>
      </geometry>
    </collision>
    <inertial>
      <origin rpy="0 0 0" xyz="0 0 0"/>
      <mass value="0.103"/>
      <inertia ixx="5.4796e-05" ixy="0" ixz="0" iyy="5.4796e-05" iyz="0" izz="3.4814e-05"/>
    </inertial>
  </link>
  <joint name="SA014__MoJo__OUTPUT_INTERFACE" type="fixed">
    <parent link="SA014__MoJo__OUTPUT_BODY"/>
    <child link="SA013__MoJo__INPUT_INTERFACE"/>
    <origin rpy="0 0 -1.57075" xyz="0 0 0.0273"/>
  </joint>
  <link name="SA013__MoJo__INPUT_INTERFACE">
    <visual>
      <origin rpy="1.57075 0 0" xyz="0 0 0.035"/>
      <geometry>
        <mesh filename="package://snake_monster/meshes/rotary_input.stl"/>
      </geometry>
      <material name="red">
        <color rgba=".82 0.06 0.06 1"/>
      </material>
    </visual>
    <collision>
      <origin rpy="0 0 0" xyz="0 0 0.0183"/>
      <geometry>
        <cylinder length="0.033" radius="0.026"/>
      </geometry>
    </collision>
    <inertial>
      <origin rpy="0 0 0" xyz="0 0 0.0366"/>
      <mass value="0.103"/>
      <inertia ixx="5.4796e-05" ixy="0" ixz="0" iyy="5.4796e-05" iyz="0" izz="3.4814e-05"/>
    </inertial>
  </link>
  <link name="SA013__MoJo__INPUT_INTERFACE__COLLAR">
    <visual>
      <origin rpy="0 0 0" xyz="0 0 0.005"/>
      <geometry>
        <cylinder length="0.01" radius="0.026"/>
      </geometry>
      <material name="black">
        <color rgba="0 0 0 1"/>
      </material>
    </visual>
  </link>
  <joint name="SA013__MoJo__INPUT_INTERFACE__COLLAR_JOINT" type="fixed">
    <parent link="SA013__MoJo__INPUT_INTERFACE"/>
    <child link="SA013__MoJo__INPUT_INTERFACE__COLLAR"/>
  </joint>
  <joint name="SA013__MoJo" type="revolute">
    <parent link="SA013__MoJo__INPUT_INTERFACE"/>
    <child link="SA013__MoJo__OUTPUT_BODY"/>
    <origin rpy="0 0 0" xyz="0 0 0.0366"/>
    <axis xyz="0 1 0"/>
    <dynamics damping=".1" friction="0.2"/>
    <limit effort="7.0" lower="-1.57" upper="1.57" velocity="2.208932"/>
  </joint>
  <transmission name="SA013__MoJo_trans">
    <type>transmission_interface/SimpleTransmission</type>
    <joint name="SA013__MoJo">
      <hardwareInterface>EffortJointInterface</hardwareInterface>
    </joint>
    <actuator name="SA013__MoJo_motor">
      <hardwareInterface>EffortJointInterface</hardwareInterface>
      <mechanicalReduction>300</mechanicalReduction>
    </actuator>
  </transmission>
  <link name="SA013__MoJo__OUTPUT_BODY">
    <visual>
      <origin rpy="1.57075 0 0" xyz="0 0 0"/>
      <geometry>
        <mesh filename="package://snake_monster/meshes/rotary_output.stl"/>
        <!-- <cylinder radius=".0025" length=".1" /> -->
      </geometry>
      <material name="red">
        <color rgba=".82 0.06 0.06 1"/>
      </material>
    </visual>
    <collision>
      <origin rpy="0 0 0" xyz="0 0 0.0183"/>
      <geometry>
        <cylinder length="0.033" radius="0.026"/>
      </geometry>
    </collision>
    <inertial>
      <origin rpy="0 0 0" xyz="0 0 0"/>
      <mass value="0.103"/>
      <inertia ixx="5.4796e-05" ixy="0" ixz="0" iyy="5.4796e-05" iyz="0" izz="3.4814e-05"/>
    </inertial>
  </link>
  <joint name="SA013__MoJo__OUTPUT_INTERFACE" type="fixed">
    <parent link="SA013__MoJo__OUTPUT_BODY"/>
    <child link="extender__leg1__INPUT_INTERFACE"/>
    <origin rpy="0 0 -1.57075" xyz="0 0 0.0273"/>
  </joint>
  <link name="extender__leg1__INPUT_INTERFACE">
    <visual>
      <origin rpy="0 0 0" xyz="0 0 0.025"/>
      <geometry>
        <cylinder length="0.05" radius=".0254"/>
      </geometry>
      <material name="silver">
        <color rgba="0.6 0.6 0.6 1"/>
      </material>
    </visual>
    <collision>
      <origin rpy="0 0 0" xyz="0 0 0.025"/>
      <geometry>
        <cylinder length="0.05" radius=".0254"/>
      </geometry>
    </collision>
    <inertial>
      <origin rpy="0 0 0" xyz="0 0 0.025"/>
      <mass value=".05"/>
      <inertia ixx="2.50134116667e-05" ixy="0" ixz="0" iyy="2.50134116667e-05" iyz="0" izz="2.919349e-05"/>
    </inertial>
  </link>
  <joint name="extender__leg1__OUTPUT_INTERFACE" type="fixed">
    <parent link="extender__leg1__INPUT_INTERFACE"/>
    <child link="SA023__MoJo__INPUT_INTERFACE"/>
    <origin rpy="0 0 1.57079632679" xyz="0 0 0.05"/>
  </joint>
  <link name="extender__leg1__INPUT_INTERFACE__COLLAR">
    <visual>
      <origin rpy="0 0 0" xyz="0 0 0.005"/>
      <geometry>
        <cylinder length="0.01" radius="0.026"/>
      </geometry>
      <material name="black">
        <color rgba="0 0 0 1"/>
      </material>
    </visual>
  </link>
  <joint name="extender__leg1__INPUT_INTERFACE__COLLAR_JOINT" type="fixed">
    <parent link="extender__leg1__INPUT_INTERFACE"/>
    <child link="extender__leg1__INPUT_INTERFACE__COLLAR"/>
  </joint>
  <link name="SA023__MoJo__INPUT_INTERFACE">
    <visual>
      <origin rpy="1.57075 0 0" xyz="0 0 0.035"/>
      <geometry>
        <mesh filename="package://snake_monster/meshes/rotary_input.stl"/>
      </geometry>
      <material name="red">
        <color rgba=".82 0.06 0.06 1"/>
      </material>
    </visual>
    <collision>
      <origin rpy="0 0 0" xyz="0 0 0.0183"/>
      <geometry>
        <cylinder length="0.033" radius="0.026"/>
      </geometry>
    </collision>
    <inertial>
      <origin rpy="0 0 0" xyz="0 0 0.0366"/>
      <mass value="0.103"/>
      <inertia ixx="5.4796e-05" ixy="0" ixz="0" iyy="5.4796e-05" iyz="0" izz="3.4814e-05"/>
    </inertial>
  </link>
  <link name="SA023__MoJo__INPUT_INTERFACE__COLLAR">
    <visual>
      <origin rpy="0 0 0" xyz="0 0 0.005"/>
      <geometry>
        <cylinder length="0.01" radius="0.026"/>
      </geometry>
      <material name="black">
        <color rgba="0 0 0 1"/>
      </material>
    </visual>
  </link>
  <joint name="SA023__MoJo__INPUT_INTERFACE__COLLAR_JOINT" type="fixed">
    <parent link="SA023__MoJo__INPUT_INTERFACE"/>
    <child link="SA023__MoJo__INPUT_INTERFACE__COLLAR"/>
  </joint>
  <joint name="SA023__MoJo" type="revolute">
    <parent link="SA023__MoJo__INPUT_INTERFACE"/>
    <child link="SA023__MoJo__OUTPUT_BODY"/>
    <origin rpy="0 0 0" xyz="0 0 0.0366"/>
    <axis xyz="0 1 0"/>
    <dynamics damping=".1" friction="0.2"/>
    <limit effort="7.0" lower="-1.57" upper="1.57" velocity="2.208932"/>
  </joint>
  <transmission name="SA023__MoJo_trans">
    <type>transmission_interface/SimpleTransmission</type>
    <joint name="SA023__MoJo">
      <hardwareInterface>EffortJointInterface</hardwareInterface>
    </joint>
    <actuator name="SA023__MoJo_motor">
      <hardwareInterface>EffortJointInterface</hardwareInterface>
      <mechanicalReduction>300</mechanicalReduction>
    </actuator>
  </transmission>
  <link name="SA023__MoJo__OUTPUT_BODY">
    <visual>
      <origin rpy="1.57075 0 0" xyz="0 0 0"/>
      <geometry>
        <mesh filename="package://snake_monster/meshes/rotary_output.stl"/>
        <!-- <cylinder radius=".0025" length=".1" /> -->
      </geometry>
      <material name="red">
        <color rgba=".82 0.06 0.06 1"/>
      </material>
    </visual>
    <collision>
      <origin rpy="0 0 0" xyz="0 0 0.0183"/>
      <geometry>
        <cylinder length="0.033" radius="0.026"/>
      </geometry>
    </collision>
    <inertial>
      <origin rpy="0 0 0" xyz="0 0 0"/>
      <mass value="0.103"/>
      <inertia ixx="5.4796e-05" ixy="0" ixz="0" iyy="5.4796e-05" iyz="0" izz="3.4814e-05"/>
    </inertial>
  </link>
  <joint name="SA023__MoJo__OUTPUT_INTERFACE" type="fixed">
    <parent link="SA023__MoJo__OUTPUT_BODY"/>
    <child link="elbow__leg1__INPUT_INTERFACE"/>
    <origin rpy="0 0 -1.57075" xyz="0 0 0.0273"/>
  </joint>
  <link name="elbow__leg1__INPUT_INTERFACE">
    <visual>
      <origin rpy="0 0 0" xyz="0 0 0.00955"/>
      <geometry>
        <cylinder length="0.0191" radius=".0254"/>
      </geometry>
      <material name="silver">
        <color rgba="0.6 0.6 0.6 1"/>
      </material>
    </visual>
    <visual>
      <origin rpy="1.57075 0 3.14159265359" xyz="0.0274 -0.0782 0.0121"/>
      <geometry>
        <mesh filename="package://snake_monster/meshes/elbow_corner.stl"/>
      </geometry>
      <material name="silver">
        <color rgba="0.6 0.6 0.6 1"/>
      </material>
    </visual>
    <collision>
      <origin rpy="0 0 0" xyz="0 0 0.00955"/>
      <geometry>
        <cylinder length="0.0191" radius=".0254"/>
      </geometry>
    </collision>
    <collision>
      <origin rpy="0 0 0" xyz="0 -0.01 0.0311"/>
      <geometry>
        <sphere radius="0.0191"/>
      </geometry>
    </collision>
    <inertial>
      <origin rpy="0 0 0" xyz="0 0 0.0391"/>
      <mass value=".045"/>
      <inertia ixx="8.6260875e-06" ixy="0" ixz="0" iyy="8.6260875e-06" iyz="0" izz="1.45161e-05"/>
    </inertial>
  </link>
  <link name="elbow__leg1__INPUT_INTERFACE__COLLAR">
    <visual>
      <origin rpy="0 0 0" xyz="0 0 0.005"/>
      <geometry>
        <cylinder length="0.01" radius="0.026"/>
      </geometry>
      <material name="black">
        <color rgba="0 0 0 1"/>
      </material>
    </visual>
  </link>
  <joint name="elbow__leg1__INPUT_INTERFACE__COLLAR_JOINT" type="fixed">
    <parent link="elbow__leg1__INPUT_INTERFACE"/>
    <child link="elbow__leg1__INPUT_INTERFACE__COLLAR"/>
  </joint>
  <joint name="elbow__leg1__MID_ELBOW_JOINT" type="fixed">
    <parent link="elbow__leg1__INPUT_INTERFACE"/>
    <child link="elbow__leg1__AFTER_CORNER_BODY"/>
    <origin rpy="-1.57079632679 0 3.14159265359" xyz="0 0 0.0445"/>
  </joint>
  <link name="elbow__leg1__AFTER_CORNER_BODY">
    <visual>
      <origin rpy="0 0 0" xyz="0 0 0.0857"/>
      <geometry>
        <cylinder length="0.1206" radius=".0254"/>
      </geometry>
      <material name="silver">
        <color rgba="0.6 0.6 0.6 1"/>
      </material>
    </visual>
    <collision>
      <origin rpy="0 0 0" xyz="0 0 0.0857"/>
      <geometry>
        <cylinder length="0.1206" radius=".0254"/>
      </geometry>
    </collision>
    <inertial>
      <origin rpy="0 0 0" xyz="0 0 0.0857"/>
      <mass value=".065"/>
      <inertia ixx="1.24599041667e-05" ixy="0" ixz="0" iyy="1.24599041667e-05" iyz="0" izz="2.09677e-05"/>
    </inertial>
  </link>
  <joint name="elbow__leg1__OUTPUT_INTERFACE" type="fixed">
    <parent link="elbow__leg1__AFTER_CORNER_BODY"/>
    <child link="foot__leg1__INPUT_INTERFACE"/>
    <origin rpy="0 0 -1.57079632679" xyz="0 0 0.146"/>
  </joint>
  <!--TODO: check dimensions -->
  <link name="foot__leg1__INPUT_INTERFACE">
    <visual>
      <origin rpy="0 0 0" xyz="0 0 0"/>
      <geometry>
        <sphere radius=".0254"/>
      </geometry>
      <material name="black">
        <color rgba="0 0 0 1"/>
      </material>
    </visual>
    <collision>
      <origin rpy="0 0 0" xyz="0 0 0"/>
      <geometry>
        <sphere radius=".0254"/>
      </geometry>
    </collision>
  </link>
  <link name="SA037__MoJo__INPUT_INTERFACE">
    <visual>
      <origin rpy="1.57075 0 0" xyz="0 0 0.035"/>
      <geometry>
        <mesh filename="package://snake_monster/meshes/rotary_input.stl"/>
      </geometry>
      <material name="red">
        <color rgba=".82 0.06 0.06 1"/>
      </material>
    </visual>
    <collision>
      <origin rpy="0 0 0" xyz="0 0 0.0183"/>
      <geometry>
        <cylinder length="0.033" radius="0.026"/>
      </geometry>
    </collision>
    <inertial>
      <origin rpy="0 0 0" xyz="0 0 0.0366"/>
      <mass value="0.103"/>
      <inertia ixx="5.4796e-05" ixy="0" ixz="0" iyy="5.4796e-05" iyz="0" izz="3.4814e-05"/>
    </inertial>
  </link>
  <link name="SA037__MoJo__INPUT_INTERFACE__COLLAR">
    <visual>
      <origin rpy="0 0 0" xyz="0 0 0.005"/>
      <geometry>
        <cylinder length="0.01" radius="0.026"/>
      </geometry>
      <material name="black">
        <color rgba="0 0 0 1"/>
      </material>
    </visual>
  </link>
  <joint name="SA037__MoJo__INPUT_INTERFACE__COLLAR_JOINT" type="fixed">
    <parent link="SA037__MoJo__INPUT_INTERFACE"/>
    <child link="SA037__MoJo__INPUT_INTERFACE__COLLAR"/>
  </joint>
  <joint name="SA037__MoJo" type="revolute">
    <parent link="SA037__MoJo__INPUT_INTERFACE"/>
    <child link="SA037__MoJo__OUTPUT_BODY"/>
    <origin rpy="0 0 0" xyz="0 0 0.0366"/>
    <axis xyz="0 1 0"/>
    <dynamics damping=".1" friction="0.2"/>
    <limit effort="7.0" lower="-1.57" upper="1.57" velocity="2.208932"/>
  </joint>
  <transmission name="SA037__MoJo_trans">
    <type>transmission_interface/SimpleTransmission</type>
    <joint name="SA037__MoJo">
      <hardwareInterface>EffortJointInterface</hardwareInterface>
    </joint>
    <actuator name="SA037__MoJo_motor">
      <hardwareInterface>EffortJointInterface</hardwareInterface>
      <mechanicalReduction>300</mechanicalReduction>
    </actuator>
  </transmission>
  <link name="SA037__MoJo__OUTPUT_BODY">
    <visual>
      <origin rpy="1.57075 0 0" xyz="0 0 0"/>
      <geometry>
        <mesh filename="package://snake_monster/meshes/rotary_output.stl"/>
        <!-- <cylinder radius=".0025" length=".1" /> -->
      </geometry>
      <material name="red">
        <color rgba=".82 0.06 0.06 1"/>
      </material>
    </visual>
    <collision>
      <origin rpy="0 0 0" xyz="0 0 0.0183"/>
      <geometry>
        <cylinder length="0.033" radius="0.026"/>
      </geometry>
    </collision>
    <inertial>
      <origin rpy="0 0 0" xyz="0 0 0"/>
      <mass value="0.103"/>
      <inertia ixx="5.4796e-05" ixy="0" ixz="0" iyy="5.4796e-05" iyz="0" izz="3.4814e-05"/>
    </inertial>
  </link>
  <joint name="SA037__MoJo__OUTPUT_INTERFACE" type="fixed">
    <parent link="SA037__MoJo__OUTPUT_BODY"/>
    <child link="SA049__MoJo__INPUT_INTERFACE"/>
    <origin rpy="0 0 -1.57075" xyz="0 0 0.0273"/>
  </joint>
  <link name="SA049__MoJo__INPUT_INTERFACE">
    <visual>
      <origin rpy="1.57075 0 0" xyz="0 0 0.035"/>
      <geometry>
        <mesh filename="package://snake_monster/meshes/rotary_input.stl"/>
      </geometry>
      <material name="red">
        <color rgba=".82 0.06 0.06 1"/>
      </material>
    </visual>
    <collision>
      <origin rpy="0 0 0" xyz="0 0 0.0183"/>
      <geometry>
        <cylinder length="0.033" radius="0.026"/>
      </geometry>
    </collision>
    <inertial>
      <origin rpy="0 0 0" xyz="0 0 0.0366"/>
      <mass value="0.103"/>
      <inertia ixx="5.4796e-05" ixy="0" ixz="0" iyy="5.4796e-05" iyz="0" izz="3.4814e-05"/>
    </inertial>
  </link>
  <link name="SA049__MoJo__INPUT_INTERFACE__COLLAR">
    <visual>
      <origin rpy="0 0 0" xyz="0 0 0.005"/>
      <geometry>
        <cylinder length="0.01" radius="0.026"/>
      </geometry>
      <material name="black">
        <color rgba="0 0 0 1"/>
      </material>
    </visual>
  </link>
  <joint name="SA049__MoJo__INPUT_INTERFACE__COLLAR_JOINT" type="fixed">
    <parent link="SA049__MoJo__INPUT_INTERFACE"/>
    <child link="SA049__MoJo__INPUT_INTERFACE__COLLAR"/>
  </joint>
  <joint name="SA049__MoJo" type="revolute">
    <parent link="SA049__MoJo__INPUT_INTERFACE"/>
    <child link="SA049__MoJo__OUTPUT_BODY"/>
    <origin rpy="0 0 0" xyz="0 0 0.0366"/>
    <axis xyz="0 1 0"/>
    <dynamics damping=".1" friction="0.2"/>
    <limit effort="7.0" lower="-1.57" upper="1.57" velocity="2.208932"/>
  </joint>
  <transmission name="SA049__MoJo_trans">
    <type>transmission_interface/SimpleTransmission</type>
    <joint name="SA049__MoJo">
      <hardwareInterface>EffortJointInterface</hardwareInterface>
    </joint>
    <actuator name="SA049__MoJo_motor">
      <hardwareInterface>EffortJointInterface</hardwareInterface>
      <mechanicalReduction>300</mechanicalReduction>
    </actuator>
  </transmission>
  <link name="SA049__MoJo__OUTPUT_BODY">
    <visual>
      <origin rpy="1.57075 0 0" xyz="0 0 0"/>
      <geometry>
        <mesh filename="package://snake_monster/meshes/rotary_output.stl"/>
        <!-- <cylinder radius=".0025" length=".1" /> -->
      </geometry>
      <material name="red">
        <color rgba=".82 0.06 0.06 1"/>
      </material>
    </visual>
    <collision>
      <origin rpy="0 0 0" xyz="0 0 0.0183"/>
      <geometry>
        <cylinder length="0.033" radius="0.026"/>
      </geometry>
    </collision>
    <inertial>
      <origin rpy="0 0 0" xyz="0 0 0"/>
      <mass value="0.103"/>
      <inertia ixx="5.4796e-05" ixy="0" ixz="0" iyy="5.4796e-05" iyz="0" izz="3.4814e-05"/>
    </inertial>
  </link>
  <joint name="SA049__MoJo__OUTPUT_INTERFACE" type="fixed">
    <parent link="SA049__MoJo__OUTPUT_BODY"/>
    <child link="extender__leg2__INPUT_INTERFACE"/>
    <origin rpy="0 0 -1.57075" xyz="0 0 0.0273"/>
  </joint>
  <link name="extender__leg2__INPUT_INTERFACE">
    <visual>
      <origin rpy="0 0 0" xyz="0 0 0.025"/>
      <geometry>
        <cylinder length="0.05" radius=".0254"/>
      </geometry>
      <material name="silver">
        <color rgba="0.6 0.6 0.6 1"/>
      </material>
    </visual>
    <collision>
      <origin rpy="0 0 0" xyz="0 0 0.025"/>
      <geometry>
        <cylinder length="0.05" radius=".0254"/>
      </geometry>
    </collision>
    <inertial>
      <origin rpy="0 0 0" xyz="0 0 0.025"/>
      <mass value=".05"/>
      <inertia ixx="2.50134116667e-05" ixy="0" ixz="0" iyy="2.50134116667e-05" iyz="0" izz="2.919349e-05"/>
    </inertial>
  </link>
  <joint name="extender__leg2__OUTPUT_INTERFACE" type="fixed">
    <parent link="extender__leg2__INPUT_INTERFACE"/>
    <child link="SA030__MoJo__INPUT_INTERFACE"/>
    <origin rpy="0 0 1.57079632679" xyz="0 0 0.05"/>
  </joint>
  <link name="extender__leg2__INPUT_INTERFACE__COLLAR">
    <visual>
      <origin rpy="0 0 0" xyz="0 0 0.005"/>
      <geometry>
        <cylinder length="0.01" radius="0.026"/>
      </geometry>
      <material name="black">
        <color rgba="0 0 0 1"/>
      </material>
    </visual>
  </link>
  <joint name="extender__leg2__INPUT_INTERFACE__COLLAR_JOINT" type="fixed">
    <parent link="extender__leg2__INPUT_INTERFACE"/>
    <child link="extender__leg2__INPUT_INTERFACE__COLLAR"/>
  </joint>
  <link name="SA030__MoJo__INPUT_INTERFACE">
    <visual>
      <origin rpy="1.57075 0 0" xyz="0 0 0.035"/>
      <geometry>
        <mesh filename="package://snake_monster/meshes/rotary_input.stl"/>
      </geometry>
      <material name="red">
        <color rgba=".82 0.06 0.06 1"/>
      </material>
    </visual>
    <collision>
      <origin rpy="0 0 0" xyz="0 0 0.0183"/>
      <geometry>
        <cylinder length="0.033" radius="0.026"/>
      </geometry>
    </collision>
    <inertial>
      <origin rpy="0 0 0" xyz="0 0 0.0366"/>
      <mass value="0.103"/>
      <inertia ixx="5.4796e-05" ixy="0" ixz="0" iyy="5.4796e-05" iyz="0" izz="3.4814e-05"/>
    </inertial>
  </link>
  <link name="SA030__MoJo__INPUT_INTERFACE__COLLAR">
    <visual>
      <origin rpy="0 0 0" xyz="0 0 0.005"/>
      <geometry>
        <cylinder length="0.01" radius="0.026"/>
      </geometry>
      <material name="black">
        <color rgba="0 0 0 1"/>
      </material>
    </visual>
  </link>
  <joint name="SA030__MoJo__INPUT_INTERFACE__COLLAR_JOINT" type="fixed">
    <parent link="SA030__MoJo__INPUT_INTERFACE"/>
    <child link="SA030__MoJo__INPUT_INTERFACE__COLLAR"/>
  </joint>
  <joint name="SA030__MoJo" type="revolute">
    <parent link="SA030__MoJo__INPUT_INTERFACE"/>
    <child link="SA030__MoJo__OUTPUT_BODY"/>
    <origin rpy="0 0 0" xyz="0 0 0.0366"/>
    <axis xyz="0 1 0"/>
    <dynamics damping=".1" friction="0.2"/>
    <limit effort="7.0" lower="-1.57" upper="1.57" velocity="2.208932"/>
  </joint>
  <transmission name="SA030__MoJo_trans">
    <type>transmission_interface/SimpleTransmission</type>
    <joint name="SA030__MoJo">
      <hardwareInterface>EffortJointInterface</hardwareInterface>
    </joint>
    <actuator name="SA030__MoJo_motor">
      <hardwareInterface>EffortJointInterface</hardwareInterface>
      <mechanicalReduction>300</mechanicalReduction>
    </actuator>
  </transmission>
  <link name="SA030__MoJo__OUTPUT_BODY">
    <visual>
      <origin rpy="1.57075 0 0" xyz="0 0 0"/>
      <geometry>
        <mesh filename="package://snake_monster/meshes/rotary_output.stl"/>
        <!-- <cylinder radius=".0025" length=".1" /> -->
      </geometry>
      <material name="red">
        <color rgba=".82 0.06 0.06 1"/>
      </material>
    </visual>
    <collision>
      <origin rpy="0 0 0" xyz="0 0 0.0183"/>
      <geometry>
        <cylinder length="0.033" radius="0.026"/>
      </geometry>
    </collision>
    <inertial>
      <origin rpy="0 0 0" xyz="0 0 0"/>
      <mass value="0.103"/>
      <inertia ixx="5.4796e-05" ixy="0" ixz="0" iyy="5.4796e-05" iyz="0" izz="3.4814e-05"/>
    </inertial>
  </link>
  <joint name="SA030__MoJo__OUTPUT_INTERFACE" type="fixed">
    <parent link="SA030__MoJo__OUTPUT_BODY"/>
    <child link="elbow__leg2__INPUT_INTERFACE"/>
    <origin rpy="0 0 -1.57075" xyz="0 0 0.0273"/>
  </joint>
  <link name="elbow__leg2__INPUT_INTERFACE">
    <visual>
      <origin rpy="0 0 0" xyz="0 0 0.00955"/>
      <geometry>
        <cylinder length="0.0191" radius=".0254"/>
      </geometry>
      <material name="silver">
        <color rgba="0.6 0.6 0.6 1"/>
      </material>
    </visual>
    <visual>
      <origin rpy="1.57075 0 3.14159265359" xyz="0.0274 -0.0782 0.0121"/>
      <geometry>
        <mesh filename="package://snake_monster/meshes/elbow_corner.stl"/>
      </geometry>
      <material name="silver">
        <color rgba="0.6 0.6 0.6 1"/>
      </material>
    </visual>
    <collision>
      <origin rpy="0 0 0" xyz="0 0 0.00955"/>
      <geometry>
        <cylinder length="0.0191" radius=".0254"/>
      </geometry>
    </collision>
    <collision>
      <origin rpy="0 0 0" xyz="0 -0.01 0.0311"/>
      <geometry>
        <sphere radius="0.0191"/>
      </geometry>
    </collision>
    <inertial>
      <origin rpy="0 0 0" xyz="0 0 0.0391"/>
      <mass value=".045"/>
      <inertia ixx="8.6260875e-06" ixy="0" ixz="0" iyy="8.6260875e-06" iyz="0" izz="1.45161e-05"/>
    </inertial>
  </link>
  <link name="elbow__leg2__INPUT_INTERFACE__COLLAR">
    <visual>
      <origin rpy="0 0 0" xyz="0 0 0.005"/>
      <geometry>
        <cylinder length="0.01" radius="0.026"/>
      </geometry>
      <material name="black">
        <color rgba="0 0 0 1"/>
      </material>
    </visual>
  </link>
  <joint name="elbow__leg2__INPUT_INTERFACE__COLLAR_JOINT" type="fixed">
    <parent link="elbow__leg2__INPUT_INTERFACE"/>
    <child link="elbow__leg2__INPUT_INTERFACE__COLLAR"/>
  </joint>
  <joint name="elbow__leg2__MID_ELBOW_JOINT" type="fixed">
    <parent link="elbow__leg2__INPUT_INTERFACE"/>
    <child link="elbow__leg2__AFTER_CORNER_BODY"/>
    <origin rpy="-1.57079632679 0 3.14159265359" xyz="0 0 0.0445"/>
  </joint>
  <link name="elbow__leg2__AFTER_CORNER_BODY">
    <visual>
      <origin rpy="0 0 0" xyz="0 0 0.0857"/>
      <geometry>
        <cylinder length="0.1206" radius=".0254"/>
      </geometry>
      <material name="silver">
        <color rgba="0.6 0.6 0.6 1"/>
      </material>
    </visual>
    <collision>
      <origin rpy="0 0 0" xyz="0 0 0.0857"/>
      <geometry>
        <cylinder length="0.1206" radius=".0254"/>
      </geometry>
    </collision>
    <inertial>
      <origin rpy="0 0 0" xyz="0 0 0.0857"/>
      <mass value=".065"/>
      <inertia ixx="1.24599041667e-05" ixy="0" ixz="0" iyy="1.24599041667e-05" iyz="0" izz="2.09677e-05"/>
    </inertial>
  </link>
  <joint name="elbow__leg2__OUTPUT_INTERFACE" type="fixed">
    <parent link="elbow__leg2__AFTER_CORNER_BODY"/>
    <child link="foot__leg2__INPUT_INTERFACE"/>
    <origin rpy="0 0 -1.57079632679" xyz="0 0 0.146"/>
  </joint>
  <!--TODO: check dimensions -->
  <link name="foot__leg2__INPUT_INTERFACE">
    <visual>
      <origin rpy="0 0 0" xyz="0 0 0"/>
      <geometry>
        <sphere radius=".0254"/>
      </geometry>
      <material name="black">
        <color rgba="0 0 0 1"/>
      </material>
    </visual>
    <collision>
      <origin rpy="0 0 0" xyz="0 0 0"/>
      <geometry>
        <sphere radius=".0254"/>
      </geometry>
    </collision>
  </link>
  <link name="SA036__MoJo__INPUT_INTERFACE">
    <visual>
      <origin rpy="1.57075 0 0" xyz="0 0 0.035"/>
      <geometry>
        <mesh filename="package://snake_monster/meshes/rotary_input.stl"/>
      </geometry>
      <material name="red">
        <color rgba=".82 0.06 0.06 1"/>
      </material>
    </visual>
    <collision>
      <origin rpy="0 0 0" xyz="0 0 0.0183"/>
      <geometry>
        <cylinder length="0.033" radius="0.026"/>
      </geometry>
    </collision>
    <inertial>
      <origin rpy="0 0 0" xyz="0 0 0.0366"/>
      <mass value="0.103"/>
      <inertia ixx="5.4796e-05" ixy="0" ixz="0" iyy="5.4796e-05" iyz="0" izz="3.4814e-05"/>
    </inertial>
  </link>
  <link name="SA036__MoJo__INPUT_INTERFACE__COLLAR">
    <visual>
      <origin rpy="0 0 0" xyz="0 0 0.005"/>
      <geometry>
        <cylinder length="0.01" radius="0.026"/>
      </geometry>
      <material name="black">
        <color rgba="0 0 0 1"/>
      </material>
    </visual>
  </link>
  <joint name="SA036__MoJo__INPUT_INTERFACE__COLLAR_JOINT" type="fixed">
    <parent link="SA036__MoJo__INPUT_INTERFACE"/>
    <child link="SA036__MoJo__INPUT_INTERFACE__COLLAR"/>
  </joint>
  <joint name="SA036__MoJo" type="revolute">
    <parent link="SA036__MoJo__INPUT_INTERFACE"/>
    <child link="SA036__MoJo__OUTPUT_BODY"/>
    <origin rpy="0 0 0" xyz="0 0 0.0366"/>
    <axis xyz="0 1 0"/>
    <dynamics damping=".1" friction="0.2"/>
    <limit effort="7.0" lower="-1.57" upper="1.57" velocity="2.208932"/>
  </joint>
  <transmission name="SA036__MoJo_trans">
    <type>transmission_interface/SimpleTransmission</type>
    <joint name="SA036__MoJo">
      <hardwareInterface>EffortJointInterface</hardwareInterface>
    </joint>
    <actuator name="SA036__MoJo_motor">
      <hardwareInterface>EffortJointInterface</hardwareInterface>
      <mechanicalReduction>300</mechanicalReduction>
    </actuator>
  </transmission>
  <link name="SA036__MoJo__OUTPUT_BODY">
    <visual>
      <origin rpy="1.57075 0 0" xyz="0 0 0"/>
      <geometry>
        <mesh filename="package://snake_monster/meshes/rotary_output.stl"/>
        <!-- <cylinder radius=".0025" length=".1" /> -->
      </geometry>
      <material name="red">
        <color rgba=".82 0.06 0.06 1"/>
      </material>
    </visual>
    <collision>
      <origin rpy="0 0 0" xyz="0 0 0.0183"/>
      <geometry>
        <cylinder length="0.033" radius="0.026"/>
      </geometry>
    </collision>
    <inertial>
      <origin rpy="0 0 0" xyz="0 0 0"/>
      <mass value="0.103"/>
      <inertia ixx="5.4796e-05" ixy="0" ixz="0" iyy="5.4796e-05" iyz="0" izz="3.4814e-05"/>
    </inertial>
  </link>
  <joint name="SA036__MoJo__OUTPUT_INTERFACE" type="fixed">
    <parent link="SA036__MoJo__OUTPUT_BODY"/>
    <child link="SA046__MoJo__INPUT_INTERFACE"/>
    <origin rpy="0 0 -1.57075" xyz="0 0 0.0273"/>
  </joint>
  <link name="SA046__MoJo__INPUT_INTERFACE">
    <visual>
      <origin rpy="1.57075 0 0" xyz="0 0 0.035"/>
      <geometry>
        <mesh filename="package://snake_monster/meshes/rotary_input.stl"/>
      </geometry>
      <material name="red">
        <color rgba=".82 0.06 0.06 1"/>
      </material>
    </visual>
    <collision>
      <origin rpy="0 0 0" xyz="0 0 0.0183"/>
      <geometry>
        <cylinder length="0.033" radius="0.026"/>
      </geometry>
    </collision>
    <inertial>
      <origin rpy="0 0 0" xyz="0 0 0.0366"/>
      <mass value="0.103"/>
      <inertia ixx="5.4796e-05" ixy="0" ixz="0" iyy="5.4796e-05" iyz="0" izz="3.4814e-05"/>
    </inertial>
  </link>
  <link name="SA046__MoJo__INPUT_INTERFACE__COLLAR">
    <visual>
      <origin rpy="0 0 0" xyz="0 0 0.005"/>
      <geometry>
        <cylinder length="0.01" radius="0.026"/>
      </geometry>
      <material name="black">
        <color rgba="0 0 0 1"/>
      </material>
    </visual>
  </link>
  <joint name="SA046__MoJo__INPUT_INTERFACE__COLLAR_JOINT" type="fixed">
    <parent link="SA046__MoJo__INPUT_INTERFACE"/>
    <child link="SA046__MoJo__INPUT_INTERFACE__COLLAR"/>
  </joint>
  <joint name="SA046__MoJo" type="revolute">
    <parent link="SA046__MoJo__INPUT_INTERFACE"/>
    <child link="SA046__MoJo__OUTPUT_BODY"/>
    <origin rpy="0 0 0" xyz="0 0 0.0366"/>
    <axis xyz="0 1 0"/>
    <dynamics damping=".1" friction="0.2"/>
    <limit effort="7.0" lower="-1.57" upper="1.57" velocity="2.208932"/>
  </joint>
  <transmission name="SA046__MoJo_trans">
    <type>transmission_interface/SimpleTransmission</type>
    <joint name="SA046__MoJo">
      <hardwareInterface>EffortJointInterface</hardwareInterface>
    </joint>
    <actuator name="SA046__MoJo_motor">
      <hardwareInterface>EffortJointInterface</hardwareInterface>
      <mechanicalReduction>300</mechanicalReduction>
    </actuator>
  </transmission>
  <link name="SA046__MoJo__OUTPUT_BODY">
    <visual>
      <origin rpy="1.57075 0 0" xyz="0 0 0"/>
      <geometry>
        <mesh filename="package://snake_monster/meshes/rotary_output.stl"/>
        <!-- <cylinder radius=".0025" length=".1" /> -->
      </geometry>
      <material name="red">
        <color rgba=".82 0.06 0.06 1"/>
      </material>
    </visual>
    <collision>
      <origin rpy="0 0 0" xyz="0 0 0.0183"/>
      <geometry>
        <cylinder length="0.033" radius="0.026"/>
      </geometry>
    </collision>
    <inertial>
      <origin rpy="0 0 0" xyz="0 0 0"/>
      <mass value="0.103"/>
      <inertia ixx="5.4796e-05" ixy="0" ixz="0" iyy="5.4796e-05" iyz="0" izz="3.4814e-05"/>
    </inertial>
  </link>
  <joint name="SA046__MoJo__OUTPUT_INTERFACE" type="fixed">
    <parent link="SA046__MoJo__OUTPUT_BODY"/>
    <child link="extender__leg3__INPUT_INTERFACE"/>
    <origin rpy="0 0 -1.57075" xyz="0 0 0.0273"/>
  </joint>
  <link name="extender__leg3__INPUT_INTERFACE">
    <visual>
      <origin rpy="0 0 0" xyz="0 0 0.025"/>
      <geometry>
        <cylinder length="0.05" radius=".0254"/>
      </geometry>
      <material name="silver">
        <color rgba="0.6 0.6 0.6 1"/>
      </material>
    </visual>
    <collision>
      <origin rpy="0 0 0" xyz="0 0 0.025"/>
      <geometry>
        <cylinder length="0.05" radius=".0254"/>
      </geometry>
    </collision>
    <inertial>
      <origin rpy="0 0 0" xyz="0 0 0.025"/>
      <mass value=".05"/>
      <inertia ixx="2.50134116667e-05" ixy="0" ixz="0" iyy="2.50134116667e-05" iyz="0" izz="2.919349e-05"/>
    </inertial>
  </link>
  <joint name="extender__leg3__OUTPUT_INTERFACE" type="fixed">
    <parent link="extender__leg3__INPUT_INTERFACE"/>
    <child link="SA038__MoJo__INPUT_INTERFACE"/>
    <origin rpy="0 0 1.57079632679" xyz="0 0 0.05"/>
  </joint>
  <link name="extender__leg3__INPUT_INTERFACE__COLLAR">
    <visual>
      <origin rpy="0 0 0" xyz="0 0 0.005"/>
      <geometry>
        <cylinder length="0.01" radius="0.026"/>
      </geometry>
      <material name="black">
        <color rgba="0 0 0 1"/>
      </material>
    </visual>
  </link>
  <joint name="extender__leg3__INPUT_INTERFACE__COLLAR_JOINT" type="fixed">
    <parent link="extender__leg3__INPUT_INTERFACE"/>
    <child link="extender__leg3__INPUT_INTERFACE__COLLAR"/>
  </joint>
  <link name="SA038__MoJo__INPUT_INTERFACE">
    <visual>
      <origin rpy="1.57075 0 0" xyz="0 0 0.035"/>
      <geometry>
        <mesh filename="package://snake_monster/meshes/rotary_input.stl"/>
      </geometry>
      <material name="red">
        <color rgba=".82 0.06 0.06 1"/>
      </material>
    </visual>
    <collision>
      <origin rpy="0 0 0" xyz="0 0 0.0183"/>
      <geometry>
        <cylinder length="0.033" radius="0.026"/>
      </geometry>
    </collision>
    <inertial>
      <origin rpy="0 0 0" xyz="0 0 0.0366"/>
      <mass value="0.103"/>
      <inertia ixx="5.4796e-05" ixy="0" ixz="0" iyy="5.4796e-05" iyz="0" izz="3.4814e-05"/>
    </inertial>
  </link>
  <link name="SA038__MoJo__INPUT_INTERFACE__COLLAR">
    <visual>
      <origin rpy="0 0 0" xyz="0 0 0.005"/>
      <geometry>
        <cylinder length="0.01" radius="0.026"/>
      </geometry>
      <material name="black">
        <color rgba="0 0 0 1"/>
      </material>
    </visual>
  </link>
  <joint name="SA038__MoJo__INPUT_INTERFACE__COLLAR_JOINT" type="fixed">
    <parent link="SA038__MoJo__INPUT_INTERFACE"/>
    <child link="SA038__MoJo__INPUT_INTERFACE__COLLAR"/>
  </joint>
  <joint name="SA038__MoJo" type="revolute">
    <parent link="SA038__MoJo__INPUT_INTERFACE"/>
    <child link="SA038__MoJo__OUTPUT_BODY"/>
    <origin rpy="0 0 0" xyz="0 0 0.0366"/>
    <axis xyz="0 1 0"/>
    <dynamics damping=".1" friction="0.2"/>
    <limit effort="7.0" lower="-1.57" upper="1.57" velocity="2.208932"/>
  </joint>
  <transmission name="SA038__MoJo_trans">
    <type>transmission_interface/SimpleTransmission</type>
    <joint name="SA038__MoJo">
      <hardwareInterface>EffortJointInterface</hardwareInterface>
    </joint>
    <actuator name="SA038__MoJo_motor">
      <hardwareInterface>EffortJointInterface</hardwareInterface>
      <mechanicalReduction>300</mechanicalReduction>
    </actuator>
  </transmission>
  <link name="SA038__MoJo__OUTPUT_BODY">
    <visual>
      <origin rpy="1.57075 0 0" xyz="0 0 0"/>
      <geometry>
        <mesh filename="package://snake_monster/meshes/rotary_output.stl"/>
        <!-- <cylinder radius=".0025" length=".1" /> -->
      </geometry>
      <material name="red">
        <color rgba=".82 0.06 0.06 1"/>
      </material>
    </visual>
    <collision>
      <origin rpy="0 0 0" xyz="0 0 0.0183"/>
      <geometry>
        <cylinder length="0.033" radius="0.026"/>
      </geometry>
    </collision>
    <inertial>
      <origin rpy="0 0 0" xyz="0 0 0"/>
      <mass value="0.103"/>
      <inertia ixx="5.4796e-05" ixy="0" ixz="0" iyy="5.4796e-05" iyz="0" izz="3.4814e-05"/>
    </inertial>
  </link>
  <joint name="SA038__MoJo__OUTPUT_INTERFACE" type="fixed">
    <parent link="SA038__MoJo__OUTPUT_BODY"/>
    <child link="elbow__leg3__INPUT_INTERFACE"/>
    <origin rpy="0 0 -1.57075" xyz="0 0 0.0273"/>
  </joint>
  <link name="elbow__leg3__INPUT_INTERFACE">
    <visual>
      <origin rpy="0 0 0" xyz="0 0 0.00955"/>
      <geometry>
        <cylinder length="0.0191" radius=".0254"/>
      </geometry>
      <material name="silver">
        <color rgba="0.6 0.6 0.6 1"/>
      </material>
    </visual>
    <visual>
      <origin rpy="1.57075 0 3.14159265359" xyz="0.0274 -0.0782 0.0121"/>
      <geometry>
        <mesh filename="package://snake_monster/meshes/elbow_corner.stl"/>
      </geometry>
      <material name="silver">
        <color rgba="0.6 0.6 0.6 1"/>
      </material>
    </visual>
    <collision>
      <origin rpy="0 0 0" xyz="0 0 0.00955"/>
      <geometry>
        <cylinder length="0.0191" radius=".0254"/>
      </geometry>
    </collision>
    <collision>
      <origin rpy="0 0 0" xyz="0 -0.01 0.0311"/>
      <geometry>
        <sphere radius="0.0191"/>
      </geometry>
    </collision>
    <inertial>
      <origin rpy="0 0 0" xyz="0 0 0.0391"/>
      <mass value=".045"/>
      <inertia ixx="8.6260875e-06" ixy="0" ixz="0" iyy="8.6260875e-06" iyz="0" izz="1.45161e-05"/>
    </inertial>
  </link>
  <link name="elbow__leg3__INPUT_INTERFACE__COLLAR">
    <visual>
      <origin rpy="0 0 0" xyz="0 0 0.005"/>
      <geometry>
        <cylinder length="0.01" radius="0.026"/>
      </geometry>
      <material name="black">
        <color rgba="0 0 0 1"/>
      </material>
    </visual>
  </link>
  <joint name="elbow__leg3__INPUT_INTERFACE__COLLAR_JOINT" type="fixed">
    <parent link="elbow__leg3__INPUT_INTERFACE"/>
    <child link="elbow__leg3__INPUT_INTERFACE__COLLAR"/>
  </joint>
  <joint name="elbow__leg3__MID_ELBOW_JOINT" type="fixed">
    <parent link="elbow__leg3__INPUT_INTERFACE"/>
    <child link="elbow__leg3__AFTER_CORNER_BODY"/>
    <origin rpy="-1.57079632679 0 3.14159265359" xyz="0 0 0.0445"/>
  </joint>
  <link name="elbow__leg3__AFTER_CORNER_BODY">
    <visual>
      <origin rpy="0 0 0" xyz="0 0 0.0857"/>
      <geometry>
        <cylinder length="0.1206" radius=".0254"/>
      </geometry>
      <material name="silver">
        <color rgba="0.6 0.6 0.6 1"/>
      </material>
    </visual>
    <collision>
      <origin rpy="0 0 0" xyz="0 0 0.0857"/>
      <geometry>
        <cylinder length="0.1206" radius=".0254"/>
      </geometry>
    </collision>
    <inertial>
      <origin rpy="0 0 0" xyz="0 0 0.0857"/>
      <mass value=".065"/>
      <inertia ixx="1.24599041667e-05" ixy="0" ixz="0" iyy="1.24599041667e-05" iyz="0" izz="2.09677e-05"/>
    </inertial>
  </link>
  <joint name="elbow__leg3__OUTPUT_INTERFACE" type="fixed">
    <parent link="elbow__leg3__AFTER_CORNER_BODY"/>
    <child link="foot__leg3__INPUT_INTERFACE"/>
    <origin rpy="0 0 -1.57079632679" xyz="0 0 0.146"/>
  </joint>
  <!--TODO: check dimensions -->
  <link name="foot__leg3__INPUT_INTERFACE">
    <visual>
      <origin rpy="0 0 0" xyz="0 0 0"/>
      <geometry>
        <sphere radius=".0254"/>
      </geometry>
      <material name="black">
        <color rgba="0 0 0 1"/>
      </material>
    </visual>
    <collision>
      <origin rpy="0 0 0" xyz="0 0 0"/>
      <geometry>
        <sphere radius=".0254"/>
      </geometry>
    </collision>
  </link>
  <link name="SA022__MoJo__INPUT_INTERFACE">
    <visual>
      <origin rpy="1.57075 0 0" xyz="0 0 0.035"/>
      <geometry>
        <mesh filename="package://snake_monster/meshes/rotary_input.stl"/>
      </geometry>
      <material name="red">
        <color rgba=".82 0.06 0.06 1"/>
      </material>
    </visual>
    <collision>
      <origin rpy="0 0 0" xyz="0 0 0.0183"/>
      <geometry>
        <cylinder length="0.033" radius="0.026"/>
      </geometry>
    </collision>
    <inertial>
      <origin rpy="0 0 0" xyz="0 0 0.0366"/>
      <mass value="0.103"/>
      <inertia ixx="5.4796e-05" ixy="0" ixz="0" iyy="5.4796e-05" iyz="0" izz="3.4814e-05"/>
    </inertial>
  </link>
  <link name="SA022__MoJo__INPUT_INTERFACE__COLLAR">
    <visual>
      <origin rpy="0 0 0" xyz="0 0 0.005"/>
      <geometry>
        <cylinder length="0.01" radius="0.026"/>
      </geometry>
      <material name="black">
        <color rgba="0 0 0 1"/>
      </material>
    </visual>
  </link>
  <joint name="SA022__MoJo__INPUT_INTERFACE__COLLAR_JOINT" type="fixed">
    <parent link="SA022__MoJo__INPUT_INTERFACE"/>
    <child link="SA022__MoJo__INPUT_INTERFACE__COLLAR"/>
  </joint>
  <joint name="SA022__MoJo" type="revolute">
    <parent link="SA022__MoJo__INPUT_INTERFACE"/>
    <child link="SA022__MoJo__OUTPUT_BODY"/>
    <origin rpy="0 0 0" xyz="0 0 0.0366"/>
    <axis xyz="0 1 0"/>
    <dynamics damping=".1" friction="0.2"/>
    <limit effort="7.0" lower="-1.57" upper="1.57" velocity="2.208932"/>
  </joint>
  <transmission name="SA022__MoJo_trans">
    <type>transmission_interface/SimpleTransmission</type>
    <joint name="SA022__MoJo">
      <hardwareInterface>EffortJointInterface</hardwareInterface>
    </joint>
    <actuator name="SA022__MoJo_motor">
      <hardwareInterface>EffortJointInterface</hardwareInterface>
      <mechanicalReduction>300</mechanicalReduction>
    </actuator>
  </transmission>
  <link name="SA022__MoJo__OUTPUT_BODY">
    <visual>
      <origin rpy="1.57075 0 0" xyz="0 0 0"/>
      <geometry>
        <mesh filename="package://snake_monster/meshes/rotary_output.stl"/>
        <!-- <cylinder radius=".0025" length=".1" /> -->
      </geometry>
      <material name="red">
        <color rgba=".82 0.06 0.06 1"/>
      </material>
    </visual>
    <collision>
      <origin rpy="0 0 0" xyz="0 0 0.0183"/>
      <geometry>
        <cylinder length="0.033" radius="0.026"/>
      </geometry>
    </collision>
    <inertial>
      <origin rpy="0 0 0" xyz="0 0 0"/>
      <mass value="0.103"/>
      <inertia ixx="5.4796e-05" ixy="0" ixz="0" iyy="5.4796e-05" iyz="0" izz="3.4814e-05"/>
    </inertial>
  </link>
  <joint name="SA022__MoJo__OUTPUT_INTERFACE" type="fixed">
    <parent link="SA022__MoJo__OUTPUT_BODY"/>
    <child link="SA050__MoJo__INPUT_INTERFACE"/>
    <origin rpy="0 0 -1.57075" xyz="0 0 0.0273"/>
  </joint>
  <link name="SA050__MoJo__INPUT_INTERFACE">
    <visual>
      <origin rpy="1.57075 0 0" xyz="0 0 0.035"/>
      <geometry>
        <mesh filename="package://snake_monster/meshes/rotary_input.stl"/>
      </geometry>
      <material name="red">
        <color rgba=".82 0.06 0.06 1"/>
      </material>
    </visual>
    <collision>
      <origin rpy="0 0 0" xyz="0 0 0.0183"/>
      <geometry>
        <cylinder length="0.033" radius="0.026"/>
      </geometry>
    </collision>
    <inertial>
      <origin rpy="0 0 0" xyz="0 0 0.0366"/>
      <mass value="0.103"/>
      <inertia ixx="5.4796e-05" ixy="0" ixz="0" iyy="5.4796e-05" iyz="0" izz="3.4814e-05"/>
    </inertial>
  </link>
  <link name="SA050__MoJo__INPUT_INTERFACE__COLLAR">
    <visual>
      <origin rpy="0 0 0" xyz="0 0 0.005"/>
      <geometry>
        <cylinder length="0.01" radius="0.026"/>
      </geometry>
      <material name="black">
        <color rgba="0 0 0 1"/>
      </material>
    </visual>
  </link>
  <joint name="SA050__MoJo__INPUT_INTERFACE__COLLAR_JOINT" type="fixed">
    <parent link="SA050__MoJo__INPUT_INTERFACE"/>
    <child link="SA050__MoJo__INPUT_INTERFACE__COLLAR"/>
  </joint>
  <joint name="SA050__MoJo" type="revolute">
    <parent link="SA050__MoJo__INPUT_INTERFACE"/>
    <child link="SA050__MoJo__OUTPUT_BODY"/>
    <origin rpy="0 0 0" xyz="0 0 0.0366"/>
    <axis xyz="0 1 0"/>
    <dynamics damping=".1" friction="0.2"/>
    <limit effort="7.0" lower="-1.57" upper="1.57" velocity="2.208932"/>
  </joint>
  <transmission name="SA050__MoJo_trans">
    <type>transmission_interface/SimpleTransmission</type>
    <joint name="SA050__MoJo">
      <hardwareInterface>EffortJointInterface</hardwareInterface>
    </joint>
    <actuator name="SA050__MoJo_motor">
      <hardwareInterface>EffortJointInterface</hardwareInterface>
      <mechanicalReduction>300</mechanicalReduction>
    </actuator>
  </transmission>
  <link name="SA050__MoJo__OUTPUT_BODY">
    <visual>
      <origin rpy="1.57075 0 0" xyz="0 0 0"/>
      <geometry>
        <mesh filename="package://snake_monster/meshes/rotary_output.stl"/>
        <!-- <cylinder radius=".0025" length=".1" /> -->
      </geometry>
      <material name="red">
        <color rgba=".82 0.06 0.06 1"/>
      </material>
    </visual>
    <collision>
      <origin rpy="0 0 0" xyz="0 0 0.0183"/>
      <geometry>
        <cylinder length="0.033" radius="0.026"/>
      </geometry>
    </collision>
    <inertial>
      <origin rpy="0 0 0" xyz="0 0 0"/>
      <mass value="0.103"/>
      <inertia ixx="5.4796e-05" ixy="0" ixz="0" iyy="5.4796e-05" iyz="0" izz="3.4814e-05"/>
    </inertial>
  </link>
  <joint name="SA050__MoJo__OUTPUT_INTERFACE" type="fixed">
    <parent link="SA050__MoJo__OUTPUT_BODY"/>
    <child link="extender__leg4__INPUT_INTERFACE"/>
    <origin rpy="0 0 -1.57075" xyz="0 0 0.0273"/>
  </joint>
  <link name="extender__leg4__INPUT_INTERFACE">
    <visual>
      <origin rpy="0 0 0" xyz="0 0 0.025"/>
      <geometry>
        <cylinder length="0.05" radius=".0254"/>
      </geometry>
      <material name="silver">
        <color rgba="0.6 0.6 0.6 1"/>
      </material>
    </visual>
    <collision>
      <origin rpy="0 0 0" xyz="0 0 0.025"/>
      <geometry>
        <cylinder length="0.05" radius=".0254"/>
      </geometry>
    </collision>
    <inertial>
      <origin rpy="0 0 0" xyz="0 0 0.025"/>
      <mass value=".05"/>
      <inertia ixx="2.50134116667e-05" ixy="0" ixz="0" iyy="2.50134116667e-05" iyz="0" izz="2.919349e-05"/>
    </inertial>
  </link>
  <joint name="extender__leg4__OUTPUT_INTERFACE" type="fixed">
    <parent link="extender__leg4__INPUT_INTERFACE"/>
    <child link="SA031__MoJo__INPUT_INTERFACE"/>
    <origin rpy="0 0 1.57079632679" xyz="0 0 0.05"/>
  </joint>
  <link name="extender__leg4__INPUT_INTERFACE__COLLAR">
    <visual>
      <origin rpy="0 0 0" xyz="0 0 0.005"/>
      <geometry>
        <cylinder length="0.01" radius="0.026"/>
      </geometry>
      <material name="black">
        <color rgba="0 0 0 1"/>
      </material>
    </visual>
  </link>
  <joint name="extender__leg4__INPUT_INTERFACE__COLLAR_JOINT" type="fixed">
    <parent link="extender__leg4__INPUT_INTERFACE"/>
    <child link="extender__leg4__INPUT_INTERFACE__COLLAR"/>
  </joint>
  <link name="SA031__MoJo__INPUT_INTERFACE">
    <visual>
      <origin rpy="1.57075 0 0" xyz="0 0 0.035"/>
      <geometry>
        <mesh filename="package://snake_monster/meshes/rotary_input.stl"/>
      </geometry>
      <material name="red">
        <color rgba=".82 0.06 0.06 1"/>
      </material>
    </visual>
    <collision>
      <origin rpy="0 0 0" xyz="0 0 0.0183"/>
      <geometry>
        <cylinder length="0.033" radius="0.026"/>
      </geometry>
    </collision>
    <inertial>
      <origin rpy="0 0 0" xyz="0 0 0.0366"/>
      <mass value="0.103"/>
      <inertia ixx="5.4796e-05" ixy="0" ixz="0" iyy="5.4796e-05" iyz="0" izz="3.4814e-05"/>
    </inertial>
  </link>
  <link name="SA031__MoJo__INPUT_INTERFACE__COLLAR">
    <visual>
      <origin rpy="0 0 0" xyz="0 0 0.005"/>
      <geometry>
        <cylinder length="0.01" radius="0.026"/>
      </geometry>
      <material name="black">
        <color rgba="0 0 0 1"/>
      </material>
    </visual>
  </link>
  <joint name="SA031__MoJo__INPUT_INTERFACE__COLLAR_JOINT" type="fixed">
    <parent link="SA031__MoJo__INPUT_INTERFACE"/>
    <child link="SA031__MoJo__INPUT_INTERFACE__COLLAR"/>
  </joint>
  <joint name="SA031__MoJo" type="revolute">
    <parent link="SA031__MoJo__INPUT_INTERFACE"/>
    <child link="SA031__MoJo__OUTPUT_BODY"/>
    <origin rpy="0 0 0" xyz="0 0 0.0366"/>
    <axis xyz="0 1 0"/>
    <dynamics damping=".1" friction="0.2"/>
    <limit effort="7.0" lower="-1.57" upper="1.57" velocity="2.208932"/>
  </joint>
  <transmission name="SA031__MoJo_trans">
    <type>transmission_interface/SimpleTransmission</type>
    <joint name="SA031__MoJo">
      <hardwareInterface>EffortJointInterface</hardwareInterface>
    </joint>
    <actuator name="SA031__MoJo_motor">
      <hardwareInterface>EffortJointInterface</hardwareInterface>
      <mechanicalReduction>300</mechanicalReduction>
    </actuator>
  </transmission>
  <link name="SA031__MoJo__OUTPUT_BODY">
    <visual>
      <origin rpy="1.57075 0 0" xyz="0 0 0"/>
      <geometry>
        <mesh filename="package://snake_monster/meshes/rotary_output.stl"/>
        <!-- <cylinder radius=".0025" length=".1" /> -->
      </geometry>
      <material name="red">
        <color rgba=".82 0.06 0.06 1"/>
      </material>
    </visual>
    <collision>
      <origin rpy="0 0 0" xyz="0 0 0.0183"/>
      <geometry>
        <cylinder length="0.033" radius="0.026"/>
      </geometry>
    </collision>
    <inertial>
      <origin rpy="0 0 0" xyz="0 0 0"/>
      <mass value="0.103"/>
      <inertia ixx="5.4796e-05" ixy="0" ixz="0" iyy="5.4796e-05" iyz="0" izz="3.4814e-05"/>
    </inertial>
  </link>
  <joint name="SA031__MoJo__OUTPUT_INTERFACE" type="fixed">
    <parent link="SA031__MoJo__OUTPUT_BODY"/>
    <child link="elbow__leg4__INPUT_INTERFACE"/>
    <origin rpy="0 0 -1.57075" xyz="0 0 0.0273"/>
  </joint>
  <link name="elbow__leg4__INPUT_INTERFACE">
    <visual>
      <origin rpy="0 0 0" xyz="0 0 0.00955"/>
      <geometry>
        <cylinder length="0.0191" radius=".0254"/>
      </geometry>
      <material name="silver">
        <color rgba="0.6 0.6 0.6 1"/>
      </material>
    </visual>
    <visual>
      <origin rpy="1.57075 0 3.14159265359" xyz="0.0274 -0.0782 0.0121"/>
      <geometry>
        <mesh filename="package://snake_monster/meshes/elbow_corner.stl"/>
      </geometry>
      <material name="silver">
        <color rgba="0.6 0.6 0.6 1"/>
      </material>
    </visual>
    <collision>
      <origin rpy="0 0 0" xyz="0 0 0.00955"/>
      <geometry>
        <cylinder length="0.0191" radius=".0254"/>
      </geometry>
    </collision>
    <collision>
      <origin rpy="0 0 0" xyz="0 -0.01 0.0311"/>
      <geometry>
        <sphere radius="0.0191"/>
      </geometry>
    </collision>
    <inertial>
      <origin rpy="0 0 0" xyz="0 0 0.0391"/>
      <mass value=".045"/>
      <inertia ixx="8.6260875e-06" ixy="0" ixz="0" iyy="8.6260875e-06" iyz="0" izz="1.45161e-05"/>
    </inertial>
  </link>
  <link name="elbow__leg4__INPUT_INTERFACE__COLLAR">
    <visual>
      <origin rpy="0 0 0" xyz="0 0 0.005"/>
      <geometry>
        <cylinder length="0.01" radius="0.026"/>
      </geometry>
      <material name="black">
        <color rgba="0 0 0 1"/>
      </material>
    </visual>
  </link>
  <joint name="elbow__leg4__INPUT_INTERFACE__COLLAR_JOINT" type="fixed">
    <parent link="elbow__leg4__INPUT_INTERFACE"/>
    <child link="elbow__leg4__INPUT_INTERFACE__COLLAR"/>
  </joint>
  <joint name="elbow__leg4__MID_ELBOW_JOINT" type="fixed">
    <parent link="elbow__leg4__INPUT_INTERFACE"/>
    <child link="elbow__leg4__AFTER_CORNER_BODY"/>
    <origin rpy="-1.57079632679 0 3.14159265359" xyz="0 0 0.0445"/>
  </joint>
  <link name="elbow__leg4__AFTER_CORNER_BODY">
    <visual>
      <origin rpy="0 0 0" xyz="0 0 0.0857"/>
      <geometry>
        <cylinder length="0.1206" radius=".0254"/>
      </geometry>
      <material name="silver">
        <color rgba="0.6 0.6 0.6 1"/>
      </material>
    </visual>
    <collision>
      <origin rpy="0 0 0" xyz="0 0 0.0857"/>
      <geometry>
        <cylinder length="0.1206" radius=".0254"/>
      </geometry>
    </collision>
    <inertial>
      <origin rpy="0 0 0" xyz="0 0 0.0857"/>
      <mass value=".065"/>
      <inertia ixx="1.24599041667e-05" ixy="0" ixz="0" iyy="1.24599041667e-05" iyz="0" izz="2.09677e-05"/>
    </inertial>
  </link>
  <joint name="elbow__leg4__OUTPUT_INTERFACE" type="fixed">
    <parent link="elbow__leg4__AFTER_CORNER_BODY"/>
    <child link="foot__leg4__INPUT_INTERFACE"/>
    <origin rpy="0 0 -1.57079632679" xyz="0 0 0.146"/>
  </joint>
  <!--TODO: check dimensions -->
  <link name="foot__leg4__INPUT_INTERFACE">
    <visual>
      <origin rpy="0 0 0" xyz="0 0 0"/>
      <geometry>
        <sphere radius=".0254"/>
      </geometry>
      <material name="black">
        <color rgba="0 0 0 1"/>
      </material>
    </visual>
    <collision>
      <origin rpy="0 0 0" xyz="0 0 0"/>
      <geometry>
        <sphere radius=".0254"/>
      </geometry>
    </collision>
  </link>
  <link name="SA002__MoJo__INPUT_INTERFACE">
    <visual>
      <origin rpy="1.57075 0 0" xyz="0 0 0.035"/>
      <geometry>
        <mesh filename="package://snake_monster/meshes/rotary_input.stl"/>
      </geometry>
      <material name="red">
        <color rgba=".82 0.06 0.06 1"/>
      </material>
    </visual>
    <collision>
      <origin rpy="0 0 0" xyz="0 0 0.0183"/>
      <geometry>
        <cylinder length="0.033" radius="0.026"/>
      </geometry>
    </collision>
    <inertial>
      <origin rpy="0 0 0" xyz="0 0 0.0366"/>
      <mass value="0.103"/>
      <inertia ixx="5.4796e-05" ixy="0" ixz="0" iyy="5.4796e-05" iyz="0" izz="3.4814e-05"/>
    </inertial>
  </link>
  <link name="SA002__MoJo__INPUT_INTERFACE__COLLAR">
    <visual>
      <origin rpy="0 0 0" xyz="0 0 0.005"/>
      <geometry>
        <cylinder length="0.01" radius="0.026"/>
      </geometry>
      <material name="black">
        <color rgba="0 0 0 1"/>
      </material>
    </visual>
  </link>
  <joint name="SA002__MoJo__INPUT_INTERFACE__COLLAR_JOINT" type="fixed">
    <parent link="SA002__MoJo__INPUT_INTERFACE"/>
    <child link="SA002__MoJo__INPUT_INTERFACE__COLLAR"/>
  </joint>
  <joint name="SA002__MoJo" type="revolute">
    <parent link="SA002__MoJo__INPUT_INTERFACE"/>
    <child link="SA002__MoJo__OUTPUT_BODY"/>
    <origin rpy="0 0 0" xyz="0 0 0.0366"/>
    <axis xyz="0 1 0"/>
    <dynamics damping=".1" friction="0.2"/>
    <limit effort="7.0" lower="-1.57" upper="1.57" velocity="2.208932"/>
  </joint>
  <transmission name="SA002__MoJo_trans">
    <type>transmission_interface/SimpleTransmission</type>
    <joint name="SA002__MoJo">
      <hardwareInterface>EffortJointInterface</hardwareInterface>
    </joint>
    <actuator name="SA002__MoJo_motor">
      <hardwareInterface>EffortJointInterface</hardwareInterface>
      <mechanicalReduction>300</mechanicalReduction>
    </actuator>
  </transmission>
  <link name="SA002__MoJo__OUTPUT_BODY">
    <visual>
      <origin rpy="1.57075 0 0" xyz="0 0 0"/>
      <geometry>
        <mesh filename="package://snake_monster/meshes/rotary_output.stl"/>
        <!-- <cylinder radius=".0025" length=".1" /> -->
      </geometry>
      <material name="red">
        <color rgba=".82 0.06 0.06 1"/>
      </material>
    </visual>
    <collision>
      <origin rpy="0 0 0" xyz="0 0 0.0183"/>
      <geometry>
        <cylinder length="0.033" radius="0.026"/>
      </geometry>
    </collision>
    <inertial>
      <origin rpy="0 0 0" xyz="0 0 0"/>
      <mass value="0.103"/>
      <inertia ixx="5.4796e-05" ixy="0" ixz="0" iyy="5.4796e-05" iyz="0" izz="3.4814e-05"/>
    </inertial>
  </link>
  <joint name="SA002__MoJo__OUTPUT_INTERFACE" type="fixed">
    <parent link="SA002__MoJo__OUTPUT_BODY"/>
    <child link="SA003__MoJo__INPUT_INTERFACE"/>
    <origin rpy="0 0 -1.57075" xyz="0 0 0.0273"/>
  </joint>
  <link name="SA003__MoJo__INPUT_INTERFACE">
    <visual>
      <origin rpy="1.57075 0 0" xyz="0 0 0.035"/>
      <geometry>
        <mesh filename="package://snake_monster/meshes/rotary_input.stl"/>
      </geometry>
      <material name="red">
        <color rgba=".82 0.06 0.06 1"/>
      </material>
    </visual>
    <collision>
      <origin rpy="0 0 0" xyz="0 0 0.0183"/>
      <geometry>
        <cylinder length="0.033" radius="0.026"/>
      </geometry>
    </collision>
    <inertial>
      <origin rpy="0 0 0" xyz="0 0 0.0366"/>
      <mass value="0.103"/>
      <inertia ixx="5.4796e-05" ixy="0" ixz="0" iyy="5.4796e-05" iyz="0" izz="3.4814e-05"/>
    </inertial>
  </link>
  <link name="SA003__MoJo__INPUT_INTERFACE__COLLAR">
    <visual>
      <origin rpy="0 0 0" xyz="0 0 0.005"/>
      <geometry>
        <cylinder length="0.01" radius="0.026"/>
      </geometry>
      <material name="black">
        <color rgba="0 0 0 1"/>
      </material>
    </visual>
  </link>
  <joint name="SA003__MoJo__INPUT_INTERFACE__COLLAR_JOINT" type="fixed">
    <parent link="SA003__MoJo__INPUT_INTERFACE"/>
    <child link="SA003__MoJo__INPUT_INTERFACE__COLLAR"/>
  </joint>
  <joint name="SA003__MoJo" type="revolute">
    <parent link="SA003__MoJo__INPUT_INTERFACE"/>
    <child link="SA003__MoJo__OUTPUT_BODY"/>
    <origin rpy="0 0 0" xyz="0 0 0.0366"/>
    <axis xyz="0 1 0"/>
    <dynamics damping=".1" friction="0.2"/>
    <limit effort="7.0" lower="-1.57" upper="1.57" velocity="2.208932"/>
  </joint>
  <transmission name="SA003__MoJo_trans">
    <type>transmission_interface/SimpleTransmission</type>
    <joint name="SA003__MoJo">
      <hardwareInterface>EffortJointInterface</hardwareInterface>
    </joint>
    <actuator name="SA003__MoJo_motor">
      <hardwareInterface>EffortJointInterface</hardwareInterface>
      <mechanicalReduction>300</mechanicalReduction>
    </actuator>
  </transmission>
  <link name="SA003__MoJo__OUTPUT_BODY">
    <visual>
      <origin rpy="1.57075 0 0" xyz="0 0 0"/>
      <geometry>
        <mesh filename="package://snake_monster/meshes/rotary_output.stl"/>
        <!-- <cylinder radius=".0025" length=".1" /> -->
      </geometry>
      <material name="red">
        <color rgba=".82 0.06 0.06 1"/>
      </material>
    </visual>
    <collision>
      <origin rpy="0 0 0" xyz="0 0 0.0183"/>
      <geometry>
        <cylinder length="0.033" radius="0.026"/>
      </geometry>
    </collision>
    <inertial>
      <origin rpy="0 0 0" xyz="0 0 0"/>
      <mass value="0.103"/>
      <inertia ixx="5.4796e-05" ixy="0" ixz="0" iyy="5.4796e-05" iyz="0" izz="3.4814e-05"/>
    </inertial>
  </link>
  <joint name="SA003__MoJo__OUTPUT_INTERFACE" type="fixed">
    <parent link="SA003__MoJo__OUTPUT_BODY"/>
    <child link="extender__leg5__INPUT_INTERFACE"/>
    <origin rpy="0 0 -1.57075" xyz="0 0 0.0273"/>
  </joint>
  <link name="extender__leg5__INPUT_INTERFACE">
    <visual>
      <origin rpy="0 0 0" xyz="0 0 0.025"/>
      <geometry>
        <cylinder length="0.05" radius=".0254"/>
      </geometry>
      <material name="silver">
        <color rgba="0.6 0.6 0.6 1"/>
      </material>
    </visual>
    <collision>
      <origin rpy="0 0 0" xyz="0 0 0.025"/>
      <geometry>
        <cylinder length="0.05" radius=".0254"/>
      </geometry>
    </collision>
    <inertial>
      <origin rpy="0 0 0" xyz="0 0 0.025"/>
      <mass value=".05"/>
      <inertia ixx="2.50134116667e-05" ixy="0" ixz="0" iyy="2.50134116667e-05" iyz="0" izz="2.919349e-05"/>
    </inertial>
  </link>
  <joint name="extender__leg5__OUTPUT_INTERFACE" type="fixed">
    <parent link="extender__leg5__INPUT_INTERFACE"/>
    <child link="SA048__MoJo__INPUT_INTERFACE"/>
    <origin rpy="0 0 1.57079632679" xyz="0 0 0.05"/>
  </joint>
  <link name="extender__leg5__INPUT_INTERFACE__COLLAR">
    <visual>
      <origin rpy="0 0 0" xyz="0 0 0.005"/>
      <geometry>
        <cylinder length="0.01" radius="0.026"/>
      </geometry>
      <material name="black">
        <color rgba="0 0 0 1"/>
      </material>
    </visual>
  </link>
  <joint name="extender__leg5__INPUT_INTERFACE__COLLAR_JOINT" type="fixed">
    <parent link="extender__leg5__INPUT_INTERFACE"/>
    <child link="extender__leg5__INPUT_INTERFACE__COLLAR"/>
  </joint>
  <link name="SA048__MoJo__INPUT_INTERFACE">
    <visual>
      <origin rpy="1.57075 0 0" xyz="0 0 0.035"/>
      <geometry>
        <mesh filename="package://snake_monster/meshes/rotary_input.stl"/>
      </geometry>
      <material name="red">
        <color rgba=".82 0.06 0.06 1"/>
      </material>
    </visual>
    <collision>
      <origin rpy="0 0 0" xyz="0 0 0.0183"/>
      <geometry>
        <cylinder length="0.033" radius="0.026"/>
      </geometry>
    </collision>
    <inertial>
      <origin rpy="0 0 0" xyz="0 0 0.0366"/>
      <mass value="0.103"/>
      <inertia ixx="5.4796e-05" ixy="0" ixz="0" iyy="5.4796e-05" iyz="0" izz="3.4814e-05"/>
    </inertial>
  </link>
  <link name="SA048__MoJo__INPUT_INTERFACE__COLLAR">
    <visual>
      <origin rpy="0 0 0" xyz="0 0 0.005"/>
      <geometry>
        <cylinder length="0.01" radius="0.026"/>
      </geometry>
      <material name="black">
        <color rgba="0 0 0 1"/>
      </material>
    </visual>
  </link>
  <joint name="SA048__MoJo__INPUT_INTERFACE__COLLAR_JOINT" type="fixed">
    <parent link="SA048__MoJo__INPUT_INTERFACE"/>
    <child link="SA048__MoJo__INPUT_INTERFACE__COLLAR"/>
  </joint>
  <joint name="SA048__MoJo" type="revolute">
    <parent link="SA048__MoJo__INPUT_INTERFACE"/>
    <child link="SA048__MoJo__OUTPUT_BODY"/>
    <origin rpy="0 0 0" xyz="0 0 0.0366"/>
    <axis xyz="0 1 0"/>
    <dynamics damping=".1" friction="0.2"/>
    <limit effort="7.0" lower="-1.57" upper="1.57" velocity="2.208932"/>
  </joint>
  <transmission name="SA048__MoJo_trans">
    <type>transmission_interface/SimpleTransmission</type>
    <joint name="SA048__MoJo">
      <hardwareInterface>EffortJointInterface</hardwareInterface>
    </joint>
    <actuator name="SA048__MoJo_motor">
      <hardwareInterface>EffortJointInterface</hardwareInterface>
      <mechanicalReduction>300</mechanicalReduction>
    </actuator>
  </transmission>
  <link name="SA048__MoJo__OUTPUT_BODY">
    <visual>
      <origin rpy="1.57075 0 0" xyz="0 0 0"/>
      <geometry>
        <mesh filename="package://snake_monster/meshes/rotary_output.stl"/>
        <!-- <cylinder radius=".0025" length=".1" /> -->
      </geometry>
      <material name="red">
        <color rgba=".82 0.06 0.06 1"/>
      </material>
    </visual>
    <collision>
      <origin rpy="0 0 0" xyz="0 0 0.0183"/>
      <geometry>
        <cylinder length="0.033" radius="0.026"/>
      </geometry>
    </collision>
    <inertial>
      <origin rpy="0 0 0" xyz="0 0 0"/>
      <mass value="0.103"/>
      <inertia ixx="5.4796e-05" ixy="0" ixz="0" iyy="5.4796e-05" iyz="0" izz="3.4814e-05"/>
    </inertial>
  </link>
  <joint name="SA048__MoJo__OUTPUT_INTERFACE" type="fixed">
    <parent link="SA048__MoJo__OUTPUT_BODY"/>
    <child link="elbow__leg5__INPUT_INTERFACE"/>
    <origin rpy="0 0 -1.57075" xyz="0 0 0.0273"/>
  </joint>
  <link name="elbow__leg5__INPUT_INTERFACE">
    <visual>
      <origin rpy="0 0 0" xyz="0 0 0.00955"/>
      <geometry>
        <cylinder length="0.0191" radius=".0254"/>
      </geometry>
      <material name="silver">
        <color rgba="0.6 0.6 0.6 1"/>
      </material>
    </visual>
    <visual>
      <origin rpy="1.57075 0 3.14159265359" xyz="0.0274 -0.0782 0.0121"/>
      <geometry>
        <mesh filename="package://snake_monster/meshes/elbow_corner.stl"/>
      </geometry>
      <material name="silver">
        <color rgba="0.6 0.6 0.6 1"/>
      </material>
    </visual>
    <collision>
      <origin rpy="0 0 0" xyz="0 0 0.00955"/>
      <geometry>
        <cylinder length="0.0191" radius=".0254"/>
      </geometry>
    </collision>
    <collision>
      <origin rpy="0 0 0" xyz="0 -0.01 0.0311"/>
      <geometry>
        <sphere radius="0.0191"/>
      </geometry>
    </collision>
    <inertial>
      <origin rpy="0 0 0" xyz="0 0 0.0391"/>
      <mass value=".045"/>
      <inertia ixx="8.6260875e-06" ixy="0" ixz="0" iyy="8.6260875e-06" iyz="0" izz="1.45161e-05"/>
    </inertial>
  </link>
  <link name="elbow__leg5__INPUT_INTERFACE__COLLAR">
    <visual>
      <origin rpy="0 0 0" xyz="0 0 0.005"/>
      <geometry>
        <cylinder length="0.01" radius="0.026"/>
      </geometry>
      <material name="black">
        <color rgba="0 0 0 1"/>
      </material>
    </visual>
  </link>
  <joint name="elbow__leg5__INPUT_INTERFACE__COLLAR_JOINT" type="fixed">
    <parent link="elbow__leg5__INPUT_INTERFACE"/>
    <child link="elbow__leg5__INPUT_INTERFACE__COLLAR"/>
  </joint>
  <joint name="elbow__leg5__MID_ELBOW_JOINT" type="fixed">
    <parent link="elbow__leg5__INPUT_INTERFACE"/>
    <child link="elbow__leg5__AFTER_CORNER_BODY"/>
    <origin rpy="-1.57079632679 0 3.14159265359" xyz="0 0 0.0445"/>
  </joint>
  <link name="elbow__leg5__AFTER_CORNER_BODY">
    <visual>
      <origin rpy="0 0 0" xyz="0 0 0.0857"/>
      <geometry>
        <cylinder length="0.1206" radius=".0254"/>
      </geometry>
      <material name="silver">
        <color rgba="0.6 0.6 0.6 1"/>
      </material>
    </visual>
    <collision>
      <origin rpy="0 0 0" xyz="0 0 0.0857"/>
      <geometry>
        <cylinder length="0.1206" radius=".0254"/>
      </geometry>
    </collision>
    <inertial>
      <origin rpy="0 0 0" xyz="0 0 0.0857"/>
      <mass value=".065"/>
      <inertia ixx="1.24599041667e-05" ixy="0" ixz="0" iyy="1.24599041667e-05" iyz="0" izz="2.09677e-05"/>
    </inertial>
  </link>
  <joint name="elbow__leg5__OUTPUT_INTERFACE" type="fixed">
    <parent link="elbow__leg5__AFTER_CORNER_BODY"/>
    <child link="foot__leg5__INPUT_INTERFACE"/>
    <origin rpy="0 0 -1.57079632679" xyz="0 0 0.146"/>
  </joint>
  <!--TODO: check dimensions -->
  <link name="foot__leg5__INPUT_INTERFACE">
    <visual>
      <origin rpy="0 0 0" xyz="0 0 0"/>
      <geometry>
        <sphere radius=".0254"/>
      </geometry>
      <material name="black">
        <color rgba="0 0 0 1"/>
      </material>
    </visual>
    <collision>
      <origin rpy="0 0 0" xyz="0 0 0"/>
      <geometry>
        <sphere radius=".0254"/>
      </geometry>
    </collision>
  </link>
  <link name="SA043__MoJo__INPUT_INTERFACE">
    <visual>
      <origin rpy="1.57075 0 0" xyz="0 0 0.035"/>
      <geometry>
        <mesh filename="package://snake_monster/meshes/rotary_input.stl"/>
      </geometry>
      <material name="red">
        <color rgba=".82 0.06 0.06 1"/>
      </material>
    </visual>
    <collision>
      <origin rpy="0 0 0" xyz="0 0 0.0183"/>
      <geometry>
        <cylinder length="0.033" radius="0.026"/>
      </geometry>
    </collision>
    <inertial>
      <origin rpy="0 0 0" xyz="0 0 0.0366"/>
      <mass value="0.103"/>
      <inertia ixx="5.4796e-05" ixy="0" ixz="0" iyy="5.4796e-05" iyz="0" izz="3.4814e-05"/>
    </inertial>
  </link>
  <link name="SA043__MoJo__INPUT_INTERFACE__COLLAR">
    <visual>
      <origin rpy="0 0 0" xyz="0 0 0.005"/>
      <geometry>
        <cylinder length="0.01" radius="0.026"/>
      </geometry>
      <material name="black">
        <color rgba="0 0 0 1"/>
      </material>
    </visual>
  </link>
  <joint name="SA043__MoJo__INPUT_INTERFACE__COLLAR_JOINT" type="fixed">
    <parent link="SA043__MoJo__INPUT_INTERFACE"/>
    <child link="SA043__MoJo__INPUT_INTERFACE__COLLAR"/>
  </joint>
  <joint name="SA043__MoJo" type="revolute">
    <parent link="SA043__MoJo__INPUT_INTERFACE"/>
    <child link="SA043__MoJo__OUTPUT_BODY"/>
    <origin rpy="0 0 0" xyz="0 0 0.0366"/>
    <axis xyz="0 1 0"/>
    <dynamics damping=".1" friction="0.2"/>
    <limit effort="7.0" lower="-1.57" upper="1.57" velocity="2.208932"/>
  </joint>
  <transmission name="SA043__MoJo_trans">
    <type>transmission_interface/SimpleTransmission</type>
    <joint name="SA043__MoJo">
      <hardwareInterface>EffortJointInterface</hardwareInterface>
    </joint>
    <actuator name="SA043__MoJo_motor">
      <hardwareInterface>EffortJointInterface</hardwareInterface>
      <mechanicalReduction>300</mechanicalReduction>
    </actuator>
  </transmission>
  <link name="SA043__MoJo__OUTPUT_BODY">
    <visual>
      <origin rpy="1.57075 0 0" xyz="0 0 0"/>
      <geometry>
        <mesh filename="package://snake_monster/meshes/rotary_output.stl"/>
        <!-- <cylinder radius=".0025" length=".1" /> -->
      </geometry>
      <material name="red">
        <color rgba=".82 0.06 0.06 1"/>
      </material>
    </visual>
    <collision>
      <origin rpy="0 0 0" xyz="0 0 0.0183"/>
      <geometry>
        <cylinder length="0.033" radius="0.026"/>
      </geometry>
    </collision>
    <inertial>
      <origin rpy="0 0 0" xyz="0 0 0"/>
      <mass value="0.103"/>
      <inertia ixx="5.4796e-05" ixy="0" ixz="0" iyy="5.4796e-05" iyz="0" izz="3.4814e-05"/>
    </inertial>
  </link>
  <joint name="SA043__MoJo__OUTPUT_INTERFACE" type="fixed">
    <parent link="SA043__MoJo__OUTPUT_BODY"/>
    <child link="SA005__MoJo__INPUT_INTERFACE"/>
    <origin rpy="0 0 -1.57075" xyz="0 0 0.0273"/>
  </joint>
  <link name="SA005__MoJo__INPUT_INTERFACE">
    <visual>
      <origin rpy="1.57075 0 0" xyz="0 0 0.035"/>
      <geometry>
        <mesh filename="package://snake_monster/meshes/rotary_input.stl"/>
      </geometry>
      <material name="red">
        <color rgba=".82 0.06 0.06 1"/>
      </material>
    </visual>
    <collision>
      <origin rpy="0 0 0" xyz="0 0 0.0183"/>
      <geometry>
        <cylinder length="0.033" radius="0.026"/>
      </geometry>
    </collision>
    <inertial>
      <origin rpy="0 0 0" xyz="0 0 0.0366"/>
      <mass value="0.103"/>
      <inertia ixx="5.4796e-05" ixy="0" ixz="0" iyy="5.4796e-05" iyz="0" izz="3.4814e-05"/>
    </inertial>
  </link>
  <link name="SA005__MoJo__INPUT_INTERFACE__COLLAR">
    <visual>
      <origin rpy="0 0 0" xyz="0 0 0.005"/>
      <geometry>
        <cylinder length="0.01" radius="0.026"/>
      </geometry>
      <material name="black">
        <color rgba="0 0 0 1"/>
      </material>
    </visual>
  </link>
  <joint name="SA005__MoJo__INPUT_INTERFACE__COLLAR_JOINT" type="fixed">
    <parent link="SA005__MoJo__INPUT_INTERFACE"/>
    <child link="SA005__MoJo__INPUT_INTERFACE__COLLAR"/>
  </joint>
  <joint name="SA005__MoJo" type="revolute">
    <parent link="SA005__MoJo__INPUT_INTERFACE"/>
    <child link="SA005__MoJo__OUTPUT_BODY"/>
    <origin rpy="0 0 0" xyz="0 0 0.0366"/>
    <axis xyz="0 1 0"/>
    <dynamics damping=".1" friction="0.2"/>
    <limit effort="7.0" lower="-1.57" upper="1.57" velocity="2.208932"/>
  </joint>
  <transmission name="SA005__MoJo_trans">
    <type>transmission_interface/SimpleTransmission</type>
    <joint name="SA005__MoJo">
      <hardwareInterface>EffortJointInterface</hardwareInterface>
    </joint>
    <actuator name="SA005__MoJo_motor">
      <hardwareInterface>EffortJointInterface</hardwareInterface>
      <mechanicalReduction>300</mechanicalReduction>
    </actuator>
  </transmission>
  <link name="SA005__MoJo__OUTPUT_BODY">
    <visual>
      <origin rpy="1.57075 0 0" xyz="0 0 0"/>
      <geometry>
        <mesh filename="package://snake_monster/meshes/rotary_output.stl"/>
        <!-- <cylinder radius=".0025" length=".1" /> -->
      </geometry>
      <material name="red">
        <color rgba=".82 0.06 0.06 1"/>
      </material>
    </visual>
    <collision>
      <origin rpy="0 0 0" xyz="0 0 0.0183"/>
      <geometry>
        <cylinder length="0.033" radius="0.026"/>
      </geometry>
    </collision>
    <inertial>
      <origin rpy="0 0 0" xyz="0 0 0"/>
      <mass value="0.103"/>
      <inertia ixx="5.4796e-05" ixy="0" ixz="0" iyy="5.4796e-05" iyz="0" izz="3.4814e-05"/>
    </inertial>
  </link>
  <joint name="SA005__MoJo__OUTPUT_INTERFACE" type="fixed">
    <parent link="SA005__MoJo__OUTPUT_BODY"/>
    <child link="extender__leg6__INPUT_INTERFACE"/>
    <origin rpy="0 0 -1.57075" xyz="0 0 0.0273"/>
  </joint>
  <link name="extender__leg6__INPUT_INTERFACE">
    <visual>
      <origin rpy="0 0 0" xyz="0 0 0.025"/>
      <geometry>
        <cylinder length="0.05" radius=".0254"/>
      </geometry>
      <material name="silver">
        <color rgba="0.6 0.6 0.6 1"/>
      </material>
    </visual>
    <collision>
      <origin rpy="0 0 0" xyz="0 0 0.025"/>
      <geometry>
        <cylinder length="0.05" radius=".0254"/>
      </geometry>
    </collision>
    <inertial>
      <origin rpy="0 0 0" xyz="0 0 0.025"/>
      <mass value=".05"/>
      <inertia ixx="2.50134116667e-05" ixy="0" ixz="0" iyy="2.50134116667e-05" iyz="0" izz="2.919349e-05"/>
    </inertial>
  </link>
  <joint name="extender__leg6__OUTPUT_INTERFACE" type="fixed">
    <parent link="extender__leg6__INPUT_INTERFACE"/>
    <child link="SA001__MoJo__INPUT_INTERFACE"/>
    <origin rpy="0 0 1.57079632679" xyz="0 0 0.05"/>
  </joint>
  <link name="extender__leg6__INPUT_INTERFACE__COLLAR">
    <visual>
      <origin rpy="0 0 0" xyz="0 0 0.005"/>
      <geometry>
        <cylinder length="0.01" radius="0.026"/>
      </geometry>
      <material name="black">
        <color rgba="0 0 0 1"/>
      </material>
    </visual>
  </link>
  <joint name="extender__leg6__INPUT_INTERFACE__COLLAR_JOINT" type="fixed">
    <parent link="extender__leg6__INPUT_INTERFACE"/>
    <child link="extender__leg6__INPUT_INTERFACE__COLLAR"/>
  </joint>
  <link name="SA001__MoJo__INPUT_INTERFACE">
    <visual>
      <origin rpy="1.57075 0 0" xyz="0 0 0.035"/>
      <geometry>
        <mesh filename="package://snake_monster/meshes/rotary_input.stl"/>
      </geometry>
      <material name="red">
        <color rgba=".82 0.06 0.06 1"/>
      </material>
    </visual>
    <collision>
      <origin rpy="0 0 0" xyz="0 0 0.0183"/>
      <geometry>
        <cylinder length="0.033" radius="0.026"/>
      </geometry>
    </collision>
    <inertial>
      <origin rpy="0 0 0" xyz="0 0 0.0366"/>
      <mass value="0.103"/>
      <inertia ixx="5.4796e-05" ixy="0" ixz="0" iyy="5.4796e-05" iyz="0" izz="3.4814e-05"/>
    </inertial>
  </link>
  <link name="SA001__MoJo__INPUT_INTERFACE__COLLAR">
    <visual>
      <origin rpy="0 0 0" xyz="0 0 0.005"/>
      <geometry>
        <cylinder length="0.01" radius="0.026"/>
      </geometry>
      <material name="black">
        <color rgba="0 0 0 1"/>
      </material>
    </visual>
  </link>
  <joint name="SA001__MoJo__INPUT_INTERFACE__COLLAR_JOINT" type="fixed">
    <parent link="SA001__MoJo__INPUT_INTERFACE"/>
    <child link="SA001__MoJo__INPUT_INTERFACE__COLLAR"/>
  </joint>
  <joint name="SA001__MoJo" type="revolute">
    <parent link="SA001__MoJo__INPUT_INTERFACE"/>
    <child link="SA001__MoJo__OUTPUT_BODY"/>
    <origin rpy="0 0 0" xyz="0 0 0.0366"/>
    <axis xyz="0 1 0"/>
    <dynamics damping=".1" friction="0.2"/>
    <limit effort="7.0" lower="-1.57" upper="1.57" velocity="2.208932"/>
  </joint>
  <transmission name="SA001__MoJo_trans">
    <type>transmission_interface/SimpleTransmission</type>
    <joint name="SA001__MoJo">
      <hardwareInterface>EffortJointInterface</hardwareInterface>
    </joint>
    <actuator name="SA001__MoJo_motor">
      <hardwareInterface>EffortJointInterface</hardwareInterface>
      <mechanicalReduction>300</mechanicalReduction>
    </actuator>
  </transmission>
  <link name="SA001__MoJo__OUTPUT_BODY">
    <visual>
      <origin rpy="1.57075 0 0" xyz="0 0 0"/>
      <geometry>
        <mesh filename="package://snake_monster/meshes/rotary_output.stl"/>
        <!-- <cylinder radius=".0025" length=".1" /> -->
      </geometry>
      <material name="red">
        <color rgba=".82 0.06 0.06 1"/>
      </material>
    </visual>
    <collision>
      <origin rpy="0 0 0" xyz="0 0 0.0183"/>
      <geometry>
        <cylinder length="0.033" radius="0.026"/>
      </geometry>
    </collision>
    <inertial>
      <origin rpy="0 0 0" xyz="0 0 0"/>
      <mass value="0.103"/>
      <inertia ixx="5.4796e-05" ixy="0" ixz="0" iyy="5.4796e-05" iyz="0" izz="3.4814e-05"/>
    </inertial>
  </link>
  <joint name="SA001__MoJo__OUTPUT_INTERFACE" type="fixed">
    <parent link="SA001__MoJo__OUTPUT_BODY"/>
    <child link="elbow__leg6__INPUT_INTERFACE"/>
    <origin rpy="0 0 -1.57075" xyz="0 0 0.0273"/>
  </joint>
  <link name="elbow__leg6__INPUT_INTERFACE">
    <visual>
      <origin rpy="0 0 0" xyz="0 0 0.00955"/>
      <geometry>
        <cylinder length="0.0191" radius=".0254"/>
      </geometry>
      <material name="silver">
        <color rgba="0.6 0.6 0.6 1"/>
      </material>
    </visual>
    <visual>
      <origin rpy="1.57075 0 3.14159265359" xyz="0.0274 -0.0782 0.0121"/>
      <geometry>
        <mesh filename="package://snake_monster/meshes/elbow_corner.stl"/>
      </geometry>
      <material name="silver">
        <color rgba="0.6 0.6 0.6 1"/>
      </material>
    </visual>
    <collision>
      <origin rpy="0 0 0" xyz="0 0 0.00955"/>
      <geometry>
        <cylinder length="0.0191" radius=".0254"/>
      </geometry>
    </collision>
    <collision>
      <origin rpy="0 0 0" xyz="0 -0.01 0.0311"/>
      <geometry>
        <sphere radius="0.0191"/>
      </geometry>
    </collision>
    <inertial>
      <origin rpy="0 0 0" xyz="0 0 0.0391"/>
      <mass value=".045"/>
      <inertia ixx="8.6260875e-06" ixy="0" ixz="0" iyy="8.6260875e-06" iyz="0" izz="1.45161e-05"/>
    </inertial>
  </link>
  <link name="elbow__leg6__INPUT_INTERFACE__COLLAR">
    <visual>
      <origin rpy="0 0 0" xyz="0 0 0.005"/>
      <geometry>
        <cylinder length="0.01" radius="0.026"/>
      </geometry>
      <material name="black">
        <color rgba="0 0 0 1"/>
      </material>
    </visual>
  </link>
  <joint name="elbow__leg6__INPUT_INTERFACE__COLLAR_JOINT" type="fixed">
    <parent link="elbow__leg6__INPUT_INTERFACE"/>
    <child link="elbow__leg6__INPUT_INTERFACE__COLLAR"/>
  </joint>
  <joint name="elbow__leg6__MID_ELBOW_JOINT" type="fixed">
    <parent link="elbow__leg6__INPUT_INTERFACE"/>
    <child link="elbow__leg6__AFTER_CORNER_BODY"/>
    <origin rpy="-1.57079632679 0 3.14159265359" xyz="0 0 0.0445"/>
  </joint>
  <link name="elbow__leg6__AFTER_CORNER_BODY">
    <visual>
      <origin rpy="0 0 0" xyz="0 0 0.0857"/>
      <geometry>
        <cylinder length="0.1206" radius=".0254"/>
      </geometry>
      <material name="silver">
        <color rgba="0.6 0.6 0.6 1"/>
      </material>
    </visual>
    <collision>
      <origin rpy="0 0 0" xyz="0 0 0.0857"/>
      <geometry>
        <cylinder length="0.1206" radius=".0254"/>
      </geometry>
    </collision>
    <inertial>
      <origin rpy="0 0 0" xyz="0 0 0.0857"/>
      <mass value=".065"/>
      <inertia ixx="1.24599041667e-05" ixy="0" ixz="0" iyy="1.24599041667e-05" iyz="0" izz="2.09677e-05"/>
    </inertial>
  </link>
  <joint name="elbow__leg6__OUTPUT_INTERFACE" type="fixed">
    <parent link="elbow__leg6__AFTER_CORNER_BODY"/>
    <child link="foot__leg6__INPUT_INTERFACE"/>
    <origin rpy="0 0 -1.57079632679" xyz="0 0 0.146"/>
  </joint>
  <!--TODO: check dimensions -->
  <link name="foot__leg6__INPUT_INTERFACE">
    <visual>
      <origin rpy="0 0 0" xyz="0 0 0"/>
      <geometry>
        <sphere radius=".0254"/>
      </geometry>
      <material name="black">
        <color rgba="0 0 0 1"/>
      </material>
    </visual>
    <collision>
      <origin rpy="0 0 0" xyz="0 0 0"/>
      <geometry>
        <sphere radius=".0254"/>
      </geometry>
    </collision>
  </link>
</robot>

