<?xml version="1.0"?>
<sdf version='1.6'>
  <world name='default'>
    <light name='sun' type='directional'>
      <cast_shadows>1</cast_shadows>
      <pose frame=''>0 0 10 0 -0 0</pose>
      <diffuse>0.8 0.8 0.8 1</diffuse>
      <specular>0.1 0.1 0.1 1</specular>
      <attenuation>
        <range>1000</range>
        <constant>0.9</constant>
        <linear>0.01</linear>
        <quadratic>0.001</quadratic>
      </attenuation>
      <direction>-0.5 0.5 -1</direction>
    </light>
    <model name='ground_plane'>
      <static>1</static>
      <link name='link'>
        <collision name='collision'>
          <geometry>
            <plane>
              <normal>0 0 1</normal>
              <size>100 100</size>
            </plane>
          </geometry>
          <surface>
            <friction>
              <ode>
                <mu>100</mu>
                <mu2>50</mu2>
              </ode>
              <torsional>
                <ode/>
              </torsional>
            </friction>
            <contact>
              <ode/>
            </contact>
            <bounce/>
          </surface>
          <max_contacts>10</max_contacts>
        </collision>
        <visual name='visual'>
          <cast_shadows>0</cast_shadows>
          <geometry>
            <plane>
              <normal>0 0 1</normal>
              <size>100 100</size>
            </plane>
          </geometry>
          <material>
            <script>
              <uri>file://media/materials/scripts/gazebo.material</uri>
              <name>Gazebo/Grey</name>
            </script>
          </material>
        </visual>
        <self_collide>0</self_collide>
        <kinematic>0</kinematic>
        <gravity>1</gravity>
      </link>
    </model>
    <gravity>0 0 -1.62</gravity>
    <magnetic_field>6e-06 2.3e-05 -4.2e-05</magnetic_field>
    <atmosphere type='adiabatic'/>
    <physics name='default_physics' default='0' type='ode'>
      <max_step_size>0.001</max_step_size>
      <real_time_factor>1</real_time_factor>
      <real_time_update_rate>1000</real_time_update_rate>
    </physics>
    <scene>
      <ambient>0.4 0.4 0.4 1</ambient>
      <background>0.7 0.7 0.7 1</background>
      <shadows>1</shadows>
    </scene>
    <spherical_coordinates>
      <surface_model>EARTH_WGS84</surface_model>
      <latitude_deg>0</latitude_deg>
      <longitude_deg>0</longitude_deg>
      <elevation>0</elevation>
      <heading_deg>0</heading_deg>
    </spherical_coordinates>
    <model name='unit_box_7'>
      <pose frame=''>-0.316695 3.57445 0.5 0 -0 0</pose>
      <link name='link'>
        <inertial>
          <mass>1</mass>
          <inertia>
            <ixx>0.166667</ixx>
            <ixy>0</ixy>
            <ixz>0</ixz>
            <iyy>0.166667</iyy>
            <iyz>0</iyz>
            <izz>0.166667</izz>
          </inertia>
        </inertial>
        <collision name='collision'>
          <geometry>
            <box>
              <size>1 1 1</size>
            </box>
          </geometry>
          <max_contacts>10</max_contacts>
          <surface>
            <contact>
              <ode/>
            </contact>
            <bounce/>
            <friction>
              <torsional>
                <ode/>
              </torsional>
              <ode/>
            </friction>
          </surface>
        </collision>
        <visual name='visual'>
          <geometry>
            <box>
              <size>1 1 1</size>
            </box>
          </geometry>
          <material>
            <script>
              <name>Gazebo/Grey</name>
              <uri>file://media/materials/scripts/gazebo.material</uri>
            </script>
          </material>
        </visual>
        <self_collide>0</self_collide>
        <kinematic>0</kinematic>
        <gravity>1</gravity>
      </link>
    </model>
    <model name='unit_box_8_0_clone'>
      <pose frame=''>-0.300884 6.07077 0.5 0 -0 0</pose>
      <link name='link'>
        <inertial>
          <mass>1</mass>
          <inertia>
            <ixx>0.166667</ixx>
            <ixy>0</ixy>
            <ixz>0</ixz>
            <iyy>0.166667</iyy>
            <iyz>0</iyz>
            <izz>0.166667</izz>
          </inertia>
        </inertial>
        <collision name='collision'>
          <geometry>
            <box>
              <size>1 3.407 1</size>
            </box>
          </geometry>
          <max_contacts>10</max_contacts>
          <surface>
            <contact>
              <ode/>
            </contact>
            <bounce/>
            <friction>
              <torsional>
                <ode/>
              </torsional>
              <ode/>
            </friction>
          </surface>
        </collision>
        <visual name='visual'>
          <geometry>
            <box>
              <size>1 3.407 1</size>
            </box>
          </geometry>
          <material>
            <script>
              <name>Gazebo/Grey</name>
              <uri>file://media/materials/scripts/gazebo.material</uri>
            </script>
          </material>
        </visual>
        <self_collide>0</self_collide>
        <kinematic>0</kinematic>
        <gravity>1</gravity>
      </link>
    </model>
    <model name='unit_box_8_0_clone_0'>
      <pose frame=''>0.203098 -0.251752 0.5 0 -0 0</pose>
      <link name='link'>
        <inertial>
          <mass>1</mass>
          <inertia>
            <ixx>0.166667</ixx>
            <ixy>0</ixy>
            <ixz>0</ixz>
            <iyy>0.166667</iyy>
            <iyz>0</iyz>
            <izz>0.166667</izz>
          </inertia>
        </inertial>
        <collision name='collision'>
          <geometry>
            <box>
              <size>1 3.40701 1</size>
            </box>
          </geometry>
          <max_contacts>10</max_contacts>
          <surface>
            <contact>
              <ode/>
            </contact>
            <bounce/>
            <friction>
              <torsional>
                <ode/>
              </torsional>
              <ode/>
            </friction>
          </surface>
        </collision>
        <visual name='visual'>
          <geometry>
            <box>
              <size>1 3.40701 1</size>
            </box>
          </geometry>
          <material>
            <script>
              <name>Gazebo/Grey</name>
              <uri>file://media/materials/scripts/gazebo.material</uri>
            </script>
          </material>
        </visual>
        <self_collide>0</self_collide>
        <kinematic>0</kinematic>
        <gravity>1</gravity>
      </link>
    </model>
    <model name='unit_box_8_0_clone_1'>
      <pose frame=''>-2.20149 -0.344836 0.5 0 -0 0</pose>
      <link name='link'>
        <inertial>
          <mass>1</mass>
          <inertia>
            <ixx>0.166667</ixx>
            <ixy>0</ixy>
            <ixz>0</ixz>
            <iyy>0.166667</iyy>
            <iyz>0</iyz>
            <izz>0.166667</izz>
          </inertia>
        </inertial>
        <collision name='collision'>
          <geometry>
            <box>
              <size>1 3.40701 1</size>
            </box>
          </geometry>
          <max_contacts>10</max_contacts>
          <surface>
            <contact>
              <ode/>
            </contact>
            <bounce/>
            <friction>
              <torsional>
                <ode/>
              </torsional>
              <ode/>
            </friction>
          </surface>
        </collision>
        <visual name='visual'>
          <geometry>
            <box>
              <size>1 3.40701 1</size>
            </box>
          </geometry>
          <material>
            <script>
              <name>Gazebo/Grey</name>
              <uri>file://media/materials/scripts/gazebo.material</uri>
            </script>
          </material>
        </visual>
        <self_collide>0</self_collide>
        <kinematic>0</kinematic>
        <gravity>1</gravity>
      </link>
    </model>
    <model name='unit_box_2_clone'>
      <pose frame=''>-2.08571 -2.6688 0.5 0 -0 0</pose>
      <link name='link'>
        <inertial>
          <mass>1</mass>
          <inertia>
            <ixx>0.166667</ixx>
            <ixy>0</ixy>
            <ixz>0</ixz>
            <iyy>0.166667</iyy>
            <iyz>0</iyz>
            <izz>0.166667</izz>
          </inertia>
        </inertial>
        <collision name='collision'>
          <geometry>
            <box>
              <size>1 1 1</size>
            </box>
          </geometry>
          <max_contacts>10</max_contacts>
          <surface>
            <contact>
              <ode/>
            </contact>
            <bounce/>
            <friction>
              <torsional>
                <ode/>
              </torsional>
              <ode/>
            </friction>
          </surface>
        </collision>
        <visual name='visual'>
          <geometry>
            <box>
              <size>1 1 1</size>
            </box>
          </geometry>
          <material>
            <script>
              <name>Gazebo/Grey</name>
              <uri>file://media/materials/scripts/gazebo.material</uri>
            </script>
          </material>
        </visual>
        <self_collide>0</self_collide>
        <kinematic>0</kinematic>
        <gravity>1</gravity>
      </link>
    </model>
    <model name='unit_box_2_clone_0'>
      <pose frame=''>0.142337 -2.72466 0.5 0 -0 0</pose>
      <link name='link'>
        <inertial>
          <mass>1</mass>
          <inertia>
            <ixx>0.166667</ixx>
            <ixy>0</ixy>
            <ixz>0</ixz>
            <iyy>0.166667</iyy>
            <iyz>0</iyz>
            <izz>0.166667</izz>
          </inertia>
        </inertial>
        <collision name='collision'>
          <geometry>
            <box>
              <size>1 1 1</size>
            </box>
          </geometry>
          <max_contacts>10</max_contacts>
          <surface>
            <contact>
              <ode/>
            </contact>
            <bounce/>
            <friction>
              <torsional>
                <ode/>
              </torsional>
              <ode/>
            </friction>
          </surface>
        </collision>
        <visual name='visual'>
          <geometry>
            <box>
              <size>1 1 1</size>
            </box>
          </geometry>
          <material>
            <script>
              <name>Gazebo/Grey</name>
              <uri>file://media/materials/scripts/gazebo.material</uri>
            </script>
          </material>
        </visual>
        <self_collide>0</self_collide>
        <kinematic>0</kinematic>
        <gravity>1</gravity>
      </link>
    </model>
    <model name='unit_box_2_clone_1'>
      <pose frame=''>-2.86667 -3.94186 0.5 -0 -0 -0</pose>
      <link name='link'>
        <inertial>
          <mass>1</mass>
          <inertia>
            <ixx>0.166667</ixx>
            <ixy>0</ixy>
            <ixz>0</ixz>
            <iyy>0.166667</iyy>
            <iyz>0</iyz>
            <izz>0.166667</izz>
          </inertia>
        </inertial>
        <collision name='collision'>
          <geometry>
            <box>
              <size>1 1 1</size>
            </box>
          </geometry>
          <max_contacts>10</max_contacts>
          <surface>
            <contact>
              <ode/>
            </contact>
            <bounce/>
            <friction>
              <torsional>
                <ode/>
              </torsional>
              <ode/>
            </friction>
          </surface>
        </collision>
        <visual name='visual'>
          <geometry>
            <box>
              <size>1 1 1</size>
            </box>
          </geometry>
          <material>
            <script>
              <name>Gazebo/Grey</name>
              <uri>file://media/materials/scripts/gazebo.material</uri>
            </script>
          </material>
        </visual>
        <self_collide>0</self_collide>
        <kinematic>0</kinematic>
        <gravity>1</gravity>
      </link>
    </model>
    <model name='unit_box_2_clone_2'>
      <pose frame=''>-0.310316 -3.99695 0.5 0 -0 0</pose>
      <link name='link'>
        <inertial>
          <mass>1</mass>
          <inertia>
            <ixx>0.166667</ixx>
            <ixy>0</ixy>
            <ixz>0</ixz>
            <iyy>0.166667</iyy>
            <iyz>0</iyz>
            <izz>0.166667</izz>
          </inertia>
        </inertial>
        <collision name='collision'>
          <geometry>
            <box>
              <size>1 1 1</size>
            </box>
          </geometry>
          <max_contacts>10</max_contacts>
          <surface>
            <contact>
              <ode/>
            </contact>
            <bounce/>
            <friction>
              <torsional>
                <ode/>
              </torsional>
              <ode/>
            </friction>
          </surface>
        </collision>
        <visual name='visual'>
          <geometry>
            <box>
              <size>1 1 1</size>
            </box>
          </geometry>
          <material>
            <script>
              <name>Gazebo/Grey</name>
              <uri>file://media/materials/scripts/gazebo.material</uri>
            </script>
          </material>
        </visual>
        <self_collide>0</self_collide>
        <kinematic>0</kinematic>
        <gravity>1</gravity>
      </link>
    </model>
    <model name='unit_box_8_0_clone_1_clone'>
      <pose frame=''>-2.93047 -6.61141 0.499661 -0.000199 0 0</pose>
      <link name='link'>
        <inertial>
          <mass>1</mass>
          <inertia>
            <ixx>0.166667</ixx>
            <ixy>0</ixy>
            <ixz>0</ixz>
            <iyy>0.166667</iyy>
            <iyz>0</iyz>
            <izz>0.166667</izz>
          </inertia>
        </inertial>
        <collision name='collision'>
          <geometry>
            <box>
              <size>1 3.40701 1</size>
            </box>
          </geometry>
          <max_contacts>10</max_contacts>
          <surface>
            <contact>
              <ode/>
            </contact>
            <bounce/>
            <friction>
              <torsional>
                <ode/>
              </torsional>
              <ode/>
            </friction>
          </surface>
        </collision>
        <visual name='visual'>
          <geometry>
            <box>
              <size>1 3.40701 1</size>
            </box>
          </geometry>
          <material>
            <script>
              <name>Gazebo/Grey</name>
              <uri>file://media/materials/scripts/gazebo.material</uri>
            </script>
          </material>
        </visual>
        <self_collide>0</self_collide>
        <kinematic>0</kinematic>
        <gravity>1</gravity>
      </link>
    </model>
    <model name='unit_box_8_0_clone_1_clone_0'>
      <pose frame=''>-0.354042 -6.76334 0.499661 -0.000199 0 0</pose>
      <link name='link'>
        <inertial>
          <mass>1</mass>
          <inertia>
            <ixx>0.166667</ixx>
            <ixy>0</ixy>
            <ixz>0</ixz>
            <iyy>0.166667</iyy>
            <iyz>0</iyz>
            <izz>0.166667</izz>
          </inertia>
        </inertial>
        <collision name='collision'>
          <geometry>
            <box>
              <size>1 3.40701 1</size>
            </box>
          </geometry>
          <max_contacts>10</max_contacts>
          <surface>
            <contact>
              <ode/>
            </contact>
            <bounce/>
            <friction>
              <torsional>
                <ode/>
              </torsional>
              <ode/>
            </friction>
          </surface>
        </collision>
        <visual name='visual'>
          <geometry>
            <box>
              <size>1 3.40701 1</size>
            </box>
          </geometry>
          <material>
            <script>
              <name>Gazebo/Grey</name>
              <uri>file://media/materials/scripts/gazebo.material</uri>
            </script>
          </material>
        </visual>
        <self_collide>0</self_collide>
        <kinematic>0</kinematic>
        <gravity>1</gravity>
      </link>
    </model>
    <state world_name='default'>
      <sim_time>2508 917000000</sim_time>
      <real_time>1388 176782640</real_time>
      <wall_time>1623004439 571205128</wall_time>
      <iterations>1212978</iterations>
      <model name='ground_plane'>
        <pose frame=''>0 0 0 0 -0 0</pose>
        <scale>1 1 1</scale>
        <link name='link'>
          <pose frame=''>0 0 0 0 -0 0</pose>
          <velocity>0 0 0 0 -0 0</velocity>
          <acceleration>0 0 0 0 -0 0</acceleration>
          <wrench>0 0 0 0 -0 0</wrench>
        </link>
      </model>
      <model name='robot'>
        <pose frame=''>-1.40415 -8.77627 0.025956 2.90428 0.021319 -0.005797</pose>
        <scale>1 1 1</scale>
        <link name='SA001__MoJo__OUTPUT_BODY'>
          <pose frame=''>-1.44074 -8.77605 0.026736 1.5655 1.33353 -1.57688</pose>
          <velocity>0 -0.000115 9e-06 0.004612 4.2e-05 -1.9e-05</velocity>
          <acceleration>0.000617 0.001774 -0.001086 -0.026208 -0.016407 -2.03258</acceleration>
          <wrench>0.000127 0.000366 -0.000224 0 -0 0</wrench>
        </link>
        <link name='SA002__MoJo__OUTPUT_BODY'>
          <pose frame=''>-1.50464 -8.77599 0.026815 -1.57221 0.237305 1.55869</pose>
          <velocity>0 -0.000114 1.1e-05 0.004621 2.3e-05 -2.1e-05</velocity>
          <acceleration>0.000702 0.001645 -0.001964 -0.02513 -0.015347 2.96179</acceleration>
          <wrench>0.000145 0.000339 -0.000405 0 -0 0</wrench>
        </link>
        <link name='SA003__MoJo__OUTPUT_BODY'>
          <pose frame=''>-1.56854 -8.77524 0.026727 -1.61909 -1.33316 1.60838</pose>
          <velocity>-1e-06 -0.000113 1.2e-05 0.004635 0.000112 -5e-05</velocity>
          <acceleration>0.0008 0.001431 -0.002749 0.201027 -0.140395 -0.348919</acceleration>
          <wrench>0.000165 0.000295 -0.000566 0 -0 0</wrench>
        </link>
        <link name='SA004__MoJo__OUTPUT_BODY'>
          <pose frame=''>-1.63243 -8.77464 0.026001 1.57081 -0.237685 -1.53329</pose>
          <velocity>-6e-06 -0.000107 2.4e-05 0.004572 -0.000206 0.000188</velocity>
          <acceleration>0.001838 0.001854 -0.002226 -0.448294 0.056433 -1.70858</acceleration>
          <wrench>0.000379 0.000382 -0.000459 0 -0 0</wrench>
        </link>
        <link name='SA005__MoJo__OUTPUT_BODY'>
          <pose frame=''>-1.69629 -8.77704 0.026 1.54791 1.333 -1.55683</pose>
          <velocity>-3e-06 -0.000117 2e-06 0.004635 2.8e-05 0.000109</velocity>
          <acceleration>0.00133 0.002022 -0.000636 -2.28431 0.194168 -1.29931</acceleration>
          <wrench>0.000274 0.000416 -0.000131 0 -0 0</wrench>
        </link>
        <link name='SA006__MoJo__OUTPUT_BODY'>
          <pose frame=''>-1.76014 -8.77935 0.026344 -1.57352 0.237822 1.5732</pose>
          <velocity>-2e-06 -0.000125 -5e-06 0.00463 9e-06 -2.2e-05</velocity>
          <acceleration>0.001088 0.002467 2.4e-05 1.7816 0.025918 -1.49983</acceleration>
          <wrench>0.000224 0.000508 5e-06 0 -0 0</wrench>
        </link>
        <link name='SA007__MoJo__OUTPUT_BODY'>
          <pose frame=''>-1.82404 -8.77955 0.026175 -1.58245 -1.33292 1.58519</pose>
          <velocity>-1e-06 -0.000124 -5e-06 0.004625 0.000127 -4.5e-05</velocity>
          <acceleration>0.000858 0.002776 -7e-06 0.348084 0.009116 -2.7388</acceleration>
          <wrench>0.000177 0.000572 -2e-06 0 -0 0</wrench>
        </link>
        <link name='SA008__MoJo__OUTPUT_BODY'>
          <pose frame=''>-1.88794 -8.77974 0.025999 1.5705 -0.237928 -1.55517</pose>
          <velocity>3e-06 -0.00012 0 0.004623 0.000123 -3e-05</velocity>
          <acceleration>7.5e-05 0.003092 0.000146 -0.444898 -0.001999 2.84881</acceleration>
          <wrench>1.5e-05 0.000637 3e-05 0 -0 0</wrench>
        </link>
        <link name='SA009__MoJo__OUTPUT_BODY'>
          <pose frame=''>-1.95183 -8.78073 0.026018 1.57024 1.33283 -1.55574</pose>
          <velocity>1e-06 -0.000119 6e-06 0.004621 1.1e-05 2.1e-05</velocity>
          <acceleration>0.000349 0.003342 -0.000162 -0.546632 -0.002226 2.34351</acceleration>
          <wrench>7.2e-05 0.000689 -3.3e-05 0 -0 0</wrench>
        </link>
        <link name='SA010__MoJo__OUTPUT_BODY'>
          <pose frame=''>-2.01573 -8.78173 0.026026 -1.57121 0.23802 1.58408</pose>
          <velocity>1e-06 -0.000121 2e-06 0.004619 2e-06 1.6e-05</velocity>
          <acceleration>0.000259 0.00369 0.00016 -0.540138 -0.000968 2.92967</acceleration>
          <wrench>5.3e-05 0.00076 3.3e-05 0 -0 0</wrench>
        </link>
        <link name='SA011__MoJo__OUTPUT_BODY'>
          <pose frame=''>-2.07962 -8.78259 0.026 -1.57079 -1.33273 1.58408</pose>
          <velocity>3e-06 -0.000121 0 0.004661 0.000103 -7e-06</velocity>
          <acceleration>-4.5e-05 0.003702 6e-06 -0.632536 -0.008133 0.695908</acceleration>
          <wrench>-9e-06 0.000763 1e-06 0 -0 0</wrench>
        </link>
        <link name='SA012__MoJo__OUTPUT_BODY'>
          <pose frame=''>-2.14351 -8.78344 0.026 1.57079 -0.238112 -1.55752</pose>
          <velocity>0 -0.000122 -1e-06 0.004617 0.000109 -3e-05</velocity>
          <acceleration>0.00033 0.003956 0.000589 -0.585147 -0.011915 -0.31693</acceleration>
          <wrench>6.8e-05 0.000815 0.000121 0 -0 0</wrench>
        </link>
        <link name='SA013__MoJo__OUTPUT_BODY'>
          <pose frame=''>-2.20741 -8.78428 0.026 1.56997 1.33264 -1.55837</pose>
          <velocity>1e-06 -0.00012 1e-06 0.00462 0.000129 -3.5e-05</velocity>
          <acceleration>0.00011 0.003939 0.000459 -0.601605 -0.013835 -1.131</acceleration>
          <wrench>2.3e-05 0.000811 9.4e-05 0 -0 0</wrench>
        </link>
        <link name='SA014__MoJo__OUTPUT_BODY'>
          <pose frame=''>-2.2713 -8.78513 0.026012 -1.57043 0.238203 1.58477</pose>
          <velocity>1e-06 -0.000118 5e-06 0.004617 0.000128 -1.4e-05</velocity>
          <acceleration>4.9e-05 0.003844 0.000112 -0.599059 -0.014057 3.1325</acceleration>
          <wrench>1e-05 0.000792 2.3e-05 0 -0 0</wrench>
        </link>
        <link name='SA015__MoJo__OUTPUT_BODY'>
          <pose frame=''>-2.3352 -8.78602 0.026035 -1.57319 -1.33255 1.58724</pose>
          <velocity>-2e-06 -0.000117 8e-06 0.004604 -5.8e-05 4.4e-05</velocity>
          <acceleration>-1.7e-05 0.003669 -3.8e-05 0.31615 0.005434 2.15602</acceleration>
          <wrench>-4e-06 0.000756 -8e-06 0 -0 0</wrench>
        </link>
        <link name='SA016__MoJo__OUTPUT_BODY'>
          <pose frame=''>-2.39909 -8.78692 0.025999 1.5552 -0.237795 -1.48827</pose>
          <velocity>0 -0.00012 0 0.004613 -5.9e-05 0.000125</velocity>
          <acceleration>-3.9e-05 0.003686 -0.000101 -1.58393 0.875677 1.54767</acceleration>
          <wrench>-4e-06 0.00038 -1e-05 0 -0 0</wrench>
        </link>
        <link name='kdl_dummy_root'>
          <pose frame=''>-1.40415 -8.77627 0.025956 2.90428 0.021319 -0.005797</pose>
          <velocity>5e-06 -0.000118 0 0.004517 0.00019 -0.000156</velocity>
          <acceleration>-0.000282 0.002013 -0.000347 -0.503121 -0.008947 0.022008</acceleration>
          <wrench>-2.9e-05 0.000207 -3.6e-05 0 -0 0</wrench>
        </link>
      </model>
      <model name='unit_box_2_clone'>
        <pose frame=''>0.561472 -3.41254 0.499999 2e-06 -0 0.002425</pose>
        <scale>1 1 1</scale>
        <link name='link'>
          <pose frame=''>0.561472 -3.41254 0.499999 2e-06 -0 0.002425</pose>
          <velocity>0 0 0 0 -0 0</velocity>
          <acceleration>0.000778 -0.001832 -1.61695 0.00365 0.001555 0</acceleration>
          <wrench>0.000778 -0.001832 -1.61695 0 -0 0</wrench>
        </link>
      </model>
      <model name='unit_box_2_clone_0'>
        <pose frame=''>0.28032 -5.46006 0.499999 2e-06 0 -1e-06</pose>
        <scale>1 1 1</scale>
        <link name='link'>
          <pose frame=''>0.28032 -5.46006 0.499999 2e-06 0 -1e-06</pose>
          <velocity>0 0 0 0 -0 0</velocity>
          <acceleration>-0.000778 -0.001834 -1.61695 0.003654 -0.001556 -0</acceleration>
          <wrench>-0.000778 -0.001834 -1.61695 0 -0 0</wrench>
        </link>
      </model>
      <model name='unit_box_2_clone_1'>
        <pose frame=''>-2.93064 -4.42358 0.499999 -0 -2e-06 1e-06</pose>
        <scale>1 0.756541 1</scale>
        <link name='link'>
          <pose frame=''>-2.93064 -4.42358 0.499999 -0 -2e-06 1e-06</pose>
          <velocity>0 0 0 0 -0 0</velocity>
          <acceleration>-0.000489 0.00037 -1.61918 -0.000741 -0.00098 0</acceleration>
          <wrench>-0.000489 0.00037 -1.61918 0 -0 0</wrench>
        </link>
      </model>
      <model name='unit_box_2_clone_2'>
        <pose frame=''>1.36906 -5.47235 0.499999 2e-06 0 -1e-06</pose>
        <scale>1 1 1</scale>
        <link name='link'>
          <pose frame=''>1.36906 -5.47235 0.499999 2e-06 0 -1e-06</pose>
          <velocity>0 0 0 0 -0 0</velocity>
          <acceleration>-0.000778 -0.001834 -1.61695 0.003654 -0.001556 -0</acceleration>
          <wrench>-0.000778 -0.001834 -1.61695 0 -0 0</wrench>
        </link>
      </model>
      <model name='unit_box_7'>
        <pose frame=''>2.61528 1.57417 0.5 0 0 -1e-06</pose>
        <scale>1 0.655237 1</scale>
        <link name='link'>
          <pose frame=''>2.61528 1.57417 0.5 0 0 -1e-06</pose>
          <velocity>0 0 0 0 -0 0</velocity>
          <acceleration>1.61868 -0.000219 1.61867 -3.14115 -0.095765 3.14158</acceleration>
          <wrench>1.61868 -0.000219 1.61867 0 -0 0</wrench>
        </link>
      </model>
      <model name='unit_box_8_0_clone'>
        <pose frame=''>-1.16077 0.633168 0.5 0 0 -1.57287</pose>
        <scale>1 0.611751 1</scale>
        <link name='link'>
          <pose frame=''>-1.16077 0.633168 0.5 0 0 -1.57287</pose>
          <velocity>0 0 0 0 -0 0</velocity>
          <acceleration>-0.379465 -1.01396 1.41337 2.02872 -0.758926 1e-06</acceleration>
          <wrench>-0.379465 -1.01396 1.41337 0 -0 0</wrench>
        </link>
      </model>
      <model name='unit_box_8_0_clone_0'>
        <pose frame=''>2.62681 -4.16814 0.499986 -8e-06 0 0</pose>
        <scale>1 1.05154 1</scale>
        <link name='link'>
          <pose frame=''>2.62681 -4.16814 0.499986 -8e-06 0 0</pose>
          <velocity>0 0 0 0 -0 0</velocity>
          <acceleration>0 1.62 0 0.015108 -3e-06 -0</acceleration>
          <wrench>0 1.62 0 0 -0 0</wrench>
        </link>
      </model>
      <model name='unit_box_8_0_clone_1'>
        <pose frame=''>-1.71954 -3.40246 0.5 0 -1e-06 -1.56737</pose>
        <scale>1 1 1</scale>
        <link name='link'>
          <pose frame=''>-1.71954 -3.40246 0.5 0 -1e-06 -1.56737</pose>
          <velocity>0 0 0 0 -0 0</velocity>
          <acceleration>0.110776 0.066922 -1.50922 -0.134073 0.399035 -0.00032</acceleration>
          <wrench>0.110776 0.066922 -1.50922 0 -0 0</wrench>
        </link>
      </model>
      <model name='unit_box_8_0_clone_1_clone'>
        <pose frame=''>-2.93046 -6.67161 0.499995 3e-06 -0 0</pose>
        <scale>1 1 1</scale>
        <link name='link'>
          <pose frame=''>-2.93046 -6.67161 0.499995 3e-06 -0 0</pose>
          <velocity>0 0 0 0 -0 0</velocity>
          <acceleration>-1e-06 -1.61466 -0.005339 -0.906942 -6e-06 0</acceleration>
          <wrench>-1e-06 -1.61466 -0.005339 0 -0 0</wrench>
        </link>
      </model>
      <model name='unit_box_8_0_clone_1_clone_0'>
        <pose frame=''>-0.884299 -6.66115 0.499995 3e-06 -0 0</pose>
        <scale>1 1 1</scale>
        <link name='link'>
          <pose frame=''>-0.884299 -6.66115 0.499995 3e-06 -0 0</pose>
          <velocity>0 0 0 0 -0 0</velocity>
          <acceleration>-1e-06 -1.61466 -0.005339 -0.906942 -5e-06 -0</acceleration>
          <wrench>-1e-06 -1.61466 -0.005339 0 -0 0</wrench>
        </link>
      </model>
      <model name='unit_box_8_0_clone_clone'>
        <pose frame=''>0.576842 -0.781271 0.499962 2e-05 -0 0</pose>
        <scale>1 1.14378 1</scale>
        <link name='link'>
          <pose frame=''>0.576842 -0.781271 0.499962 2e-05 -0 0</pose>
          <velocity>0 0 0 0 -0 0</velocity>
          <acceleration>0 -1.62 0 1.51202 -2e-06 0</acceleration>
          <wrench>0 -1.62 0 0 -0 0</wrench>
        </link>
      </model>
      <model name='unit_box_8_0_clone_clone_0'>
        <pose frame=''>2.61856 -0.575639 0.499995 -3e-06 0 0</pose>
        <scale>1 1 1</scale>
        <link name='link'>
          <pose frame=''>2.61856 -0.575639 0.499995 -3e-06 0 0</pose>
          <velocity>0 0 0 0 -0 0</velocity>
          <acceleration>1e-06 1.61464 -0.005361 0.907099 6e-06 0</acceleration>
          <wrench>1e-06 1.61464 -0.005361 0 -0 0</wrench>
        </link>
      </model>
      <model name='unit_box_8_0_clone_clone_1'>
        <pose frame=''>0.752149 2.5546 0.49986 -5.7e-05 -0 -1.56903</pose>
        <scale>0.999099 1.34049 0.999978</scale>
        <link name='link'>
          <pose frame=''>0.752149 2.5546 0.49986 -5.7e-05 -0 -1.56903</pose>
          <velocity>0 0 0 0 -0 0</velocity>
          <acceleration>1.62 0.00285 0 -0.03069 -1.51518 -0</acceleration>
          <wrench>1.62 0.00285 0 0 -0 0</wrench>
        </link>
      </model>
      <model name='unit_box_8_0_clone_clone_2'>
        <pose frame=''>-2.91329 1.68996 0.499999 0 1e-06 -0.001606</pose>
        <scale>1 0.906229 1</scale>
        <link name='link'>
          <pose frame=''>-2.91329 1.68996 0.499999 0 1e-06 -0.001606</pose>
          <velocity>0 0 0 0 -0 0</velocity>
          <acceleration>0.05922 -0.09702 -1.52298 0.349549 0.11237 -0.001204</acceleration>
          <wrench>0.05922 -0.09702 -1.52298 0 -0 0</wrench>
        </link>
      </model>
      <light name='sun'>
        <pose frame=''>0 0 10 0 -0 0</pose>
      </light>
    </state>
    <gui fullscreen='0'>
      <camera name='user_camera'>
        <pose frame=''>-0.226289 -3.48518 16.7105 -0.206118 1.57079 2.93452</pose>
        <view_controller>orbit</view_controller>
        <projection_type>perspective</projection_type>
      </camera>
    </gui>
    <model name='robot'>
      <link name='kdl_dummy_root'>
        <pose frame=''>0 0 0 0 -0 0</pose>
        <inertial>
          <pose frame=''>-0.0366 0 0 0 -0 0</pose>
          <mass>0.103</mass>
          <inertia>
            <ixx>3.4814e-05</ixx>
            <ixy>0</ixy>
            <ixz>1.22354e-21</ixz>
            <iyy>5.4796e-05</iyy>
            <iyz>0</iyz>
            <izz>5.4796e-05</izz>
          </inertia>
        </inertial>
        <collision name='kdl_dummy_root_fixed_joint_lump__SA001__MoJo__INPUT_INTERFACE_collision'>
          <pose frame=''>-0.0183 0 0 3.14159 -1.57079 3.14159</pose>
          <geometry>
            <cylinder>
              <length>0.033</length>
              <radius>0.026</radius>
            </cylinder>
          </geometry>
          <surface>
            <contact>
              <ode/>
            </contact>
            <friction>
              <ode>
                <mu>0.9</mu>
                <mu2>0.9</mu2>
              </ode>
              <torsional>
                <ode/>
              </torsional>
            </friction>
            <bounce/>
          </surface>
          <max_contacts>10</max_contacts>
        </collision>
        <visual name='kdl_dummy_root_fixed_joint_lump__SA001__MoJo__INPUT_INTERFACE_visual'>
          <pose frame=''>-0.035 0 0 3.14159 -1.57079 -1.57084</pose>
          <geometry>
            <mesh>
              <scale>1 1 1</scale>
              <uri>/home/tarun/snake_ws/src/snake_monster/meshes/rotary_input.stl</uri>
            </mesh>
          </geometry>
          <material>
            <script>
              <name>Gazebo/Red</name>
              <uri>file://media/materials/scripts/gazebo.material</uri>
            </script>
          </material>
        </visual>
        <visual name='kdl_dummy_root_fixed_joint_lump__SA001__MoJo__INPUT_INTERFACE__COLLAR_visual_1'>
          <pose frame=''>-0.005 0 0 3.14159 -1.57079 3.14159</pose>
          <geometry>
            <cylinder>
              <length>0.01</length>
              <radius>0.026</radius>
            </cylinder>
          </geometry>
          <material>
            <script>
              <name>Gazebo/Black</name>
              <uri>file://media/materials/scripts/gazebo.material</uri>
            </script>
          </material>
        </visual>
        <velocity_decay/>
        <gravity>1</gravity>
        <velocity_decay/>
        <self_collide>1</self_collide>
        <kinematic>0</kinematic>
      </link>
      <link name='SA001__MoJo__OUTPUT_BODY'>
        <pose frame=''>-0.0366 0 0 3.14159 -1.57079 3.14159</pose>
        <inertial>
          <pose frame=''>0 0 0.03195 0 -0 0</pose>
          <mass>0.206</mass>
          <inertia>
            <ixx>0.000319877</ixx>
            <ixy>0</ixy>
            <ixz>0</ixz>
            <iyy>0.000319877</iyy>
            <iyz>0</iyz>
            <izz>6.9628e-05</izz>
          </inertia>
        </inertial>
        <collision name='SA001__MoJo__OUTPUT_BODY_collision'>
          <pose frame=''>0 0 0.0183 0 -0 0</pose>
          <geometry>
            <cylinder>
              <length>0.033</length>
              <radius>0.026</radius>
            </cylinder>
          </geometry>
          <surface>
            <contact>
              <ode/>
            </contact>
            <friction>
              <ode>
                <mu>0.9</mu>
                <mu2>0.9</mu2>
              </ode>
              <torsional>
                <ode/>
              </torsional>
            </friction>
            <bounce/>
          </surface>
          <max_contacts>10</max_contacts>
        </collision>
        <collision name='SA001__MoJo__OUTPUT_BODY_fixed_joint_lump__SA002__MoJo__INPUT_INTERFACE_collision_1'>
          <pose frame=''>0 0 0.0456 0 0 -1.57075</pose>
          <geometry>
            <cylinder>
              <length>0.033</length>
              <radius>0.026</radius>
            </cylinder>
          </geometry>
          <surface>
            <contact>
              <ode/>
            </contact>
            <friction>
              <ode>
                <mu>0.9</mu>
                <mu2>0.9</mu2>
              </ode>
              <torsional>
                <ode/>
              </torsional>
            </friction>
            <bounce/>
          </surface>
          <max_contacts>10</max_contacts>
        </collision>
        <visual name='SA001__MoJo__OUTPUT_BODY_visual'>
          <pose frame=''>0 0 0 1.57075 -0 0</pose>
          <geometry>
            <mesh>
              <scale>1 1 1</scale>
              <uri>/home/tarun/snake_ws/src/snake_monster/meshes/rotary_output.stl</uri>
            </mesh>
          </geometry>
          <material>
            <script>
              <name>Gazebo/Red</name>
              <uri>file://media/materials/scripts/gazebo.material</uri>
            </script>
          </material>
        </visual>
        <visual name='SA001__MoJo__OUTPUT_BODY_fixed_joint_lump__SA002__MoJo__INPUT_INTERFACE_visual_1'>
          <pose frame=''>0 0 0.0623 1.57075 -0 -1.57075</pose>
          <geometry>
            <mesh>
              <scale>1 1 1</scale>
              <uri>/home/tarun/snake_ws/src/snake_monster/meshes/rotary_input.stl</uri>
            </mesh>
          </geometry>
          <material>
            <script>
              <name>Gazebo/Red</name>
              <uri>file://media/materials/scripts/gazebo.material</uri>
            </script>
          </material>
        </visual>
        <visual name='SA001__MoJo__OUTPUT_BODY_fixed_joint_lump__SA002__MoJo__INPUT_INTERFACE__COLLAR_visual_2'>
          <pose frame=''>0 0 0.0323 0 0 -1.57075</pose>
          <geometry>
            <cylinder>
              <length>0.01</length>
              <radius>0.026</radius>
            </cylinder>
          </geometry>
          <material>
            <script>
              <name>Gazebo/Black</name>
              <uri>file://media/materials/scripts/gazebo.material</uri>
            </script>
          </material>
        </visual>
        <velocity_decay/>
        <velocity_decay/>
        <gravity>1</gravity>
        <velocity_decay/>
        <self_collide>1</self_collide>
        <kinematic>0</kinematic>
      </link>
      <joint name='SA001__MoJo' type='revolute'>
        <child>SA001__MoJo__OUTPUT_BODY</child>
        <parent>kdl_dummy_root</parent>
        <axis>
          <xyz>0 1 0</xyz>
          <limit>
            <lower>-1.57</lower>
            <upper>1.57</upper>
            <effort>7</effort>
            <velocity>2.20893</velocity>
          </limit>
          <dynamics>
            <damping>0.1</damping>
            <friction>0.2</friction>
            <spring_reference>0</spring_reference>
            <spring_stiffness>0</spring_stiffness>
          </dynamics>
          <use_parent_model_frame>1</use_parent_model_frame>
        </axis>
      </joint>
      <link name='SA002__MoJo__OUTPUT_BODY'>
        <pose frame=''>-0.1005 0 0 1.5708 -4.6e-05 -1.5708</pose>
        <inertial>
          <pose frame=''>0 0 0.03195 0 -0 0</pose>
          <mass>0.206</mass>
          <inertia>
            <ixx>0.000319877</ixx>
            <ixy>0</ixy>
            <ixz>0</ixz>
            <iyy>0.000319877</iyy>
            <iyz>0</iyz>
            <izz>6.9628e-05</izz>
          </inertia>
        </inertial>
        <collision name='SA002__MoJo__OUTPUT_BODY_collision'>
          <pose frame=''>0 0 0.0183 0 -0 0</pose>
          <geometry>
            <cylinder>
              <length>0.033</length>
              <radius>0.026</radius>
            </cylinder>
          </geometry>
          <surface>
            <contact>
              <ode/>
            </contact>
            <friction>
              <ode>
                <mu>0.9</mu>
                <mu2>0.9</mu2>
              </ode>
              <torsional>
                <ode/>
              </torsional>
            </friction>
            <bounce/>
          </surface>
          <max_contacts>10</max_contacts>
        </collision>
        <collision name='SA002__MoJo__OUTPUT_BODY_fixed_joint_lump__SA003__MoJo__INPUT_INTERFACE_collision_1'>
          <pose frame=''>0 0 0.0456 0 0 -1.57075</pose>
          <geometry>
            <cylinder>
              <length>0.033</length>
              <radius>0.026</radius>
            </cylinder>
          </geometry>
          <surface>
            <contact>
              <ode/>
            </contact>
            <friction>
              <ode>
                <mu>0.9</mu>
                <mu2>0.9</mu2>
              </ode>
              <torsional>
                <ode/>
              </torsional>
            </friction>
            <bounce/>
          </surface>
          <max_contacts>10</max_contacts>
        </collision>
        <visual name='SA002__MoJo__OUTPUT_BODY_visual'>
          <pose frame=''>0 0 0 1.57075 -0 0</pose>
          <geometry>
            <mesh>
              <scale>1 1 1</scale>
              <uri>/home/tarun/snake_ws/src/snake_monster/meshes/rotary_output.stl</uri>
            </mesh>
          </geometry>
          <material>
            <script>
              <name>Gazebo/Red</name>
              <uri>file://media/materials/scripts/gazebo.material</uri>
            </script>
          </material>
        </visual>
        <visual name='SA002__MoJo__OUTPUT_BODY_fixed_joint_lump__SA003__MoJo__INPUT_INTERFACE_visual_1'>
          <pose frame=''>0 0 0.0623 1.57075 -0 -1.57075</pose>
          <geometry>
            <mesh>
              <scale>1 1 1</scale>
              <uri>/home/tarun/snake_ws/src/snake_monster/meshes/rotary_input.stl</uri>
            </mesh>
          </geometry>
          <material>
            <script>
              <name>Gazebo/Red</name>
              <uri>file://media/materials/scripts/gazebo.material</uri>
            </script>
          </material>
        </visual>
        <visual name='SA002__MoJo__OUTPUT_BODY_fixed_joint_lump__SA003__MoJo__INPUT_INTERFACE__COLLAR_visual_2'>
          <pose frame=''>0 0 0.0323 0 0 -1.57075</pose>
          <geometry>
            <cylinder>
              <length>0.01</length>
              <radius>0.026</radius>
            </cylinder>
          </geometry>
          <material>
            <script>
              <name>Gazebo/Black</name>
              <uri>file://media/materials/scripts/gazebo.material</uri>
            </script>
          </material>
        </visual>
        <velocity_decay/>
        <velocity_decay/>
        <gravity>1</gravity>
        <velocity_decay/>
        <self_collide>1</self_collide>
        <kinematic>0</kinematic>
      </link>
      <joint name='SA002__MoJo' type='revolute'>
        <child>SA002__MoJo__OUTPUT_BODY</child>
        <parent>SA001__MoJo__OUTPUT_BODY</parent>
        <axis>
          <xyz>0 4.6e-05 1</xyz>
          <limit>
            <lower>-1.57</lower>
            <upper>1.57</upper>
            <effort>7</effort>
            <velocity>2.20893</velocity>
          </limit>
          <dynamics>
            <damping>0.1</damping>
            <friction>0.2</friction>
            <spring_reference>0</spring_reference>
            <spring_stiffness>0</spring_stiffness>
          </dynamics>
          <use_parent_model_frame>1</use_parent_model_frame>
        </axis>
      </joint>
      <link name='SA003__MoJo__OUTPUT_BODY'>
        <pose frame=''>-0.1644 0 0 1.5708 1.5707 -1.5708</pose>
        <inertial>
          <pose frame=''>0 0 0.03195 0 -0 0</pose>
          <mass>0.206</mass>
          <inertia>
            <ixx>0.000319877</ixx>
            <ixy>0</ixy>
            <ixz>0</ixz>
            <iyy>0.000319877</iyy>
            <iyz>0</iyz>
            <izz>6.9628e-05</izz>
          </inertia>
        </inertial>
        <collision name='SA003__MoJo__OUTPUT_BODY_collision'>
          <pose frame=''>0 0 0.0183 0 -0 0</pose>
          <geometry>
            <cylinder>
              <length>0.033</length>
              <radius>0.026</radius>
            </cylinder>
          </geometry>
          <surface>
            <contact>
              <ode/>
            </contact>
            <friction>
              <ode>
                <mu>0.9</mu>
                <mu2>0.9</mu2>
              </ode>
              <torsional>
                <ode/>
              </torsional>
            </friction>
            <bounce/>
          </surface>
          <max_contacts>10</max_contacts>
        </collision>
        <collision name='SA003__MoJo__OUTPUT_BODY_fixed_joint_lump__SA004__MoJo__INPUT_INTERFACE_collision_1'>
          <pose frame=''>0 0 0.0456 0 0 -1.57075</pose>
          <geometry>
            <cylinder>
              <length>0.033</length>
              <radius>0.026</radius>
            </cylinder>
          </geometry>
          <surface>
            <contact>
              <ode/>
            </contact>
            <friction>
              <ode>
                <mu>0.9</mu>
                <mu2>0.9</mu2>
              </ode>
              <torsional>
                <ode/>
              </torsional>
            </friction>
            <bounce/>
          </surface>
          <max_contacts>10</max_contacts>
        </collision>
        <visual name='SA003__MoJo__OUTPUT_BODY_visual'>
          <pose frame=''>0 0 0 1.57075 -0 0</pose>
          <geometry>
            <mesh>
              <scale>1 1 1</scale>
              <uri>/home/tarun/snake_ws/src/snake_monster/meshes/rotary_output.stl</uri>
            </mesh>
          </geometry>
          <material>
            <script>
              <name>Gazebo/Red</name>
              <uri>file://media/materials/scripts/gazebo.material</uri>
            </script>
          </material>
        </visual>
        <visual name='SA003__MoJo__OUTPUT_BODY_fixed_joint_lump__SA004__MoJo__INPUT_INTERFACE_visual_1'>
          <pose frame=''>0 0 0.0623 1.57075 -0 -1.57075</pose>
          <geometry>
            <mesh>
              <scale>1 1 1</scale>
              <uri>/home/tarun/snake_ws/src/snake_monster/meshes/rotary_input.stl</uri>
            </mesh>
          </geometry>
          <material>
            <script>
              <name>Gazebo/Red</name>
              <uri>file://media/materials/scripts/gazebo.material</uri>
            </script>
          </material>
        </visual>
        <visual name='SA003__MoJo__OUTPUT_BODY_fixed_joint_lump__SA004__MoJo__INPUT_INTERFACE__COLLAR_visual_2'>
          <pose frame=''>0 0 0.0323 0 0 -1.57075</pose>
          <geometry>
            <cylinder>
              <length>0.01</length>
              <radius>0.026</radius>
            </cylinder>
          </geometry>
          <material>
            <script>
              <name>Gazebo/Black</name>
              <uri>file://media/materials/scripts/gazebo.material</uri>
            </script>
          </material>
        </visual>
        <velocity_decay/>
        <velocity_decay/>
        <gravity>1</gravity>
        <velocity_decay/>
        <self_collide>1</self_collide>
        <kinematic>0</kinematic>
      </link>
      <joint name='SA003__MoJo' type='revolute'>
        <child>SA003__MoJo__OUTPUT_BODY</child>
        <parent>SA002__MoJo__OUTPUT_BODY</parent>
        <axis>
          <xyz>0 -1 9.3e-05</xyz>
          <limit>
            <lower>-1.57</lower>
            <upper>1.57</upper>
            <effort>7</effort>
            <velocity>2.20893</velocity>
          </limit>
          <dynamics>
            <damping>0.1</damping>
            <friction>0.2</friction>
            <spring_reference>0</spring_reference>
            <spring_stiffness>0</spring_stiffness>
          </dynamics>
          <use_parent_model_frame>1</use_parent_model_frame>
        </axis>
      </joint>
      <link name='SA004__MoJo__OUTPUT_BODY'>
        <pose frame=''>-0.2283 -0 0 -1.5708 0.000139 1.5708</pose>
        <inertial>
          <pose frame=''>0 0 0.03195 0 -0 0</pose>
          <mass>0.206</mass>
          <inertia>
            <ixx>0.000319877</ixx>
            <ixy>0</ixy>
            <ixz>0</ixz>
            <iyy>0.000319877</iyy>
            <iyz>0</iyz>
            <izz>6.9628e-05</izz>
          </inertia>
        </inertial>
        <collision name='SA004__MoJo__OUTPUT_BODY_collision'>
          <pose frame=''>0 0 0.0183 0 -0 0</pose>
          <geometry>
            <cylinder>
              <length>0.033</length>
              <radius>0.026</radius>
            </cylinder>
          </geometry>
          <surface>
            <contact>
              <ode/>
            </contact>
            <friction>
              <ode>
                <mu>0.9</mu>
                <mu2>0.9</mu2>
              </ode>
              <torsional>
                <ode/>
              </torsional>
            </friction>
            <bounce/>
          </surface>
          <max_contacts>10</max_contacts>
        </collision>
        <collision name='SA004__MoJo__OUTPUT_BODY_fixed_joint_lump__SA005__MoJo__INPUT_INTERFACE_collision_1'>
          <pose frame=''>0 0 0.0456 0 0 -1.57075</pose>
          <geometry>
            <cylinder>
              <length>0.033</length>
              <radius>0.026</radius>
            </cylinder>
          </geometry>
          <surface>
            <contact>
              <ode/>
            </contact>
            <friction>
              <ode>
                <mu>0.9</mu>
                <mu2>0.9</mu2>
              </ode>
              <torsional>
                <ode/>
              </torsional>
            </friction>
            <bounce/>
          </surface>
          <max_contacts>10</max_contacts>
        </collision>
        <visual name='SA004__MoJo__OUTPUT_BODY_visual'>
          <pose frame=''>0 0 0 1.57075 -0 0</pose>
          <geometry>
            <mesh>
              <scale>1 1 1</scale>
              <uri>/home/tarun/snake_ws/src/snake_monster/meshes/rotary_output.stl</uri>
            </mesh>
          </geometry>
          <material>
            <script>
              <name>Gazebo/Red</name>
              <uri>file://media/materials/scripts/gazebo.material</uri>
            </script>
          </material>
        </visual>
        <visual name='SA004__MoJo__OUTPUT_BODY_fixed_joint_lump__SA005__MoJo__INPUT_INTERFACE_visual_1'>
          <pose frame=''>0 0 0.0623 1.57075 -0 -1.57075</pose>
          <geometry>
            <mesh>
              <scale>1 1 1</scale>
              <uri>/home/tarun/snake_ws/src/snake_monster/meshes/rotary_input.stl</uri>
            </mesh>
          </geometry>
          <material>
            <script>
              <name>Gazebo/Red</name>
              <uri>file://media/materials/scripts/gazebo.material</uri>
            </script>
          </material>
        </visual>
        <visual name='SA004__MoJo__OUTPUT_BODY_fixed_joint_lump__SA005__MoJo__INPUT_INTERFACE__COLLAR_visual_2'>
          <pose frame=''>0 0 0.0323 0 0 -1.57075</pose>
          <geometry>
            <cylinder>
              <length>0.01</length>
              <radius>0.026</radius>
            </cylinder>
          </geometry>
          <material>
            <script>
              <name>Gazebo/Black</name>
              <uri>file://media/materials/scripts/gazebo.material</uri>
            </script>
          </material>
        </visual>
        <velocity_decay/>
        <velocity_decay/>
        <gravity>1</gravity>
        <velocity_decay/>
        <self_collide>1</self_collide>
        <kinematic>0</kinematic>
      </link>
      <joint name='SA004__MoJo' type='revolute'>
        <child>SA004__MoJo__OUTPUT_BODY</child>
        <parent>SA003__MoJo__OUTPUT_BODY</parent>
        <axis>
          <xyz>0 -0.000139 -1</xyz>
          <limit>
            <lower>-1.57</lower>
            <upper>1.57</upper>
            <effort>7</effort>
            <velocity>2.20893</velocity>
          </limit>
          <dynamics>
            <damping>0.1</damping>
            <friction>0.2</friction>
            <spring_reference>0</spring_reference>
            <spring_stiffness>0</spring_stiffness>
          </dynamics>
          <use_parent_model_frame>1</use_parent_model_frame>
        </axis>
      </joint>
      <link name='SA005__MoJo__OUTPUT_BODY'>
        <pose frame=''>-0.2922 -0 0 -1.5708 -1.57061 1.5708</pose>
        <inertial>
          <pose frame=''>0 0 0.03195 0 -0 0</pose>
          <mass>0.206</mass>
          <inertia>
            <ixx>0.000319877</ixx>
            <ixy>0</ixy>
            <ixz>0</ixz>
            <iyy>0.000319877</iyy>
            <iyz>0</iyz>
            <izz>6.9628e-05</izz>
          </inertia>
        </inertial>
        <collision name='SA005__MoJo__OUTPUT_BODY_collision'>
          <pose frame=''>0 0 0.0183 0 -0 0</pose>
          <geometry>
            <cylinder>
              <length>0.033</length>
              <radius>0.026</radius>
            </cylinder>
          </geometry>
          <surface>
            <contact>
              <ode/>
            </contact>
            <friction>
              <ode>
                <mu>0.9</mu>
                <mu2>0.9</mu2>
              </ode>
              <torsional>
                <ode/>
              </torsional>
            </friction>
            <bounce/>
          </surface>
          <max_contacts>10</max_contacts>
        </collision>
        <collision name='SA005__MoJo__OUTPUT_BODY_fixed_joint_lump__SA006__MoJo__INPUT_INTERFACE_collision_1'>
          <pose frame=''>0 0 0.0456 0 0 -1.57075</pose>
          <geometry>
            <cylinder>
              <length>0.033</length>
              <radius>0.026</radius>
            </cylinder>
          </geometry>
          <surface>
            <contact>
              <ode/>
            </contact>
            <friction>
              <ode>
                <mu>0.9</mu>
                <mu2>0.9</mu2>
              </ode>
              <torsional>
                <ode/>
              </torsional>
            </friction>
            <bounce/>
          </surface>
          <max_contacts>10</max_contacts>
        </collision>
        <visual name='SA005__MoJo__OUTPUT_BODY_visual'>
          <pose frame=''>0 0 0 1.57075 -0 0</pose>
          <geometry>
            <mesh>
              <scale>1 1 1</scale>
              <uri>/home/tarun/snake_ws/src/snake_monster/meshes/rotary_output.stl</uri>
            </mesh>
          </geometry>
          <material>
            <script>
              <name>Gazebo/Red</name>
              <uri>file://media/materials/scripts/gazebo.material</uri>
            </script>
          </material>
        </visual>
        <visual name='SA005__MoJo__OUTPUT_BODY_fixed_joint_lump__SA006__MoJo__INPUT_INTERFACE_visual_1'>
          <pose frame=''>0 0 0.0623 1.57075 -0 -1.57075</pose>
          <geometry>
            <mesh>
              <scale>1 1 1</scale>
              <uri>/home/tarun/snake_ws/src/snake_monster/meshes/rotary_input.stl</uri>
            </mesh>
          </geometry>
          <material>
            <script>
              <name>Gazebo/Red</name>
              <uri>file://media/materials/scripts/gazebo.material</uri>
            </script>
          </material>
        </visual>
        <visual name='SA005__MoJo__OUTPUT_BODY_fixed_joint_lump__SA006__MoJo__INPUT_INTERFACE__COLLAR_visual_2'>
          <pose frame=''>0 0 0.0323 0 0 -1.57075</pose>
          <geometry>
            <cylinder>
              <length>0.01</length>
              <radius>0.026</radius>
            </cylinder>
          </geometry>
          <material>
            <script>
              <name>Gazebo/Black</name>
              <uri>file://media/materials/scripts/gazebo.material</uri>
            </script>
          </material>
        </visual>
        <velocity_decay/>
        <velocity_decay/>
        <gravity>1</gravity>
        <velocity_decay/>
        <self_collide>1</self_collide>
        <kinematic>0</kinematic>
      </link>
      <joint name='SA005__MoJo' type='revolute'>
        <child>SA005__MoJo__OUTPUT_BODY</child>
        <parent>SA004__MoJo__OUTPUT_BODY</parent>
        <axis>
          <xyz>0 1 -0.000185</xyz>
          <limit>
            <lower>-1.57</lower>
            <upper>1.57</upper>
            <effort>7</effort>
            <velocity>2.20893</velocity>
          </limit>
          <dynamics>
            <damping>0.1</damping>
            <friction>0.2</friction>
            <spring_reference>0</spring_reference>
            <spring_stiffness>0</spring_stiffness>
          </dynamics>
          <use_parent_model_frame>1</use_parent_model_frame>
        </axis>
      </joint>
      <link name='SA006__MoJo__OUTPUT_BODY'>
        <pose frame=''>-0.3561 -0 0 1.5708 -0.000232 -1.5708</pose>
        <inertial>
          <pose frame=''>0 0 0.03195 0 -0 0</pose>
          <mass>0.206</mass>
          <inertia>
            <ixx>0.000319877</ixx>
            <ixy>0</ixy>
            <ixz>0</ixz>
            <iyy>0.000319877</iyy>
            <iyz>0</iyz>
            <izz>6.9628e-05</izz>
          </inertia>
        </inertial>
        <collision name='SA006__MoJo__OUTPUT_BODY_collision'>
          <pose frame=''>0 0 0.0183 0 -0 0</pose>
          <geometry>
            <cylinder>
              <length>0.033</length>
              <radius>0.026</radius>
            </cylinder>
          </geometry>
          <surface>
            <contact>
              <ode/>
            </contact>
            <friction>
              <ode>
                <mu>0.9</mu>
                <mu2>0.9</mu2>
              </ode>
              <torsional>
                <ode/>
              </torsional>
            </friction>
            <bounce/>
          </surface>
          <max_contacts>10</max_contacts>
        </collision>
        <collision name='SA006__MoJo__OUTPUT_BODY_fixed_joint_lump__SA007__MoJo__INPUT_INTERFACE_collision_1'>
          <pose frame=''>0 0 0.0456 0 0 -1.57075</pose>
          <geometry>
            <cylinder>
              <length>0.033</length>
              <radius>0.026</radius>
            </cylinder>
          </geometry>
          <surface>
            <contact>
              <ode/>
            </contact>
            <friction>
              <ode>
                <mu>0.9</mu>
                <mu2>0.9</mu2>
              </ode>
              <torsional>
                <ode/>
              </torsional>
            </friction>
            <bounce/>
          </surface>
          <max_contacts>10</max_contacts>
        </collision>
        <visual name='SA006__MoJo__OUTPUT_BODY_visual'>
          <pose frame=''>0 0 0 1.57075 -0 0</pose>
          <geometry>
            <mesh>
              <scale>1 1 1</scale>
              <uri>/home/tarun/snake_ws/src/snake_monster/meshes/rotary_output.stl</uri>
            </mesh>
          </geometry>
          <material>
            <script>
              <name>Gazebo/Red</name>
              <uri>file://media/materials/scripts/gazebo.material</uri>
            </script>
          </material>
        </visual>
        <visual name='SA006__MoJo__OUTPUT_BODY_fixed_joint_lump__SA007__MoJo__INPUT_INTERFACE_visual_1'>
          <pose frame=''>0 0 0.0623 1.57075 -0 -1.57075</pose>
          <geometry>
            <mesh>
              <scale>1 1 1</scale>
              <uri>/home/tarun/snake_ws/src/snake_monster/meshes/rotary_input.stl</uri>
            </mesh>
          </geometry>
          <material>
            <script>
              <name>Gazebo/Red</name>
              <uri>file://media/materials/scripts/gazebo.material</uri>
            </script>
          </material>
        </visual>
        <visual name='SA006__MoJo__OUTPUT_BODY_fixed_joint_lump__SA007__MoJo__INPUT_INTERFACE__COLLAR_visual_2'>
          <pose frame=''>0 0 0.0323 0 0 -1.57075</pose>
          <geometry>
            <cylinder>
              <length>0.01</length>
              <radius>0.026</radius>
            </cylinder>
          </geometry>
          <material>
            <script>
              <name>Gazebo/Black</name>
              <uri>file://media/materials/scripts/gazebo.material</uri>
            </script>
          </material>
        </visual>
        <velocity_decay/>
        <velocity_decay/>
        <gravity>1</gravity>
        <velocity_decay/>
        <self_collide>1</self_collide>
        <kinematic>0</kinematic>
      </link>
      <joint name='SA006__MoJo' type='revolute'>
        <child>SA006__MoJo__OUTPUT_BODY</child>
        <parent>SA005__MoJo__OUTPUT_BODY</parent>
        <axis>
          <xyz>0 0.000232 1</xyz>
          <limit>
            <lower>-1.57</lower>
            <upper>1.57</upper>
            <effort>7</effort>
            <velocity>2.20893</velocity>
          </limit>
          <dynamics>
            <damping>0.1</damping>
            <friction>0.2</friction>
            <spring_reference>0</spring_reference>
            <spring_stiffness>0</spring_stiffness>
          </dynamics>
          <use_parent_model_frame>1</use_parent_model_frame>
        </axis>
      </joint>
      <link name='SA007__MoJo__OUTPUT_BODY'>
        <pose frame=''>-0.42 -0 0 1.5708 1.57052 -1.5708</pose>
        <inertial>
          <pose frame=''>0 0 0.03195 0 -0 0</pose>
          <mass>0.206</mass>
          <inertia>
            <ixx>0.000319877</ixx>
            <ixy>0</ixy>
            <ixz>0</ixz>
            <iyy>0.000319877</iyy>
            <iyz>0</iyz>
            <izz>6.9628e-05</izz>
          </inertia>
        </inertial>
        <collision name='SA007__MoJo__OUTPUT_BODY_collision'>
          <pose frame=''>0 0 0.0183 0 -0 0</pose>
          <geometry>
            <cylinder>
              <length>0.033</length>
              <radius>0.026</radius>
            </cylinder>
          </geometry>
          <surface>
            <contact>
              <ode/>
            </contact>
            <friction>
              <ode>
                <mu>0.9</mu>
                <mu2>0.9</mu2>
              </ode>
              <torsional>
                <ode/>
              </torsional>
            </friction>
            <bounce/>
          </surface>
          <max_contacts>10</max_contacts>
        </collision>
        <collision name='SA007__MoJo__OUTPUT_BODY_fixed_joint_lump__SA008__MoJo__INPUT_INTERFACE_collision_1'>
          <pose frame=''>0 0 0.0456 0 0 -1.57075</pose>
          <geometry>
            <cylinder>
              <length>0.033</length>
              <radius>0.026</radius>
            </cylinder>
          </geometry>
          <surface>
            <contact>
              <ode/>
            </contact>
            <friction>
              <ode>
                <mu>0.9</mu>
                <mu2>0.9</mu2>
              </ode>
              <torsional>
                <ode/>
              </torsional>
            </friction>
            <bounce/>
          </surface>
          <max_contacts>10</max_contacts>
        </collision>
        <visual name='SA007__MoJo__OUTPUT_BODY_visual'>
          <pose frame=''>0 0 0 1.57075 -0 0</pose>
          <geometry>
            <mesh>
              <scale>1 1 1</scale>
              <uri>/home/tarun/snake_ws/src/snake_monster/meshes/rotary_output.stl</uri>
            </mesh>
          </geometry>
          <material>
            <script>
              <name>Gazebo/Red</name>
              <uri>file://media/materials/scripts/gazebo.material</uri>
            </script>
          </material>
        </visual>
        <visual name='SA007__MoJo__OUTPUT_BODY_fixed_joint_lump__SA008__MoJo__INPUT_INTERFACE_visual_1'>
          <pose frame=''>0 0 0.0623 1.57075 -0 -1.57075</pose>
          <geometry>
            <mesh>
              <scale>1 1 1</scale>
              <uri>/home/tarun/snake_ws/src/snake_monster/meshes/rotary_input.stl</uri>
            </mesh>
          </geometry>
          <material>
            <script>
              <name>Gazebo/Red</name>
              <uri>file://media/materials/scripts/gazebo.material</uri>
            </script>
          </material>
        </visual>
        <visual name='SA007__MoJo__OUTPUT_BODY_fixed_joint_lump__SA008__MoJo__INPUT_INTERFACE__COLLAR_visual_2'>
          <pose frame=''>0 0 0.0323 0 0 -1.57075</pose>
          <geometry>
            <cylinder>
              <length>0.01</length>
              <radius>0.026</radius>
            </cylinder>
          </geometry>
          <material>
            <script>
              <name>Gazebo/Black</name>
              <uri>file://media/materials/scripts/gazebo.material</uri>
            </script>
          </material>
        </visual>
        <velocity_decay/>
        <velocity_decay/>
        <gravity>1</gravity>
        <velocity_decay/>
        <self_collide>1</self_collide>
        <kinematic>0</kinematic>
      </link>
      <joint name='SA007__MoJo' type='revolute'>
        <child>SA007__MoJo__OUTPUT_BODY</child>
        <parent>SA006__MoJo__OUTPUT_BODY</parent>
        <axis>
          <xyz>0 -1 0.000278</xyz>
          <limit>
            <lower>-1.57</lower>
            <upper>1.57</upper>
            <effort>7</effort>
            <velocity>2.20893</velocity>
          </limit>
          <dynamics>
            <damping>0.1</damping>
            <friction>0.2</friction>
            <spring_reference>0</spring_reference>
            <spring_stiffness>0</spring_stiffness>
          </dynamics>
          <use_parent_model_frame>1</use_parent_model_frame>
        </axis>
      </joint>
      <link name='SA008__MoJo__OUTPUT_BODY'>
        <pose frame=''>-0.4839 -0 0 -1.5708 0.000324 1.5708</pose>
        <inertial>
          <pose frame=''>0 0 0.03195 0 -0 0</pose>
          <mass>0.206</mass>
          <inertia>
            <ixx>0.000319877</ixx>
            <ixy>0</ixy>
            <ixz>0</ixz>
            <iyy>0.000319877</iyy>
            <iyz>0</iyz>
            <izz>6.9628e-05</izz>
          </inertia>
        </inertial>
        <collision name='SA008__MoJo__OUTPUT_BODY_collision'>
          <pose frame=''>0 0 0.0183 0 -0 0</pose>
          <geometry>
            <cylinder>
              <length>0.033</length>
              <radius>0.026</radius>
            </cylinder>
          </geometry>
          <surface>
            <contact>
              <ode/>
            </contact>
            <friction>
              <ode>
                <mu>0.9</mu>
                <mu2>0.9</mu2>
              </ode>
              <torsional>
                <ode/>
              </torsional>
            </friction>
            <bounce/>
          </surface>
          <max_contacts>10</max_contacts>
        </collision>
        <collision name='SA008__MoJo__OUTPUT_BODY_fixed_joint_lump__SA009__MoJo__INPUT_INTERFACE_collision_1'>
          <pose frame=''>0 0 0.0456 0 0 -1.57075</pose>
          <geometry>
            <cylinder>
              <length>0.033</length>
              <radius>0.026</radius>
            </cylinder>
          </geometry>
          <surface>
            <contact>
              <ode/>
            </contact>
            <friction>
              <ode>
                <mu>0.9</mu>
                <mu2>0.9</mu2>
              </ode>
              <torsional>
                <ode/>
              </torsional>
            </friction>
            <bounce/>
          </surface>
          <max_contacts>10</max_contacts>
        </collision>
        <visual name='SA008__MoJo__OUTPUT_BODY_visual'>
          <pose frame=''>0 0 0 1.57075 -0 0</pose>
          <geometry>
            <mesh>
              <scale>1 1 1</scale>
              <uri>/home/tarun/snake_ws/src/snake_monster/meshes/rotary_output.stl</uri>
            </mesh>
          </geometry>
          <material>
            <script>
              <name>Gazebo/Red</name>
              <uri>file://media/materials/scripts/gazebo.material</uri>
            </script>
          </material>
        </visual>
        <visual name='SA008__MoJo__OUTPUT_BODY_fixed_joint_lump__SA009__MoJo__INPUT_INTERFACE_visual_1'>
          <pose frame=''>0 0 0.0623 1.57075 -0 -1.57075</pose>
          <geometry>
            <mesh>
              <scale>1 1 1</scale>
              <uri>/home/tarun/snake_ws/src/snake_monster/meshes/rotary_input.stl</uri>
            </mesh>
          </geometry>
          <material>
            <script>
              <name>Gazebo/Red</name>
              <uri>file://media/materials/scripts/gazebo.material</uri>
            </script>
          </material>
        </visual>
        <visual name='SA008__MoJo__OUTPUT_BODY_fixed_joint_lump__SA009__MoJo__INPUT_INTERFACE__COLLAR_visual_2'>
          <pose frame=''>0 0 0.0323 0 0 -1.57075</pose>
          <geometry>
            <cylinder>
              <length>0.01</length>
              <radius>0.026</radius>
            </cylinder>
          </geometry>
          <material>
            <script>
              <name>Gazebo/Black</name>
              <uri>file://media/materials/scripts/gazebo.material</uri>
            </script>
          </material>
        </visual>
        <velocity_decay/>
        <velocity_decay/>
        <gravity>1</gravity>
        <velocity_decay/>
        <self_collide>1</self_collide>
        <kinematic>0</kinematic>
      </link>
      <joint name='SA008__MoJo' type='revolute'>
        <child>SA008__MoJo__OUTPUT_BODY</child>
        <parent>SA007__MoJo__OUTPUT_BODY</parent>
        <axis>
          <xyz>0 -0.000324 -1</xyz>
          <limit>
            <lower>-1.57</lower>
            <upper>1.57</upper>
            <effort>7</effort>
            <velocity>2.20893</velocity>
          </limit>
          <dynamics>
            <damping>0.1</damping>
            <friction>0.2</friction>
            <spring_reference>0</spring_reference>
            <spring_stiffness>0</spring_stiffness>
          </dynamics>
          <use_parent_model_frame>1</use_parent_model_frame>
        </axis>
      </joint>
      <link name='SA009__MoJo__OUTPUT_BODY'>
        <pose frame=''>-0.5478 -0 0 -1.5708 -1.57043 1.5708</pose>
        <inertial>
          <pose frame=''>0 0 0.03195 0 -0 0</pose>
          <mass>0.206</mass>
          <inertia>
            <ixx>0.000319877</ixx>
            <ixy>0</ixy>
            <ixz>0</ixz>
            <iyy>0.000319877</iyy>
            <iyz>0</iyz>
            <izz>6.9628e-05</izz>
          </inertia>
        </inertial>
        <collision name='SA009__MoJo__OUTPUT_BODY_collision'>
          <pose frame=''>0 0 0.0183 0 -0 0</pose>
          <geometry>
            <cylinder>
              <length>0.033</length>
              <radius>0.026</radius>
            </cylinder>
          </geometry>
          <surface>
            <contact>
              <ode/>
            </contact>
            <friction>
              <ode>
                <mu>0.9</mu>
                <mu2>0.9</mu2>
              </ode>
              <torsional>
                <ode/>
              </torsional>
            </friction>
            <bounce/>
          </surface>
          <max_contacts>10</max_contacts>
        </collision>
        <collision name='SA009__MoJo__OUTPUT_BODY_fixed_joint_lump__SA010__MoJo__INPUT_INTERFACE_collision_1'>
          <pose frame=''>0 0 0.0456 0 0 -1.57075</pose>
          <geometry>
            <cylinder>
              <length>0.033</length>
              <radius>0.026</radius>
            </cylinder>
          </geometry>
          <surface>
            <contact>
              <ode/>
            </contact>
            <friction>
              <ode>
                <mu>0.9</mu>
                <mu2>0.9</mu2>
              </ode>
              <torsional>
                <ode/>
              </torsional>
            </friction>
            <bounce/>
          </surface>
          <max_contacts>10</max_contacts>
        </collision>
        <visual name='SA009__MoJo__OUTPUT_BODY_visual'>
          <pose frame=''>0 0 0 1.57075 -0 0</pose>
          <geometry>
            <mesh>
              <scale>1 1 1</scale>
              <uri>/home/tarun/snake_ws/src/snake_monster/meshes/rotary_output.stl</uri>
            </mesh>
          </geometry>
          <material>
            <script>
              <name>Gazebo/Red</name>
              <uri>file://media/materials/scripts/gazebo.material</uri>
            </script>
          </material>
        </visual>
        <visual name='SA009__MoJo__OUTPUT_BODY_fixed_joint_lump__SA010__MoJo__INPUT_INTERFACE_visual_1'>
          <pose frame=''>0 0 0.0623 1.57075 -0 -1.57075</pose>
          <geometry>
            <mesh>
              <scale>1 1 1</scale>
              <uri>/home/tarun/snake_ws/src/snake_monster/meshes/rotary_input.stl</uri>
            </mesh>
          </geometry>
          <material>
            <script>
              <name>Gazebo/Red</name>
              <uri>file://media/materials/scripts/gazebo.material</uri>
            </script>
          </material>
        </visual>
        <visual name='SA009__MoJo__OUTPUT_BODY_fixed_joint_lump__SA010__MoJo__INPUT_INTERFACE__COLLAR_visual_2'>
          <pose frame=''>0 0 0.0323 0 0 -1.57075</pose>
          <geometry>
            <cylinder>
              <length>0.01</length>
              <radius>0.026</radius>
            </cylinder>
          </geometry>
          <material>
            <script>
              <name>Gazebo/Black</name>
              <uri>file://media/materials/scripts/gazebo.material</uri>
            </script>
          </material>
        </visual>
        <velocity_decay/>
        <velocity_decay/>
        <gravity>1</gravity>
        <velocity_decay/>
        <self_collide>1</self_collide>
        <kinematic>0</kinematic>
      </link>
      <joint name='SA009__MoJo' type='revolute'>
        <child>SA009__MoJo__OUTPUT_BODY</child>
        <parent>SA008__MoJo__OUTPUT_BODY</parent>
        <axis>
          <xyz>0 1 -0.000371</xyz>
          <limit>
            <lower>-1.57</lower>
            <upper>1.57</upper>
            <effort>7</effort>
            <velocity>2.20893</velocity>
          </limit>
          <dynamics>
            <damping>0.1</damping>
            <friction>0.2</friction>
            <spring_reference>0</spring_reference>
            <spring_stiffness>0</spring_stiffness>
          </dynamics>
          <use_parent_model_frame>1</use_parent_model_frame>
        </axis>
      </joint>
      <link name='SA010__MoJo__OUTPUT_BODY'>
        <pose frame=''>-0.6117 -0 0 1.5708 -0.000417 -1.5708</pose>
        <inertial>
          <pose frame=''>0 0 0.03195 0 -0 0</pose>
          <mass>0.206</mass>
          <inertia>
            <ixx>0.000319877</ixx>
            <ixy>0</ixy>
            <ixz>0</ixz>
            <iyy>0.000319877</iyy>
            <iyz>0</iyz>
            <izz>6.9628e-05</izz>
          </inertia>
        </inertial>
        <collision name='SA010__MoJo__OUTPUT_BODY_collision'>
          <pose frame=''>0 0 0.0183 0 -0 0</pose>
          <geometry>
            <cylinder>
              <length>0.033</length>
              <radius>0.026</radius>
            </cylinder>
          </geometry>
          <surface>
            <contact>
              <ode/>
            </contact>
            <friction>
              <ode>
                <mu>0.9</mu>
                <mu2>0.9</mu2>
              </ode>
              <torsional>
                <ode/>
              </torsional>
            </friction>
            <bounce/>
          </surface>
          <max_contacts>10</max_contacts>
        </collision>
        <collision name='SA010__MoJo__OUTPUT_BODY_fixed_joint_lump__SA011__MoJo__INPUT_INTERFACE_collision_1'>
          <pose frame=''>0 0 0.0456 0 0 -1.57075</pose>
          <geometry>
            <cylinder>
              <length>0.033</length>
              <radius>0.026</radius>
            </cylinder>
          </geometry>
          <surface>
            <contact>
              <ode/>
            </contact>
            <friction>
              <ode>
                <mu>0.9</mu>
                <mu2>0.9</mu2>
              </ode>
              <torsional>
                <ode/>
              </torsional>
            </friction>
            <bounce/>
          </surface>
          <max_contacts>10</max_contacts>
        </collision>
        <visual name='SA010__MoJo__OUTPUT_BODY_visual'>
          <pose frame=''>0 0 0 1.57075 -0 0</pose>
          <geometry>
            <mesh>
              <scale>1 1 1</scale>
              <uri>/home/tarun/snake_ws/src/snake_monster/meshes/rotary_output.stl</uri>
            </mesh>
          </geometry>
          <material>
            <script>
              <name>Gazebo/Red</name>
              <uri>file://media/materials/scripts/gazebo.material</uri>
            </script>
          </material>
        </visual>
        <visual name='SA010__MoJo__OUTPUT_BODY_fixed_joint_lump__SA011__MoJo__INPUT_INTERFACE_visual_1'>
          <pose frame=''>0 0 0.0623 1.57075 -0 -1.57075</pose>
          <geometry>
            <mesh>
              <scale>1 1 1</scale>
              <uri>/home/tarun/snake_ws/src/snake_monster/meshes/rotary_input.stl</uri>
            </mesh>
          </geometry>
          <material>
            <script>
              <name>Gazebo/Red</name>
              <uri>file://media/materials/scripts/gazebo.material</uri>
            </script>
          </material>
        </visual>
        <visual name='SA010__MoJo__OUTPUT_BODY_fixed_joint_lump__SA011__MoJo__INPUT_INTERFACE__COLLAR_visual_2'>
          <pose frame=''>0 0 0.0323 0 0 -1.57075</pose>
          <geometry>
            <cylinder>
              <length>0.01</length>
              <radius>0.026</radius>
            </cylinder>
          </geometry>
          <material>
            <script>
              <name>Gazebo/Black</name>
              <uri>file://media/materials/scripts/gazebo.material</uri>
            </script>
          </material>
        </visual>
        <velocity_decay/>
        <velocity_decay/>
        <gravity>1</gravity>
        <velocity_decay/>
        <self_collide>1</self_collide>
        <kinematic>0</kinematic>
      </link>
      <joint name='SA010__MoJo' type='revolute'>
        <child>SA010__MoJo__OUTPUT_BODY</child>
        <parent>SA009__MoJo__OUTPUT_BODY</parent>
        <axis>
          <xyz>0 0.000417 1</xyz>
          <limit>
            <lower>-1.57</lower>
            <upper>1.57</upper>
            <effort>7</effort>
            <velocity>2.20893</velocity>
          </limit>
          <dynamics>
            <damping>0.1</damping>
            <friction>0.2</friction>
            <spring_reference>0</spring_reference>
            <spring_stiffness>0</spring_stiffness>
          </dynamics>
          <use_parent_model_frame>1</use_parent_model_frame>
        </axis>
      </joint>
      <link name='SA011__MoJo__OUTPUT_BODY'>
        <pose frame=''>-0.6756 -0 0 1.5708 1.57033 -1.5708</pose>
        <inertial>
          <pose frame=''>0 0 0.03195 0 -0 0</pose>
          <mass>0.206</mass>
          <inertia>
            <ixx>0.000319877</ixx>
            <ixy>0</ixy>
            <ixz>0</ixz>
            <iyy>0.000319877</iyy>
            <iyz>0</iyz>
            <izz>6.9628e-05</izz>
          </inertia>
        </inertial>
        <collision name='SA011__MoJo__OUTPUT_BODY_collision'>
          <pose frame=''>0 0 0.0183 0 -0 0</pose>
          <geometry>
            <cylinder>
              <length>0.033</length>
              <radius>0.026</radius>
            </cylinder>
          </geometry>
          <surface>
            <contact>
              <ode/>
            </contact>
            <friction>
              <ode>
                <mu>0.9</mu>
                <mu2>0.9</mu2>
              </ode>
              <torsional>
                <ode/>
              </torsional>
            </friction>
            <bounce/>
          </surface>
          <max_contacts>10</max_contacts>
        </collision>
        <collision name='SA011__MoJo__OUTPUT_BODY_fixed_joint_lump__SA012__MoJo__INPUT_INTERFACE_collision_1'>
          <pose frame=''>0 0 0.0456 0 0 -1.57075</pose>
          <geometry>
            <cylinder>
              <length>0.033</length>
              <radius>0.026</radius>
            </cylinder>
          </geometry>
          <surface>
            <contact>
              <ode/>
            </contact>
            <friction>
              <ode>
                <mu>0.9</mu>
                <mu2>0.9</mu2>
              </ode>
              <torsional>
                <ode/>
              </torsional>
            </friction>
            <bounce/>
          </surface>
          <max_contacts>10</max_contacts>
        </collision>
        <visual name='SA011__MoJo__OUTPUT_BODY_visual'>
          <pose frame=''>0 0 0 1.57075 -0 0</pose>
          <geometry>
            <mesh>
              <scale>1 1 1</scale>
              <uri>/home/tarun/snake_ws/src/snake_monster/meshes/rotary_output.stl</uri>
            </mesh>
          </geometry>
          <material>
            <script>
              <name>Gazebo/Red</name>
              <uri>file://media/materials/scripts/gazebo.material</uri>
            </script>
          </material>
        </visual>
        <visual name='SA011__MoJo__OUTPUT_BODY_fixed_joint_lump__SA012__MoJo__INPUT_INTERFACE_visual_1'>
          <pose frame=''>0 0 0.0623 1.57075 -0 -1.57075</pose>
          <geometry>
            <mesh>
              <scale>1 1 1</scale>
              <uri>/home/tarun/snake_ws/src/snake_monster/meshes/rotary_input.stl</uri>
            </mesh>
          </geometry>
          <material>
            <script>
              <name>Gazebo/Red</name>
              <uri>file://media/materials/scripts/gazebo.material</uri>
            </script>
          </material>
        </visual>
        <visual name='SA011__MoJo__OUTPUT_BODY_fixed_joint_lump__SA012__MoJo__INPUT_INTERFACE__COLLAR_visual_2'>
          <pose frame=''>0 0 0.0323 0 0 -1.57075</pose>
          <geometry>
            <cylinder>
              <length>0.01</length>
              <radius>0.026</radius>
            </cylinder>
          </geometry>
          <material>
            <script>
              <name>Gazebo/Black</name>
              <uri>file://media/materials/scripts/gazebo.material</uri>
            </script>
          </material>
        </visual>
        <velocity_decay/>
        <velocity_decay/>
        <gravity>1</gravity>
        <velocity_decay/>
        <self_collide>1</self_collide>
        <kinematic>0</kinematic>
      </link>
      <joint name='SA011__MoJo' type='revolute'>
        <child>SA011__MoJo__OUTPUT_BODY</child>
        <parent>SA010__MoJo__OUTPUT_BODY</parent>
        <axis>
          <xyz>0 -1 0.000463</xyz>
          <limit>
            <lower>-1.57</lower>
            <upper>1.57</upper>
            <effort>7</effort>
            <velocity>2.20893</velocity>
          </limit>
          <dynamics>
            <damping>0.1</damping>
            <friction>0.2</friction>
            <spring_reference>0</spring_reference>
            <spring_stiffness>0</spring_stiffness>
          </dynamics>
          <use_parent_model_frame>1</use_parent_model_frame>
        </axis>
      </joint>
      <link name='SA012__MoJo__OUTPUT_BODY'>
        <pose frame=''>-0.7395 -0 0 -1.5708 0.00051 1.5708</pose>
        <inertial>
          <pose frame=''>0 0 0.03195 0 -0 0</pose>
          <mass>0.206</mass>
          <inertia>
            <ixx>0.000319877</ixx>
            <ixy>0</ixy>
            <ixz>0</ixz>
            <iyy>0.000319877</iyy>
            <iyz>0</iyz>
            <izz>6.9628e-05</izz>
          </inertia>
        </inertial>
        <collision name='SA012__MoJo__OUTPUT_BODY_collision'>
          <pose frame=''>0 0 0.0183 0 -0 0</pose>
          <geometry>
            <cylinder>
              <length>0.033</length>
              <radius>0.026</radius>
            </cylinder>
          </geometry>
          <surface>
            <contact>
              <ode/>
            </contact>
            <friction>
              <ode>
                <mu>0.9</mu>
                <mu2>0.9</mu2>
              </ode>
              <torsional>
                <ode/>
              </torsional>
            </friction>
            <bounce/>
          </surface>
          <max_contacts>10</max_contacts>
        </collision>
        <collision name='SA012__MoJo__OUTPUT_BODY_fixed_joint_lump__SA013__MoJo__INPUT_INTERFACE_collision_1'>
          <pose frame=''>0 0 0.0456 0 0 -1.57075</pose>
          <geometry>
            <cylinder>
              <length>0.033</length>
              <radius>0.026</radius>
            </cylinder>
          </geometry>
          <surface>
            <contact>
              <ode/>
            </contact>
            <friction>
              <ode>
                <mu>0.9</mu>
                <mu2>0.9</mu2>
              </ode>
              <torsional>
                <ode/>
              </torsional>
            </friction>
            <bounce/>
          </surface>
          <max_contacts>10</max_contacts>
        </collision>
        <visual name='SA012__MoJo__OUTPUT_BODY_visual'>
          <pose frame=''>0 0 0 1.57075 -0 0</pose>
          <geometry>
            <mesh>
              <scale>1 1 1</scale>
              <uri>/home/tarun/snake_ws/src/snake_monster/meshes/rotary_output.stl</uri>
            </mesh>
          </geometry>
          <material>
            <script>
              <name>Gazebo/Red</name>
              <uri>file://media/materials/scripts/gazebo.material</uri>
            </script>
          </material>
        </visual>
        <visual name='SA012__MoJo__OUTPUT_BODY_fixed_joint_lump__SA013__MoJo__INPUT_INTERFACE_visual_1'>
          <pose frame=''>0 0 0.0623 1.57075 -0 -1.57075</pose>
          <geometry>
            <mesh>
              <scale>1 1 1</scale>
              <uri>/home/tarun/snake_ws/src/snake_monster/meshes/rotary_input.stl</uri>
            </mesh>
          </geometry>
          <material>
            <script>
              <name>Gazebo/Red</name>
              <uri>file://media/materials/scripts/gazebo.material</uri>
            </script>
          </material>
        </visual>
        <visual name='SA012__MoJo__OUTPUT_BODY_fixed_joint_lump__SA013__MoJo__INPUT_INTERFACE__COLLAR_visual_2'>
          <pose frame=''>0 0 0.0323 0 0 -1.57075</pose>
          <geometry>
            <cylinder>
              <length>0.01</length>
              <radius>0.026</radius>
            </cylinder>
          </geometry>
          <material>
            <script>
              <name>Gazebo/Black</name>
              <uri>file://media/materials/scripts/gazebo.material</uri>
            </script>
          </material>
        </visual>
        <velocity_decay/>
        <velocity_decay/>
        <gravity>1</gravity>
        <velocity_decay/>
        <self_collide>1</self_collide>
        <kinematic>0</kinematic>
      </link>
      <joint name='SA012__MoJo' type='revolute'>
        <child>SA012__MoJo__OUTPUT_BODY</child>
        <parent>SA011__MoJo__OUTPUT_BODY</parent>
        <axis>
          <xyz>0 -0.00051 -1</xyz>
          <limit>
            <lower>-1.57</lower>
            <upper>1.57</upper>
            <effort>7</effort>
            <velocity>2.20893</velocity>
          </limit>
          <dynamics>
            <damping>0.1</damping>
            <friction>0.2</friction>
            <spring_reference>0</spring_reference>
            <spring_stiffness>0</spring_stiffness>
          </dynamics>
          <use_parent_model_frame>1</use_parent_model_frame>
        </axis>
      </joint>
      <link name='SA013__MoJo__OUTPUT_BODY'>
        <pose frame=''>-0.8034 -0 0 -1.5708 -1.57024 1.5708</pose>
        <inertial>
          <pose frame=''>0 0 0.03195 0 -0 0</pose>
          <mass>0.206</mass>
          <inertia>
            <ixx>0.000319877</ixx>
            <ixy>0</ixy>
            <ixz>0</ixz>
            <iyy>0.000319877</iyy>
            <iyz>0</iyz>
            <izz>6.9628e-05</izz>
          </inertia>
        </inertial>
        <collision name='SA013__MoJo__OUTPUT_BODY_collision'>
          <pose frame=''>0 0 0.0183 0 -0 0</pose>
          <geometry>
            <cylinder>
              <length>0.033</length>
              <radius>0.026</radius>
            </cylinder>
          </geometry>
          <surface>
            <contact>
              <ode/>
            </contact>
            <friction>
              <ode>
                <mu>0.9</mu>
                <mu2>0.9</mu2>
              </ode>
              <torsional>
                <ode/>
              </torsional>
            </friction>
            <bounce/>
          </surface>
          <max_contacts>10</max_contacts>
        </collision>
        <collision name='SA013__MoJo__OUTPUT_BODY_fixed_joint_lump__SA014__MoJo__INPUT_INTERFACE_collision_1'>
          <pose frame=''>0 0 0.0456 0 0 -1.57075</pose>
          <geometry>
            <cylinder>
              <length>0.033</length>
              <radius>0.026</radius>
            </cylinder>
          </geometry>
          <surface>
            <contact>
              <ode/>
            </contact>
            <friction>
              <ode>
                <mu>0.9</mu>
                <mu2>0.9</mu2>
              </ode>
              <torsional>
                <ode/>
              </torsional>
            </friction>
            <bounce/>
          </surface>
          <max_contacts>10</max_contacts>
        </collision>
        <visual name='SA013__MoJo__OUTPUT_BODY_visual'>
          <pose frame=''>0 0 0 1.57075 -0 0</pose>
          <geometry>
            <mesh>
              <scale>1 1 1</scale>
              <uri>/home/tarun/snake_ws/src/snake_monster/meshes/rotary_output.stl</uri>
            </mesh>
          </geometry>
          <material>
            <script>
              <name>Gazebo/Red</name>
              <uri>file://media/materials/scripts/gazebo.material</uri>
            </script>
          </material>
        </visual>
        <visual name='SA013__MoJo__OUTPUT_BODY_fixed_joint_lump__SA014__MoJo__INPUT_INTERFACE_visual_1'>
          <pose frame=''>0 0 0.0623 1.57075 -0 -1.57075</pose>
          <geometry>
            <mesh>
              <scale>1 1 1</scale>
              <uri>/home/tarun/snake_ws/src/snake_monster/meshes/rotary_input.stl</uri>
            </mesh>
          </geometry>
          <material>
            <script>
              <name>Gazebo/Red</name>
              <uri>file://media/materials/scripts/gazebo.material</uri>
            </script>
          </material>
        </visual>
        <visual name='SA013__MoJo__OUTPUT_BODY_fixed_joint_lump__SA014__MoJo__INPUT_INTERFACE__COLLAR_visual_2'>
          <pose frame=''>0 0 0.0323 0 0 -1.57075</pose>
          <geometry>
            <cylinder>
              <length>0.01</length>
              <radius>0.026</radius>
            </cylinder>
          </geometry>
          <material>
            <script>
              <name>Gazebo/Black</name>
              <uri>file://media/materials/scripts/gazebo.material</uri>
            </script>
          </material>
        </visual>
        <velocity_decay/>
        <velocity_decay/>
        <gravity>1</gravity>
        <velocity_decay/>
        <self_collide>1</self_collide>
        <kinematic>0</kinematic>
      </link>
      <joint name='SA013__MoJo' type='revolute'>
        <child>SA013__MoJo__OUTPUT_BODY</child>
        <parent>SA012__MoJo__OUTPUT_BODY</parent>
        <axis>
          <xyz>0 1 -0.000556</xyz>
          <limit>
            <lower>-1.57</lower>
            <upper>1.57</upper>
            <effort>7</effort>
            <velocity>2.20893</velocity>
          </limit>
          <dynamics>
            <damping>0.1</damping>
            <friction>0.2</friction>
            <spring_reference>0</spring_reference>
            <spring_stiffness>0</spring_stiffness>
          </dynamics>
          <use_parent_model_frame>1</use_parent_model_frame>
        </axis>
      </joint>
      <link name='SA014__MoJo__OUTPUT_BODY'>
        <pose frame=''>-0.8673 -0 0 1.5708 -0.000602 -1.5708</pose>
        <inertial>
          <pose frame=''>0 0 0.03195 0 -0 0</pose>
          <mass>0.206</mass>
          <inertia>
            <ixx>0.000319877</ixx>
            <ixy>0</ixy>
            <ixz>0</ixz>
            <iyy>0.000319877</iyy>
            <iyz>0</iyz>
            <izz>6.9628e-05</izz>
          </inertia>
        </inertial>
        <collision name='SA014__MoJo__OUTPUT_BODY_collision'>
          <pose frame=''>0 0 0.0183 0 -0 0</pose>
          <geometry>
            <cylinder>
              <length>0.033</length>
              <radius>0.026</radius>
            </cylinder>
          </geometry>
          <surface>
            <contact>
              <ode/>
            </contact>
            <friction>
              <ode>
                <mu>0.9</mu>
                <mu2>0.9</mu2>
              </ode>
              <torsional>
                <ode/>
              </torsional>
            </friction>
            <bounce/>
          </surface>
          <max_contacts>10</max_contacts>
        </collision>
        <collision name='SA014__MoJo__OUTPUT_BODY_fixed_joint_lump__SA015__MoJo__INPUT_INTERFACE_collision_1'>
          <pose frame=''>0 0 0.0456 0 0 -1.57075</pose>
          <geometry>
            <cylinder>
              <length>0.033</length>
              <radius>0.026</radius>
            </cylinder>
          </geometry>
          <surface>
            <contact>
              <ode/>
            </contact>
            <friction>
              <ode>
                <mu>0.9</mu>
                <mu2>0.9</mu2>
              </ode>
              <torsional>
                <ode/>
              </torsional>
            </friction>
            <bounce/>
          </surface>
          <max_contacts>10</max_contacts>
        </collision>
        <visual name='SA014__MoJo__OUTPUT_BODY_visual'>
          <pose frame=''>0 0 0 1.57075 -0 0</pose>
          <geometry>
            <mesh>
              <scale>1 1 1</scale>
              <uri>/home/tarun/snake_ws/src/snake_monster/meshes/rotary_output.stl</uri>
            </mesh>
          </geometry>
          <material>
            <script>
              <name>Gazebo/Red</name>
              <uri>file://media/materials/scripts/gazebo.material</uri>
            </script>
          </material>
        </visual>
        <visual name='SA014__MoJo__OUTPUT_BODY_fixed_joint_lump__SA015__MoJo__INPUT_INTERFACE_visual_1'>
          <pose frame=''>0 0 0.0623 1.57075 -0 -1.57075</pose>
          <geometry>
            <mesh>
              <scale>1 1 1</scale>
              <uri>/home/tarun/snake_ws/src/snake_monster/meshes/rotary_input.stl</uri>
            </mesh>
          </geometry>
          <material>
            <script>
              <name>Gazebo/Red</name>
              <uri>file://media/materials/scripts/gazebo.material</uri>
            </script>
          </material>
        </visual>
        <visual name='SA014__MoJo__OUTPUT_BODY_fixed_joint_lump__SA015__MoJo__INPUT_INTERFACE__COLLAR_visual_2'>
          <pose frame=''>0 0 0.0323 0 0 -1.57075</pose>
          <geometry>
            <cylinder>
              <length>0.01</length>
              <radius>0.026</radius>
            </cylinder>
          </geometry>
          <material>
            <script>
              <name>Gazebo/Black</name>
              <uri>file://media/materials/scripts/gazebo.material</uri>
            </script>
          </material>
        </visual>
        <velocity_decay/>
        <velocity_decay/>
        <gravity>1</gravity>
        <velocity_decay/>
        <self_collide>1</self_collide>
        <kinematic>0</kinematic>
      </link>
      <joint name='SA014__MoJo' type='revolute'>
        <child>SA014__MoJo__OUTPUT_BODY</child>
        <parent>SA013__MoJo__OUTPUT_BODY</parent>
        <axis>
          <xyz>0 0.000602 1</xyz>
          <limit>
            <lower>-1.57</lower>
            <upper>1.57</upper>
            <effort>7</effort>
            <velocity>2.20893</velocity>
          </limit>
          <dynamics>
            <damping>0.1</damping>
            <friction>0.2</friction>
            <spring_reference>0</spring_reference>
            <spring_stiffness>0</spring_stiffness>
          </dynamics>
          <use_parent_model_frame>1</use_parent_model_frame>
        </axis>
      </joint>
      <link name='SA015__MoJo__OUTPUT_BODY'>
        <pose frame=''>-0.9312 -0 0 1.5708 1.57015 -1.5708</pose>
        <inertial>
          <pose frame=''>0 0 0.03195 0 -0 0</pose>
          <mass>0.206</mass>
          <inertia>
            <ixx>0.000319877</ixx>
            <ixy>0</ixy>
            <ixz>0</ixz>
            <iyy>0.000319877</iyy>
            <iyz>0</iyz>
            <izz>6.9628e-05</izz>
          </inertia>
        </inertial>
        <collision name='SA015__MoJo__OUTPUT_BODY_collision'>
          <pose frame=''>0 0 0.0183 0 -0 0</pose>
          <geometry>
            <cylinder>
              <length>0.033</length>
              <radius>0.026</radius>
            </cylinder>
          </geometry>
          <surface>
            <contact>
              <ode/>
            </contact>
            <friction>
              <ode>
                <mu>0.9</mu>
                <mu2>0.9</mu2>
              </ode>
              <torsional>
                <ode/>
              </torsional>
            </friction>
            <bounce/>
          </surface>
          <max_contacts>10</max_contacts>
        </collision>
        <collision name='SA015__MoJo__OUTPUT_BODY_fixed_joint_lump__SA016__MoJo__INPUT_INTERFACE_collision_1'>
          <pose frame=''>0 0 0.0456 0 0 -1.57075</pose>
          <geometry>
            <cylinder>
              <length>0.033</length>
              <radius>0.026</radius>
            </cylinder>
          </geometry>
          <surface>
            <contact>
              <ode/>
            </contact>
            <friction>
              <ode>
                <mu>0.9</mu>
                <mu2>0.9</mu2>
              </ode>
              <torsional>
                <ode/>
              </torsional>
            </friction>
            <bounce/>
          </surface>
          <max_contacts>10</max_contacts>
        </collision>
        <visual name='SA015__MoJo__OUTPUT_BODY_visual'>
          <pose frame=''>0 0 0 1.57075 -0 0</pose>
          <geometry>
            <mesh>
              <scale>1 1 1</scale>
              <uri>/home/tarun/snake_ws/src/snake_monster/meshes/rotary_output.stl</uri>
            </mesh>
          </geometry>
          <material>
            <script>
              <name>Gazebo/Red</name>
              <uri>file://media/materials/scripts/gazebo.material</uri>
            </script>
          </material>
        </visual>
        <visual name='SA015__MoJo__OUTPUT_BODY_fixed_joint_lump__SA016__MoJo__INPUT_INTERFACE_visual_1'>
          <pose frame=''>0 0 0.0623 1.57075 -0 -1.57075</pose>
          <geometry>
            <mesh>
              <scale>1 1 1</scale>
              <uri>/home/tarun/snake_ws/src/snake_monster/meshes/rotary_input.stl</uri>
            </mesh>
          </geometry>
          <material>
            <script>
              <name>Gazebo/Red</name>
              <uri>file://media/materials/scripts/gazebo.material</uri>
            </script>
          </material>
        </visual>
        <visual name='SA015__MoJo__OUTPUT_BODY_fixed_joint_lump__SA016__MoJo__INPUT_INTERFACE__COLLAR_visual_2'>
          <pose frame=''>0 0 0.0323 0 0 -1.57075</pose>
          <geometry>
            <cylinder>
              <length>0.01</length>
              <radius>0.026</radius>
            </cylinder>
          </geometry>
          <material>
            <script>
              <name>Gazebo/Black</name>
              <uri>file://media/materials/scripts/gazebo.material</uri>
            </script>
          </material>
        </visual>
        <velocity_decay/>
        <velocity_decay/>
        <gravity>1</gravity>
        <velocity_decay/>
        <self_collide>1</self_collide>
        <kinematic>0</kinematic>
      </link>
      <joint name='SA015__MoJo' type='revolute'>
        <child>SA015__MoJo__OUTPUT_BODY</child>
        <parent>SA014__MoJo__OUTPUT_BODY</parent>
        <axis>
          <xyz>0 -1 0.000649</xyz>
          <limit>
            <lower>-1.57</lower>
            <upper>1.57</upper>
            <effort>7</effort>
            <velocity>2.20893</velocity>
          </limit>
          <dynamics>
            <damping>0.1</damping>
            <friction>0.2</friction>
            <spring_reference>0</spring_reference>
            <spring_stiffness>0</spring_stiffness>
          </dynamics>
          <use_parent_model_frame>1</use_parent_model_frame>
        </axis>
      </joint>
      <link name='SA016__MoJo__OUTPUT_BODY'>
        <pose frame=''>-0.9951 -0 0 -1.5708 0.000695 1.5708</pose>
        <inertial>
          <pose frame=''>0 0 0 0 -0 0</pose>
          <mass>0.103</mass>
          <inertia>
            <ixx>5.4796e-05</ixx>
            <ixy>0</ixy>
            <ixz>0</ixz>
            <iyy>5.4796e-05</iyy>
            <iyz>0</iyz>
            <izz>3.4814e-05</izz>
          </inertia>
        </inertial>
        <collision name='SA016__MoJo__OUTPUT_BODY_collision'>
          <pose frame=''>0 0 0.0183 0 -0 0</pose>
          <geometry>
            <cylinder>
              <length>0.033</length>
              <radius>0.026</radius>
            </cylinder>
          </geometry>
          <surface>
            <contact>
              <ode/>
            </contact>
            <friction>
              <ode>
                <mu>0.9</mu>
                <mu2>0.9</mu2>
              </ode>
              <torsional>
                <ode/>
              </torsional>
            </friction>
            <bounce/>
          </surface>
          <max_contacts>10</max_contacts>
        </collision>
        <visual name='SA016__MoJo__OUTPUT_BODY_visual'>
          <pose frame=''>0 0 0 1.57075 -0 0</pose>
          <geometry>
            <mesh>
              <scale>1 1 1</scale>
              <uri>/home/tarun/snake_ws/src/snake_monster/meshes/rotary_output.stl</uri>
            </mesh>
          </geometry>
          <material>
            <script>
              <name>Gazebo/Red</name>
              <uri>file://media/materials/scripts/gazebo.material</uri>
            </script>
          </material>
        </visual>
        <gravity>1</gravity>
        <velocity_decay/>
        <self_collide>1</self_collide>
        <kinematic>0</kinematic>
      </link>
      <joint name='SA016__MoJo' type='revolute'>
        <child>SA016__MoJo__OUTPUT_BODY</child>
        <parent>SA015__MoJo__OUTPUT_BODY</parent>
        <axis>
          <xyz>0 -0.000695 -1</xyz>
          <limit>
            <lower>-1.57</lower>
            <upper>1.57</upper>
            <effort>7</effort>
            <velocity>2.20893</velocity>
          </limit>
          <dynamics>
            <damping>0.1</damping>
            <friction>0.2</friction>
            <spring_reference>0</spring_reference>
            <spring_stiffness>0</spring_stiffness>
          </dynamics>
          <use_parent_model_frame>1</use_parent_model_frame>
        </axis>
      </joint>
      <static>0</static>
      <plugin name='gazebo_ros_control' filename='libgazebo_ros_control.so'>
        <robotNamespace>/snake</robotNamespace>
      </plugin>
      <pose frame=''>0 0 0.03 0 -0 0</pose>
    </model>
    <model name='unit_box_8_0_clone_clone'>
      <pose frame=''>0.590461 -1.01295 0.499995 -3e-06 -0 -0</pose>
      <link name='link'>
        <inertial>
          <mass>1</mass>
          <inertia>
            <ixx>0.166667</ixx>
            <ixy>0</ixy>
            <ixz>0</ixz>
            <iyy>0.166667</iyy>
            <iyz>0</iyz>
            <izz>0.166667</izz>
          </inertia>
        </inertial>
        <collision name='collision'>
          <geometry>
            <box>
              <size>1 3.40701 1</size>
            </box>
          </geometry>
          <max_contacts>10</max_contacts>
          <surface>
            <contact>
              <ode/>
            </contact>
            <bounce/>
            <friction>
              <torsional>
                <ode/>
              </torsional>
              <ode/>
            </friction>
          </surface>
        </collision>
        <visual name='visual'>
          <geometry>
            <box>
              <size>1 3.40701 1</size>
            </box>
          </geometry>
          <material>
            <script>
              <name>Gazebo/Grey</name>
              <uri>file://media/materials/scripts/gazebo.material</uri>
            </script>
          </material>
        </visual>
        <self_collide>0</self_collide>
        <kinematic>0</kinematic>
        <gravity>1</gravity>
      </link>
    </model>
    <model name='unit_box_8_0_clone_clone_0'>
      <pose frame=''>2.54169 -0.578308 0.499995 3e-06 -0 0</pose>
      <link name='link'>
        <inertial>
          <mass>1</mass>
          <inertia>
            <ixx>0.166667</ixx>
            <ixy>0</ixy>
            <ixz>0</ixz>
            <iyy>0.166667</iyy>
            <iyz>0</iyz>
            <izz>0.166667</izz>
          </inertia>
        </inertial>
        <collision name='collision'>
          <geometry>
            <box>
              <size>0.999995 3.40701 1</size>
            </box>
          </geometry>
          <max_contacts>10</max_contacts>
          <surface>
            <contact>
              <ode/>
            </contact>
            <bounce/>
            <friction>
              <torsional>
                <ode/>
              </torsional>
              <ode/>
            </friction>
          </surface>
        </collision>
        <visual name='visual'>
          <geometry>
            <box>
              <size>0.999995 3.40701 1</size>
            </box>
          </geometry>
          <material>
            <script>
              <name>Gazebo/Grey</name>
              <uri>file://media/materials/scripts/gazebo.material</uri>
            </script>
          </material>
        </visual>
        <self_collide>0</self_collide>
        <kinematic>0</kinematic>
        <gravity>1</gravity>
      </link>
    </model>
    <model name='unit_box_8_0_clone_clone_1'>
      <pose frame=''>-2.52022 0.514083 0.499995 3e-06 -0 0</pose>
      <link name='link'>
        <inertial>
          <mass>1</mass>
          <inertia>
            <ixx>0.166667</ixx>
            <ixy>0</ixy>
            <ixz>0</ixz>
            <iyy>0.166667</iyy>
            <iyz>0</iyz>
            <izz>0.166667</izz>
          </inertia>
        </inertial>
        <collision name='collision'>
          <geometry>
            <box>
              <size>1 3.40701 1</size>
            </box>
          </geometry>
          <max_contacts>10</max_contacts>
          <surface>
            <contact>
              <ode/>
            </contact>
            <bounce/>
            <friction>
              <torsional>
                <ode/>
              </torsional>
              <ode/>
            </friction>
          </surface>
        </collision>
        <visual name='visual'>
          <geometry>
            <box>
              <size>1 3.40701 1</size>
            </box>
          </geometry>
          <material>
            <script>
              <name>Gazebo/Grey</name>
              <uri>file://media/materials/scripts/gazebo.material</uri>
            </script>
          </material>
        </visual>
        <self_collide>0</self_collide>
        <kinematic>0</kinematic>
        <gravity>1</gravity>
      </link>
    </model>
    <model name='unit_box_8_0_clone_clone_2'>
      <pose frame=''>-2.13392 2.53058 0.499999 0 1e-06 -1.57289</pose>
      <link name='link'>
        <inertial>
          <mass>1</mass>
          <inertia>
            <ixx>0.166667</ixx>
            <ixy>0</ixy>
            <ixz>0</ixz>
            <iyy>0.166667</iyy>
            <iyz>0</iyz>
            <izz>0.166667</izz>
          </inertia>
        </inertial>
        <collision name='collision'>
          <geometry>
            <box>
              <size>1 3.40701 1</size>
            </box>
          </geometry>
          <max_contacts>10</max_contacts>
          <surface>
            <contact>
              <ode/>
            </contact>
            <bounce/>
            <friction>
              <torsional>
                <ode/>
              </torsional>
              <ode/>
            </friction>
          </surface>
        </collision>
        <visual name='visual'>
          <geometry>
            <box>
              <size>1 3.40701 1</size>
            </box>
          </geometry>
          <material>
            <script>
              <name>Gazebo/Grey</name>
              <uri>file://media/materials/scripts/gazebo.material</uri>
            </script>
          </material>
        </visual>
        <self_collide>0</self_collide>
        <kinematic>0</kinematic>
        <gravity>1</gravity>
      </link>
    </model>
  </world>
</sdf>
